Workbook

Sheet setup
B3: Phase Setup
B4: Phase Id | C4: 402
B6: Main Study Setup | H6: Stratification Types | K6: matrix sproc
C7: Stratification % | D7: (separate study ids by and exclamation point ! for more than one) | E7: Stratification Type | H7: 1 = 2 Cross | K7: call report_matrix(studyids, stratfication type, stratification%);
B8: StudyIDs (2Cross) | C8: 50 | D8: 3037 | E8: 1 | H8: 2 = 3 Cross ETH/ED
B9: StudyIDs (3Cross) | C9: 50 | D9: 3037 | E9: 2 | H9: 3 = 3 Cross SEX/ETH
B10: StudyIDs (2Cross) | C10: 100 | D10: 3037 | E10: 1
B11: StudyIDs (3Cross) | C11: 100 | D11: 3037 | E11: 2
B12: StudyIDs (3Cross alternate view) | C12: 100 | D12: 3037 | E12: 3
B13: Validity/Reliability Setup | H13: Total study count for this report | K13: =COUNTIF(M:M, "Active") - COUNTIFS(L:L, "OSEP*",M:M, "Active") - COUNTIFS(L:L,"C_*",M:M, "Active") +2 -> 18
B14: Reports will show based on the ordered list below | H14: Phase Study List
B15: Report Order (do not touch) | C15: Study Id (separate studyids by !) | D15: Study Name | E15: Study Acronym | F15: Total Assignment | H15: study_id | I15: study_type_description | J15: sort_order | K15: study_name | L15: study_acronym | M15: study_status
A16: =LEN(C16) - LEN(SUBSTITUTE(C16, "!", "")) + 1 -> 1 | B16: 1 | C16: 3725 | D16: CELF-6 Standardization Record Form 1 (Ages 5-8) | E16: CELF6_RF1_STDZ | F16: =aurora_data!BJ58 -> 732 | H16: 3726 | I16: Main | J16: 1 | K16: CELF-6 Standardization Record Form 2 (Ages 9-21) | L16: CELF6_RF2_STDZ_9-21 | M16: Active
A17: =LEN(C17) - LEN(SUBSTITUTE(C17, "!", "")) + 1 -> 1 | B17: 2 | C17: 3726 | D17: CELF-6 Standardization Record Form 2 (Ages 9-21) | E17: CELF6_RF2_STDZ | F17: =aurora_data!BJ210 -> 1068 | H17: 3725 | I17: Main | J17: 1 | K17: CELF-6 Standardization Record Form 1 (Ages 5-8) | L17: CELF6_RF1_STDZ_5-8 | M17: Active
A18: =LEN(C18) - LEN(SUBSTITUTE(C18, "!", "")) + 1 -> 1 | B18: 3 | C18: 3727 | D18: Retest CELF-6 Standardization Record Form 1 (Ages 5-8) | E18: R_CELF6_RF1_STDZ | F18: =aurora_data!U257 -> 100 | H18: 3757 | I18: Clinical | J18: 2 | K18: CELF-6 RF2 OSEP Gifted and Talented (Ages 9-21) | L18: OSEP_GT_RF2 | M18: Active
A19: =LEN(C19) - LEN(SUBSTITUTE(C19, "!", "")) + 1 -> 1 | B19: 4 | C19: 3728 | D19: Retest CELF-6 Standardization Record Form 2 (Ages 9-16) | E19: R_CELF6_RF2_STDZ | F19: =aurora_data!U357 -> 104 | H19: 3756 | I19: Clinical | J19: 2 | K19: CELF-6 RF1 OSEP Gifted and Talented (Ages 5-8) | L19: OSEP_GT_RF1 | M19: Active
A20: =LEN(C20) - LEN(SUBSTITUTE(C20, "!", "")) + 1 -> 1 | B20: 5 | C20: 3732 | D20: Validity CELF-6 RF1/CELFP-3 (Ages 5-6) | E20: V_CELFP3_RF1 | F20: =aurora_data!U457 -> 35 | H20: 3755 | I20: Clinical | J20: 2 | K20: CELF-6 RF2 OSEP Speech Impairment (Ages 9-21) | L20: OSEP_SI_RF2 | M20: Active
A21: =LEN(C21) - LEN(SUBSTITUTE(C21, "!", "")) + 1 -> 1 | B21: 6 | C21: 3729 | D21: Validity CELF-6 RF1/CELF-5 (Ages 5-8) | E21: V_CELF5_RF1 | F21: =aurora_data!U548 -> 26 | H21: 3754 | I21: Clinical | J21: 2 | K21: CELF-6 RF1 OSEP Speech Impairment (Ages 5-8) | L21: OSEP_SI_RF1 | M21: Active
A22: =LEN(C22) - LEN(SUBSTITUTE(C22, "!", "")) + 1 -> 1 | B22: 7 | C22: 3730 | D22: Validity CELF-6 RF2/CELF-5 (Ages 9-16) | E22: V_CELF5_RF2 | F22: =aurora_data!U648 -> 26 | H22: 3753 | I22: Clinical | J22: 2 | K22: CELF-6 RF2 OSEP Specific Learning Disability (Ages 9-21) | L22: OSEP_SLD_RF2 | M22: Active
A23: =LEN(C23) - LEN(SUBSTITUTE(C23, "!", "")) + 1 -> 1 | B23: 8 | C23: 3731 | D23: Validity CELF-6 RF2/CELF-5 Meta (Ages 9-21) | E23: V_META_RF2 | F23: =aurora_data!U757 -> 35 | H23: 3752 | I23: Clinical | J23: 2 | K23: CELF-6 RF1 OSEP Specific Learning Disability (Ages 5-8) | L23: OSEP_SLD_RF1 | M23: Active
A24: =LEN(C24) - LEN(SUBSTITUTE(C24, "!", "")) + 1 -> 1 | B24: 9 | C24: 3733 | D24: Validity CELF-6 RF1/CCC-2 (Ages 5-8) | E24: V_CCC2_RF1 | F24: =aurora_data!U848 -> 25 | H24: 3751 | I24: Clinical | J24: 2 | K24: CELF-6 RF2 OSEP ADHD (Ages 9-17) | L24: OSEP_ADHD_RF2 | M24: Active
A25: =LEN(C25) - LEN(SUBSTITUTE(C25, "!", "")) + 1 -> 1 | B25: 10 | C25: 3734 | D25: Validity CELF-6 RF2/CCC-2 (Ages 9-16) | E25: V_CCC2_RF2 | F25: =aurora_data!U948 -> 29 | H25: 3750 | I25: Clinical | J25: 2 | K25: CELF-6 RF1 OSEP ADHD (Ages 5-8) | L25: OSEP_ADHD_RF1 | M25: Active
A26: =LEN(C26) - LEN(SUBSTITUTE(C26, "!", "")) + 1 -> 1 | B26: 11 | C26: 3735 | D26: Counterbalance CELF-5/CELF-6 RF1 (Ages 5-8) | E26: CB_CELF5_RF1 | F26: =aurora_data!U1048 -> 27 | H26: 3749 | I26: Clinical | J26: 2 | K26: CELF-6 RF2 OSEP Intellectual Disability (Ages 9-21) | L26: OSEP_ID_RF2 | M26: Active
A27: =LEN(C27) - LEN(SUBSTITUTE(C27, "!", "")) + 1 -> 1 | B27: 12 | C27: 3736 | D27: Counterbalance CELF-5/CELF-6 RF2 (Ages 9-16) | E27: CB_CELF5_RF2 | F27: =aurora_data!U1148 -> 27 | H27: 3748 | I27: Clinical | J27: 2 | K27: CELF-6 RF1 OSEP Intellectual Disability (Ages 5-8) | L27: OSEP_ID_RF1 | M27: Active
A28: =LEN(C28) - LEN(SUBSTITUTE(C28, "!", "")) + 1 -> 1 | B28: 13 | C28: 3737 | D28: Counterbalance CELF-5 Meta/CELF-6 RF2 (Ages 9-21) | E28: CB_META_RF2 | F28: =aurora_data!U1257 -> 33 | H28: 3747 | I28: Clinical | J28: 2 | K28: CELF-6 RF1 OSEP Developmental Delay (Ages 5-8) | L28: OSEP_DD_RF1 | M28: Active
A29: =LEN(C29) - LEN(SUBSTITUTE(C29, "!", "")) + 1 -> 1 | B29: 14 | C29: 3738 | D29: Counterbalance CELFP-3/CELF-6 RF1 (Ages 5-6) | E29: CB_CELFP3_RF1 | F29: =aurora_data!U1357 -> 35 | H29: 3746 | I29: Clinical | J29: 2 | K29: CELF-6 RF 2 Clinical Specific Learning Disability in Reading and/or Writing (Ages 9-21) | L29: C_SLDRW_RF2 | M29: Active
A30: =LEN(C30) - LEN(SUBSTITUTE(C30, "!", "")) + 1 -> 1 | B30: 15 | C30: 3758 | D30: CELF-6 Standardization Record Form 1 (Ages 5-8) Usability | E30: CELF6_RF1_USB | F30: =aurora_data!U1446 -> 2 | H30: 3745 | I30: Clinical | J30: 2 | K30: CELF-6 RF 1 Clinical Specific Learning Disability in Reading and/or Writing (Age 8) | L30: C_SLDRW_RF1 | M30: Active
A31: =LEN(C31) - LEN(SUBSTITUTE(C31, "!", "")) + 1 -> 1 | B31: 16 | C31: 3759 | D31: CELF-6 Standardization Record Form 2 (Ages 9-21) Usability | E31: CELF6_RF2_USB | F31: =aurora_data!U1546 -> 1 | H31: 3744 | I31: Clinical | J31: 2 | K31: CELF-6 RF 2 Clinical Autism Spectrum Disorder (Ages 9-16) | L31: C_ASDL_RF2 | M31: Active
A32: =LEN(C32) - LEN(SUBSTITUTE(C32, "!", "")) + 1 -> 1 | B32: 17 | C32: 3760 | D32: CELF-6 RF 1 Clinical Language Disorder (Ages 5-8) Usability | E32: C_LD_RF1_USB | F32: =aurora_data!U1646 -> 1 | H32: 3743 | I32: Clinical | J32: 2 | K32: CELF-6 RF 1 Clinical Autism Spectrum Disorder (Ages 5-8) | L32: C_ASDL_RF1 | M32: Active
A33: =LEN(C33) - LEN(SUBSTITUTE(C33, "!", "")) + 1 -> 1 | B33: 18 | C33: 3761 | D33: CELF-6 RF 2 Clinical Language Disorder (Ages 9-21) Usability | E33: C_LD_RF2_USB | F33: =aurora_data!U1746 -> 1 | H33: 3741 | I33: Clinical | J33: 2 | K33: CELF-6 RF 1 Clinical Hard of Hearing (Ages 5-8) | L33: C_HH_RF1 | M33: Active
B34: Total | C34: =SUM(A16:A33) -> 18 | H34: 3740 | I34: Clinical | J34: 2 | K34: CELF-6 RF 2 Clinical Language Disorder (Ages 9-16) | L34: C_LD_RF2 | M34: Active
H35: 3739 | I35: Clinical | J35: 2 | K35: CELF-6 RF 1 Clinical Language Disorder (Ages 5-8) | L35: C_LD_RF1 | M35: Active
H36: 3742 | I36: Clinical | J36: 2 | K36: CELF-6 RF 2 Clinical Hard of Hearing (Ages 9-16) | L36: C_HH_RF2 | M36: Active
H37: 3727 | I37: Reliability | J37: 3 | K37: Retest CELF-6 Standardization Record Form 1 (Ages 5-8) | L37: R_CELF6_RF1_STDZ_5-8 | M37: Active
H38: 3728 | I38: Reliability | J38: 3 | K38: Retest CELF-6 Standardization Record Form 2 (Ages 9-16) | L38: R_CELF6_RF2_STDZ_9-16 | M38: Active
H39: 3732 | I39: Validity | J39: 4 | K39: Validity CELF-6 RF1/CELFP-3 (Ages 5-6) | L39: V_CELFP3_RF1 | M39: Active
H40: 3729 | I40: Validity | J40: 4 | K40: Validity CELF-6 RF1/CELF-5 (Ages 5-8) | L40: V_CELF5_RF1 | M40: Active
H41: 3730 | I41: Validity | J41: 4 | K41: Validity CELF-6 RF2/CELF-5 (Ages 9-16) | L41: V_CELF5_RF2 | M41: Active
H42: 3731 | I42: Validity | J42: 4 | K42: Validity CELF-6 RF2/CELF-5 Meta (Ages 9-21) | L42: V_META_RF2 | M42: Active
H43: 3733 | I43: Validity | J43: 4 | K43: Validity CELF-6 RF1/CCC-2 (Ages 5-8) | L43: V_CCC2_RF1 | M43: Active
...

Sheet Open Cells
A8: =setup!C16 -> 3725
A9: =setup!D16 -> CELF-6 Standardization Record Form 1 (Ages 5-8)
A10: status | B10: day | C10: Yr | D10: Wk | E10: WeekOf | F10: ageband | G10: variable_type | H10: variable_value | I10: target | J10: targetRounded | K10: AssignDay | L10: AssignCounts | M10: totalCells | N10: cummAssingCount | O10: openCells | P10: reportSession | Q10: last_refreshed
A11: Total Assignments | B11: 08/05/2026 | C11: 2026 | D11: 32 | E11: 08/03/2026 | F11: 05.00.00-05.05.30 | G11: ED | H11: 1 | I11: 6.96 | J11: 7 | K11: 01/01/2024 | L11: 10 | M11: 2400 | N11: 10 | O11: 0 | P11: 0 | Q11: 08/05/2026 @ 7:32 AM
A12: Total Assignments | B12: 08/05/2026 | C12: 2026 | D12: 32 | E12: 08/03/2026 | F12: 05.00.00-05.05.30 | G12: ED | H12: 2 | I12: 19.98 | J12: 20 | K12: 01/01/2024 | L12: 22 | M12: 2400 | N12: 22 | O12: 0 | P12: 0 | Q12: 08/05/2026 @ 7:32 AM
A13: Total Assignments | B13: 08/05/2026 | C13: 2026 | D13: 32 | E13: 08/03/2026 | F13: 05.00.00-05.05.30 | G13: ED | H13: 3 | I13: 32.57 | J13: 33 | K13: 01/01/2024 | L13: 39 | M13: 2400 | N13: 39 | O13: 0 | P13: 0 | Q13: 08/05/2026 @ 7:32 AM
A14: Total Assignments | B14: 08/05/2026 | C14: 2026 | D14: 32 | E14: 08/03/2026 | F14: 05.00.00-05.05.30 | G14: ED | H14: 4 | I14: 40.48 | J14: 40 | K14: 01/01/2024 | L14: 46 | M14: 2400 | N14: 46 | O14: 0 | P14: 0 | Q14: 08/05/2026 @ 7:32 AM
A15: Total Assignments | B15: 08/05/2026 | C15: 2026 | D15: 32 | E15: 08/03/2026 | F15: 05.00.00-05.05.30 | G15: ETH | H15: AS | I15: 4.58 | J15: 5 | K15: 01/01/2024 | L15: 8 | M15: 2400 | N15: 8 | O15: 0 | P15: 0 | Q15: 08/05/2026 @ 7:32 AM
A16: Total Assignments | B16: 08/05/2026 | C16: 2026 | D16: 32 | E16: 08/03/2026 | F16: 05.00.00-05.05.30 | G16: ETH | H16: BL | I16: 13.31 | J16: 13 | K16: 01/01/2024 | L16: 15 | M16: 2400 | N16: 15 | O16: 0 | P16: 0 | Q16: 08/05/2026 @ 7:32 AM
A17: Total Assignments | B17: 08/05/2026 | C17: 2026 | D17: 32 | E17: 08/03/2026 | F17: 05.00.00-05.05.30 | G17: ETH | H17: HI | I17: 23.1 | J17: 23 | K17: 01/01/2024 | L17: 23 | M17: 2400 | N17: 23 | O17: 0 | P17: 0 | Q17: 08/05/2026 @ 7:32 AM
A18: Total Assignments | B18: 08/05/2026 | C18: 2026 | D18: 32 | E18: 08/03/2026 | F18: 05.00.00-05.05.30 | G18: ETH | H18: OT | I18: 10.54 | J18: 11 | K18: 01/01/2024 | L18: 15 | M18: 2400 | N18: 15 | O18: 0 | P18: 0 | Q18: 08/05/2026 @ 7:32 AM
A19: Total Assignments | B19: 08/05/2026 | C19: 2026 | D19: 32 | E19: 08/03/2026 | F19: 05.00.00-05.05.30 | G19: ETH | H19: WH | I19: 48.47 | J19: 48 | K19: 01/01/2024 | L19: 56 | M19: 2400 | N19: 56 | O19: 0 | P19: 0 | Q19: 08/05/2026 @ 7:32 AM
A20: Total Assignments | B20: 08/05/2026 | C20: 2026 | D20: 32 | E20: 08/03/2026 | F20: 05.00.00-05.05.30 | G20: REGION | H20: MW | I20: 21.13 | J20: 21 | K20: 01/01/2024 | L20: 29 | M20: 2400 | N20: 29 | O20: 0 | P20: 0 | Q20: 08/05/2026 @ 7:32 AM
A21: Total Assignments | B21: 08/05/2026 | C21: 2026 | D21: 32 | E21: 08/03/2026 | F21: 05.00.00-05.05.30 | G21: REGION | H21: NE | I21: 15.8 | J21: 16 | K21: 01/01/2024 | L21: 18 | M21: 2400 | N21: 18 | O21: 0 | P21: 0 | Q21: 08/05/2026 @ 7:32 AM
A22: Total Assignments | B22: 08/05/2026 | C22: 2026 | D22: 32 | E22: 08/03/2026 | F22: 05.00.00-05.05.30 | G22: REGION | H22: SO | I22: 39.96 | J22: 40 | K22: 01/01/2024 | L22: 44 | M22: 2400 | N22: 44 | O22: 0 | P22: 0 | Q22: 08/05/2026 @ 7:32 AM
... A106: Total Assignments | B106: 08/05/2026 | C106: 2026 | D106: 32 | E106: 08/03/2026 | F106: 08.00.00-08.11.30 | G106: SEX | H106: OTHER | I106: 0 | J106: 0 | K106: 08/05/2026 | L106: 0 | M106: 2400 | N106: 0 | O106: 0 | P106: 0 | Q106: 08/05/2026 @ 7:32 AM
A158: =setup!C17 -> 3726
A159: =setup!D17 -> CELF-6 Standardization Record Form 2 (Ages 9-21)
A160: status | B160: day | C160: Yr | D160: Wk | E160: WeekOf | F160: ageband | G160: variable_type | H160: variable_value | I160: target | J160: targetRounded | K160: AssignDay | L160: AssignCounts | M160: totalCells | N160: cummAssingCount | O160: openCells | P160: reportSession | Q160: last_refreshed
A161: Total Assignments | B161: 08/05/2026 | C161: 2026 | D161: 32 | E161: 08/03/2026 | F161: 09.00.00-09.11.30 | G161: ED | H161: 1 | I161: 8.29 | J161: 8 | K161: 01/01/2024 | L161: 10 | M161: 3600 | N161: 10 | O161: 0 | P161: 0 | Q161: 08/05/2026 @ 7:31 AM
A162: Total Assignments | B162: 08/05/2026 | C162: 2026 | D162: 32 | E162: 08/03/2026 | F162: 09.00.00-09.11.30 | G162: ED | H162: 2 | I162: 20.14 | J162: 20 | K162: 01/01/2024 | L162: 27 | M162: 3600 | N162: 27 | O162: 0 | P162: 0 | Q162: 08/05/2026 @ 7:31 AM
A163: Total Assignments | B163: 08/05/2026 | C163: 2026 | D163: 32 | E163: 08/03/2026 | F163: 09.00.00-09.11.30 | G163: ED | H163: 3 | I163: 31.94 | J163: 32 | K163: 01/01/2024 | L163: 45 | M163: 3600 | N163: 45 | O163: 0 | P163: 0 | Q163: 08/05/2026 @ 7:31 AM
A164: Total Assignments | B164: 08/05/2026 | C164: 2026 | D164: 32 | E164: 08/03/2026 | F164: 09.00.00-09.11.30 | G164: ED | H164: 4 | I164: 39.63 | J164: 40 | K164: 01/01/2024 | L164: 48 | M164: 3600 | N164: 48 | O164: 0 | P164: 0 | Q164: 08/05/2026 @ 7:31 AM
A165: Total Assignments | B165: 08/05/2026 | C165: 2026 | D165: 32 | E165: 08/03/2026 | F165: 09.00.00-09.11.30 | G165: ETH | H165: AS | I165: 5.08 | J165: 5 | K165: 01/01/2024 | L165: 6 | M165: 3600 | N165: 6 | O165: 0 | P165: 0 | Q165: 08/05/2026 @ 7:31 AM
A166: Total Assignments | B166: 08/05/2026 | C166: 2026 | D166: 32 | E166: 08/03/2026 | F166: 09.00.00-09.11.30 | G166: ETH | H166: BL | I166: 12.66 | J166: 13 | K166: 01/01/2024 | L166: 18 | M166: 3600 | N166: 18 | O166: 0 | P166: 0 | Q166: 08/05/2026 @ 7:31 AM
A167: Total Assignments | B167: 08/05/2026 | C167: 2026 | D167: 32 | E167: 08/03/2026 | F167: 09.00.00-09.11.30 | G167: ETH | H167: HI | I167: 24 | J167: 24 | K167: 01/01/2024 | L167: 32 | M167: 3600 | N167: 32 | O167: 0 | P167: 0 | Q167: 08/05/2026 @ 7:31 AM
A168: Total Assignments | B168: 08/05/2026 | C168: 2026 | D168: 32 | E168: 08/03/2026 | F168: 09.00.00-09.11.30 | G168: ETH | H168: OT | I168: 9.92 | J168: 10 | K168: 01/01/2024 | L168: 12 | M168: 3600 | N168: 12 | O168: 0 | P168: 0 | Q168: 08/05/2026 @ 7:31 AM
A169: Total Assignments | B169: 08/05/2026 | C169: 2026 | D169: 32 | E169: 08/03/2026 | F169: 09.00.00-09.11.30 | G169: ETH | H169: WH | I169: 48.34 | J169: 48 | K169: 01/01/2024 | L169: 62 | M169: 3600 | N169: 62 | O169: 0 | P169: 0 | Q169: 08/05/2026 @ 7:31 AM
A170: Total Assignments | B170: 08/05/2026 | C170: 2026 | D170: 32 | E170: 08/03/2026 | F170: 09.00.00-09.11.30 | G170: REGION | H170: MW | I170: 21.61 | J170: 22 | K170: 01/01/2024 | L170: 30 | M170: 3600 | N170: 30 | O170: 0 | P170: 0 | Q170: 08/05/2026 @ 7:31 AM
A171: Total Assignments | B171: 08/05/2026 | C171: 2026 | D171: 32 | E171: 08/03/2026 | F171: 09.00.00-09.11.30 | G171: REGION | H171: NE | I171: 15.54 | J171: 16 | K171: 01/01/2024 | L171: 17 | M171: 3600 | N171: 17 | O171: 0 | P171: 0 | Q171: 08/05/2026 @ 7:31 AM
A172: Total Assignments | B172: 08/05/2026 | C172: 2026 | D172: 32 | E172: 08/03/2026 | F172: 09.00.00-09.11.30 | G172: REGION | H172: SO | I172: 39.7 | J172: 40 | K172: 01/01/2024 | L172: 53 | M172: 3600 | N172: 53 | O172: 0 | P172: 0 | Q172: 08/05/2026 @ 7:31 AM
... A304: Total Assignments | B304: 08/05/2026 | C304: 2026 | D304: 32 | E304: 08/03/2026 | F304: 17.00.00-21.11.30 | G304: SEX | H304: OTHER | I304: 0 | J304: 0 | K304: 08/05/2026 | L304: 0 | M304: 3600 | N304: 0 | O304: 0 | P304: 0 | Q304: 08/05/2026 @ 7:31 AM
A356: =setup!C18 -> 3727
A357: =setup!D18 -> Retest CELF-6 Standardization Record Form 1 (Ages 5-8)
A358: status | B358: day | C358: Yr | D358: Wk | E358: WeekOf | F358: ageband | G358: variable_type | H358: variable_value | I358: target | J358: targetRounded | K358: AssignDay | L358: AssignCounts | M358: totalCells | N358: cummAssingCount | O358: openCells | P358: reportSession | Q358: last_refreshed
A359: Total Assignments | B359: 08/05/2026 | C359: 2026 | D359: 32 | E359: 08/03/2026 | F359: 05.00.00-06.11.30 | H359: 5 | I359: 1 | J359: 1 | K359: 08/05/2026 | L359: 0 | M359: 32 | N359: 0 | O359: 1 | P359: 0 | Q359: 08/05/2026 @ 7:31 AM
A360: Total Assignments | B360: 08/05/2026 | C360: 2026 | D360: 32 | E360: 08/03/2026 | F360: 05.00.00-06.11.30 | G360: ED | H360: 1 | I360: 1 | J360: 1 | K360: 01/01/2024 | L360: 2 | M360: 32 | N360: 2 | O360: 0 | P360: 0 | Q360: 08/05/2026 @ 7:31 AM
A361: Total Assignments | B361: 08/05/2026 | C361: 2026 | D361: 32 | E361: 08/03/2026 | F361: 05.00.00-06.11.30 | G361: ED | H361: 2 | I361: 1 | J361: 1 | K361: 01/01/2024 | L361: 7 | M361: 32 | N361: 7 | O361: 0 | P361: 0 | Q361: 08/05/2026 @ 7:31 AM
A362: Total Assignments | B362: 08/05/2026 | C362: 2026 | D362: 32 | E362: 08/03/2026 | F362: 05.00.00-06.11.30 | G362: ED | H362: 3 | I362: 1 | J362: 1 | K362: 01/01/2024 | L362: 15 | M362: 32 | N362: 15 | O362: 0 | P362: 0 | Q362: 08/05/2026 @ 7:31 AM
A363: Total Assignments | B363: 08/05/2026 | C363: 2026 | D363: 32 | E363: 08/03/2026 | F363: 05.00.00-06.11.30 | G363: ED | H363: 4 | I363: 1 | J363: 1 | K363: 01/01/2024 | L363: 26 | M363: 32 | N363: 26 | O363: 0 | P363: 0 | Q363: 08/05/2026 @ 7:31 AM
...

Sheet aurora_data
A1: =setup!C16 -> 3725 | F1: CELF-6 Standardization Record Form 1 (Ages 5-8) - CELF6_RF1_STDZ | AA1: =setup!C16 -> 3725 | AM1: CELF6_STDZ_Eth_by_Ed | CA1: =setup!C16 -> 3725 | CK1: CELF6_STDZ_Sex_by_Eth | DA1: 3725 | DL1: CELF6_STDZ_Sex_by_Ed | FA1: 3725 | FK1: CELF6_STDZ_Eth_by_Reg
A2: =_xlfn.CONCAT(setup!D16, " - ",setup!E16) -> CELF-6 Standardization Record Form 1 (Ages 5-8) - CELF6_RF1_STDZ | AA2: =_xlfn.CONCAT(setup!D16, " - ",setup!E16) -> CELF-6 Standardization Record Form 1 (Ages 5-8) - CELF6_RF1_STDZ | CA2: =_xlfn.CONCAT(setup!D16, " - ",setup!E16) -> CELF-6 Standardization Record Form 1 (Ages 5-8) - CELF6_RF1_STDZ | DA2: CELF-6 Standardization Record Form 1 (Ages 5-8) - CELF6_RF1_STDZ | FA2: CELF-6 Standardization Record Form 1 (Ages 5-8) - CELF6_RF1_STDZ
A3: ageband | B3: gradeband | C3: report | D3: 1 | E3: 2 | F3: 3 | G3: 4 | H3: 5 | I3: AS | J3: BL | K3: HI | L3: OT | M3: WH | N3: MW | O3: NE | P3: SO | Q3: WE | R3: F | S3: M | T3: OTHER | U3: Total | V3: LastRefreshed | AA3: ageband | AB3: gradeband | AC3: report | AD3: AS1 | AE3: AS2 | AF3: AS3 | AG3: AS4 | AH3: AS5 | AI3: BL1 | AJ3: BL2 | AK3: BL3 | AL3: BL4 | AM3: BL5 | AN3: HI1 | AO3: HI2 | AP3: HI3 | AQ3: HI4 | AR3: HI5 | AS3: OT1 | AT3: OT2 | AU3: OT3 | AV3: OT4 | AW3: OT5 | AX3: WH1 | AY3: WH2 | AZ3: WH3 | BA3: WH4 | BB3: WH5 | BC3: MW | BD3: NE | BE3: SO | BF3: WE | BG3: F | BH3: M | BI3: OTHER | BJ3: Total | BK3: LastRefreshed | CA3: ageband | CB3: gradeband | CC3: report | CD3: 1 | CE3: 2 | CF3: 3 | CG3: 4 | CH3: 5 | CI3: MAS | CJ3: FAS | CK3: MBL | CL3: FBL | CM3: MHI | CN3: FHI | CO3: MOT | CP3: FOT | CQ3: MWH | CR3: FWH | CS3: MW | CT3: NE | CU3: SO | CV3: WE | CW3: Total | CX3: LastRefreshed | DA3: ageband | DB3: gradeband | DC3: report | DD3: F1 | DE3: F2 | DF3: F3 | DG3: F4 | DH3: F5 | DI3: M1 | DJ3: M2 | DK3: M3 | DL3: M4 | DM3: M5 | DN3: OTHER1 | DO3: OTHER2 | DP3: OTHER3 | DQ3: OTHER4 | DR3: OTHER5 | DS3: AS | DT3: BL | DU3: HI | DV3: OT | DW3: WH | DX3: MW | DY3: NE | DZ3: SO | EA3: WE | EB3: Total | EC3: LastRefreshed | FA3: ageband | FB3: gradeband | FC3: report | FD3: 1 | FE3: 2 | FF3: 3 | FG3: 4 | FH3: 5 | FI3: ASMW | FJ3: ASNE | FK3: ASSO | FL3: ASWE | FM3: BLMW | FN3: BLNE | FO3: BLSO | FP3: BLWE | FQ3: HIMW | FR3: HINE | FS3: HISO | FT3: HIWE | FU3: OTMW | FV3: OTNE | FW3: OTSO | FX3: OTWE | FY3: WHMW | FZ3: WHNE | GA3: WHSO | GB3: WHWE | GC3: F | GD3: M | GE3: OTHER | GF3: Total | GG3: LastRefreshed
A4: 05.00.00-05.05.30 | C4: Target N | D4: 6.96 | E4: 19.98 | F4: 32.57 | G4: 40.48 | H4: 0 | I4: 4.58 | J4: 13.31 | K4: 23.1 | L4: 10.54 | M4: 48.47 | N4: 21.13 | O4: 15.8 | P4: 39.96 | Q4: 23.12 | R4: 50 | S4: 50 | T4: 0 | U4: 100 | V4: 08/05/2026 @ 7:34 AM | AA4: 05.00.00-05.05.30 | AC4: Target N | AD4: 0.24 | AE4: 0.42 | AF4: 0.77 | AG4: 3.15 | AH4: 0 | AI4: 1.24 | AJ4: 3.68 | AK4: 5.19 | AL4: 3.19 | AM4: 0 | AN4: 3.41 | AO4: 6.58 | AP4: 7.75 | AQ4: 5.36 | AR4: 0 | AS4: 0.51 | AT4: 1.94 | AU4: 3.47 | AV4: 4.62 | AW4: 0 | AX4: 1.55 | AY4: 7.37 | AZ4: 15.39 | BA4: 24.17 | BB4: 0 | BC4: 21.13 | BD4: 15.8 | BE4: 39.96 | BF4: 23.12 | BG4: 50 | BH4: 50 | BI4: 0 | BJ4: 100 | BK4: 08/05/2026 @ 7:34 AM | CA4: 05.00.00-05.05.30 | CC4: Target N | CD4: 6.96 | CE4: 19.98 | CF4: 32.57 | CG4: 40.48 | CH4: 0 | CI4: 2.29 | CJ4: 2.29 | CK4: 6.65 | CL4: 6.65 | CM4: 11.55 | CN4: 11.55 | CO4: 5.27 | CP4: 5.27 | CQ4: 24.23 | CR4: 24.23 | CS4: 21.13 | CT4: 15.8 | CU4: 39.96 | CV4: 23.12 | CW4: 100 | CX4: 08/05/2026 @ 7:33 AM | DA4: 05.00.00-05.05.30 | DC4: Target N | DD4: 3.48 | DE4: 9.99 | DF4: 16.29 | DG4: 20.24 | DH4: 0 | DI4: 3.48 | DJ4: 9.99 | DK4: 16.29 | DL4: 20.24 | DM4: 0 | DN4: 0 | DO4: 0 | DP4: 0 | DQ4: 0 | DR4: 0 | DS4: 4.58 | DT4: 13.31 | DU4: 23.1 | DV4: 10.54 | DW4: 48.47 | DX4: 21.13 | DY4: 15.8 | DZ4: 39.96 | EA4: 23.12 | EB4: 100 | EC4: 08/05/2026 @ 7:33 AM | FA4: 05.00.00-05.05.30 | FC4: Target N | FD4: 6.96 | FE4: 19.98 | FF4: 32.57 | FG4: 40.48 | FH4: 0 | FI4: 0.55 | FJ4: 0.88 | FK4: 1.25 | FL4: 1.9 | FM4: 2.62 | FN4: 1.74 | FO4: 8.06 | FP4: 0.89 | FQ4: 2.58 | FR4: 3.3 | FS4: 8.85 | FT4: 8.37 | FU4: 1.97 | FV4: 1.64 | FW4: 3.7 | FX4: 3.23 | FY4: 13.41 | FZ4: 8.24 | GA4: 18.09 | GB4: 8.72 | GC4: 50 | GD4: 50 | GE4: 0 | GF4: 100 | GG4: 08/05/2026 @ 7:33 AM
A5: 05.00.00-05.05.30 | C5: Stratified Usable N | D5: 8 | E5: 20 | F5: 32 | G5: 40 | H5: 0 | I5: 5 | J5: 13 | K5: 21 | L5: 12 | M5: 49 | N5: 20 | O5: 16 | P5: 41 | Q5: 23 | R5: 50 | S5: 50 | T5: 0 | U5: 100 | V5: 08/05/2026 @ 7:34 AM | AA5: 05.00.00-05.05.30 | AC5: Stratified Usable N | AD5: 1 | AE5: 0 | AF5: 1 | AG5: 3 | AH5: 0 | AI5: 1 | AJ5: 4 | AK5: 5 | AL5: 3 | AM5: 0 | AN5: 2 | AO5: 6 | AP5: 8 | AQ5: 5 | AR5: 0 | AS5: 2 | AT5: 2 | AU5: 3 | AV5: 5 | AW5: 0 | AX5: 2 | AY5: 8 | AZ5: 15 | BA5: 24 | BB5: 0 | BC5: 20 | BD5: 16 | BE5: 41 | BF5: 23 | BG5: 50 | BH5: 50 | BI5: 0 | BJ5: 100 | BK5: 08/05/2026 @ 7:34 AM | CA5: 05.00.00-05.05.30 | CC5: Stratified Usable N | CD5: 8 | CE5: 20 | CF5: 32 | CG5: 40 | CH5: 0 | CI5: 3 | CJ5: 2 | CK5: 7 | CL5: 6 | CM5: 12 | CN5: 9 | CO5: 4 | CP5: 8 | CQ5: 24 | CR5: 25 | CS5: 20 | CT5: 16 | CU5: 41 | CV5: 23 | CW5: 100 | CX5: 08/05/2026 @ 7:33 AM | DA5: 05.00.00-05.05.30 | DC5: Stratified Usable N | DD5: 4 | DE5: 9 | DF5: 19 | DG5: 18 | DH5: 0 | DI5: 4 | DJ5: 11 | DK5: 13 | DL5: 22 | DM5: 0 | DN5: 0 | DO5: 0 | DP5: 0 | DQ5: 0 | DR5: 0 | DS5: 5 | DT5: 13 | DU5: 21 | DV5: 12 | DW5: 49 | DX5: 20 | DY5: 16 | DZ5: 41 | EA5: 23 | EB5: 100 | EC5: 08/05/2026 @ 7:33 AM | FA5: 05.00.00-05.05.30 | FC5: Stratified Usable N | FD5: 8 | FE5: 20 | FF5: 32 | FG5: 40 | FH5: 0 | FI5: 1 | FJ5: 1 | FK5: 1 | FL5: 2 | FM5: 0 | FN5: 1 | FO5: 11 | FP5: 1 | FQ5: 1 | FR5: 3 | FS5: 9 | FT5: 8 | FU5: 4 | FV5: 1 | FW5: 4 | FX5: 3 | FY5: 14 | FZ5: 10 | GA5: 16 | GB5: 9 | GC5: 50 | GD5: 50 | GE5: 0 | GF5: 100 | GG5: 08/05/2026 @ 7:33 AM
A6: 05.00.00-05.05.30 | C6: Stratified Out Usable N | D6: 2 | E6: 2 | F6: 7 | G6: 6 | H6: 0 | I6: 3 | J6: 2 | K6: 2 | L6: 3 | M6: 7 | N6: 9 | O6: 2 | P6: 3 | Q6: 3 | R6: 13 | S6: 4 | T6: 0 | U6: 17 | V6: 08/05/2026 @ 7:34 AM | AA6: 05.00.00-05.05.30 | AC6: Stratified Out Usable N | AD6: 0 | AE6: 0 | AF6: 3 | AG6: 0 | AH6: 0 | AI6: 0 | AJ6: 0 | AK6: 1 | AL6: 1 | AM6: 0 | AN6: 0 | AO6: 0 | AP6: 1 | AQ6: 1 | AR6: 0 | AS6: 2 | AT6: 1 | AU6: 0 | AV6: 0 | AW6: 0 | AX6: 0 | AY6: 1 | AZ6: 2 | BA6: 4 | BB6: 0 | BC6: 9 | BD6: 2 | BE6: 3 | BF6: 3 | BG6: 13 | BH6: 4 | BI6: 0 | BJ6: 17 | BK6: 08/05/2026 @ 7:34 AM | CA6: 05.00.00-05.05.30 | CC6: Stratified Out Usable N | CD6: 2 | CE6: 2 | CF6: 7 | CG6: 6 | CH6: 0 | CI6: 1 | CJ6: 2 | CK6: 1 | CL6: 1 | CM6: 0 | CN6: 2 | CO6: 2 | CP6: 1 | CQ6: 0 | CR6: 7 | CS6: 9 | CT6: 2 | CU6: 3 | CV6: 3 | CW6: 17 | CX6: 08/05/2026 @ 7:33 AM | DA6: 05.00.00-05.05.30 | DC6: Stratified Out Usable N | DD6: 0 | DE6: 2 | DF6: 6 | DG6: 5 | DH6: 0 | DI6: 2 | DJ6: 0 | DK6: 1 | DL6: 1 | DM6: 0 | DN6: 0 | DO6: 0 | DP6: 0 | DQ6: 0 | DR6: 0 | DS6: 3 | DT6: 2 | DU6: 2 | DV6: 3 | DW6: 7 | DX6: 9 | DY6: 2 | DZ6: 3 | EA6: 3 | EB6: 17 | EC6: 08/05/2026 @ 7:33 AM | FA6: 05.00.00-05.05.30 | FC6: Stratified Out Usable N | FD6: 2 | FE6: 2 | FF6: 7 | FG6: 6 | FH6: 0 | FI6: 0 | FJ6: 1 | FK6: 0 | FL6: 2 | FM6: 0 | FN6: 1 | FO6: 1 | FP6: 0 | FQ6: 1 | FR6: 0 | FS6: 1 | FT6: 0 | FU6: 2 | FV6: 0 | FW6: 0 | FX6: 1 | FY6: 6 | FZ6: 0 | GA6: 1 | GB6: 0 | GC6: 13 | GD6: 4 | GE6: 0 | GF6: 17 | GG6: 08/05/2026 @ 7:33 AM
A7: 05.00.00-05.05.30 | C7: In Process N | D7: 0 | E7: 0 | F7: 0 | G7: 0 | H7: 0 | I7: 0 | J7: 0 | K7: 0 | L7: 0 | M7: 0 | N7: 0 | O7: 0 | P7: 0 | Q7: 0 | R7: 0 | S7: 0 | T7: 0 | U7: 0 | V7: 08/05/2026 @ 7:34 AM | AA7: 05.00.00-05.05.30 | AC7: In Process N | AD7: 0 | AE7: 0 | AF7: 0 | AG7: 0 | AH7: 0 | AI7: 0 | AJ7: 0 | AK7: 0 | AL7: 0 | AM7: 0 | AN7: 0 | AO7: 0 | AP7: 0 | AQ7: 0 | AR7: 0 | AS7: 0 | AT7: 0 | AU7: 0 | AV7: 0 | AW7: 0 | AX7: 0 | AY7: 0 | AZ7: 0 | BA7: 0 | BB7: 0 | BC7: 0 | BD7: 0 | BE7: 0 | BF7: 0 | BG7: 0 | BH7: 0 | BI7: 0 | BJ7: 0 | BK7: 08/05/2026 @ 7:34 AM | CA7: 05.00.00-05.05.30 | CC7: In Process N | CD7: 0 | CE7: 0 | CF7: 0 | CG7: 0 | CH7: 0 | CI7: 0 | CJ7: 0 | CK7: 0 | CL7: 0 | CM7: 0 | CN7: 0 | CO7: 0 | CP7: 0 | CQ7: 0 | CR7: 0 | CS7: 0 | CT7: 0 | CU7: 0 | CV7: 0 | CW7: 0 | CX7: 08/05/2026 @ 7:33 AM | DA7: 05.00.00-05.05.30 | DC7: In Process N | DD7: 0 | DE7: 0 | DF7: 0 | DG7: 0 | DH7: 0 | DI7: 0 | DJ7: 0 | DK7: 0 | DL7: 0 | DM7: 0 | DN7: 0 | DO7: 0 | DP7: 0 | DQ7: 0 | DR7: 0 | DS7: 0 | DT7: 0 | DU7: 0 | DV7: 0 | DW7: 0 | DX7: 0 | DY7: 0 | DZ7: 0 | EA7: 0 | EB7: 0 | EC7: 08/05/2026 @ 7:33 AM | FA7: 05.00.00-05.05.30 | FC7: In Process N | FD7: 0 | FE7: 0 | FF7: 0 | FG7: 0 | FH7: 0 | FI7: 0 | FJ7: 0 | FK7: 0 | FL7: 0 | FM7: 0 | FN7: 0 | FO7: 0 | FP7: 0 | FQ7: 0 | FR7: 0 | FS7: 0 | FT7: 0 | FU7: 0 | FV7: 0 | FW7: 0 | FX7: 0 | FY7: 0 | FZ7: 0 | GA7: 0 | GB7: 0 | GC7: 0 | GD7: 0 | GE7: 0 | GF7: 0 | GG7: 08/05/2026 @ 7:33 AM
A8: 05.00.00-05.05.30 | C8: Assigned Not Recd N | D8: 0 | E8: 0 | F8: 0 | G8: 0 | H8: 0 | I8: 0 | J8: 0 | K8: 0 | L8: 0 | M8: 0 | N8: 0 | O8: 0 | P8: 0 | Q8: 0 | R8: 0 | S8: 0 | T8: 0 | U8: 0 | V8: 08/05/2026 @ 7:34 AM | AA8: 05.00.00-05.05.30 | AC8: Assigned Not Recd N | AD8: 0 | AE8: 0 | AF8: 0 | AG8: 0 | AH8: 0 | AI8: 0 | AJ8: 0 | AK8: 0 | AL8: 0 | AM8: 0 | AN8: 0 | AO8: 0 | AP8: 0 | AQ8: 0 | AR8: 0 | AS8: 0 | AT8: 0 | AU8: 0 | AV8: 0 | AW8: 0 | AX8: 0 | AY8: 0 | AZ8: 0 | BA8: 0 | BB8: 0 | BC8: 0 | BD8: 0 | BE8: 0 | BF8: 0 | BG8: 0 | BH8: 0 | BI8: 0 | BJ8: 0 | BK8: 08/05/2026 @ 7:34 AM | CA8: 05.00.00-05.05.30 | CC8: Assigned Not Recd N | CD8: 0 | CE8: 0 | CF8: 0 | CG8: 0 | CH8: 0 | CI8: 0 | CJ8: 0 | CK8: 0 | CL8: 0 | CM8: 0 | CN8: 0 | CO8: 0 | CP8: 0 | CQ8: 0 | CR8: 0 | CS8: 0 | CT8: 0 | CU8: 0 | CV8: 0 | CW8: 0 | CX8: 08/05/2026 @ 7:33 AM | DA8: 05.00.00-05.05.30 | DC8: Assigned Not Recd N | DD8: 0 | DE8: 0 | DF8: 0 | DG8: 0 | DH8: 0 | DI8: 0 | DJ8: 0 | DK8: 0 | DL8: 0 | DM8: 0 | DN8: 0 | DO8: 0 | DP8: 0 | DQ8: 0 | DR8: 0 | DS8: 0 | DT8: 0 | DU8: 0 | DV8: 0 | DW8: 0 | DX8: 0 | DY8: 0 | DZ8: 0 | EA8: 0 | EB8: 0 | EC8: 08/05/2026 @ 7:33 AM | FA8: 05.00.00-05.05.30 | FC8: Assigned Not Recd N | FD8: 0 | FE8: 0 | FF8: 0 | FG8: 0 | FH8: 0 | FI8: 0 | FJ8: 0 | FK8: 0 | FL8: 0 | FM8: 0 | FN8: 0 | FO8: 0 | FP8: 0 | FQ8: 0 | FR8: 0 | FS8: 0 | FT8: 0 | FU8: 0 | FV8: 0 | FW8: 0 | FX8: 0 | FY8: 0 | FZ8: 0 | GA8: 0 | GB8: 0 | GC8: 0 | GD8: 0 | GE8: 0 | GF8: 0 | GG8: 08/05/2026 @ 7:33 AM
A9: 05.00.00-05.05.30 | C9: Reserved Not Recd N | D9: 0 | E9: 0 | F9: 0 | G9: 0 | H9: 0 | I9: 0 | J9: 0 | K9: 0 | L9: 0 | M9: 0 | N9: 0 | O9: 0 | P9: 0 | Q9: 0 | R9: 0 | S9: 0 | T9: 0 | U9: 0 | V9: 08/05/2026 @ 7:34 AM | AA9: 05.00.00-05.05.30 | AC9: Reserved Not Recd N | AD9: 0 | AE9: 0 | AF9: 0 | AG9: 0 | AH9: 0 | AI9: 0 | AJ9: 0 | AK9: 0 | AL9: 0 | AM9: 0 | AN9: 0 | AO9: 0 | AP9: 0 | AQ9: 0 | AR9: 0 | AS9: 0 | AT9: 0 | AU9: 0 | AV9: 0 | AW9: 0 | AX9: 0 | AY9: 0 | AZ9: 0 | BA9: 0 | BB9: 0 | BC9: 0 | BD9: 0 | BE9: 0 | BF9: 0 | BG9: 0 | BH9: 0 | BI9: 0 | BJ9: 0 | BK9: 08/05/2026 @ 7:34 AM | CA9: 05.00.00-05.05.30 | CC9: Reserved Not Recd N | CD9: 0 | CE9: 0 | CF9: 0 | CG9: 0 | CH9: 0 | CI9: 0 | CJ9: 0 | CK9: 0 | CL9: 0 | CM9: 0 | CN9: 0 | CO9: 0 | CP9: 0 | CQ9: 0 | CR9: 0 | CS9: 0 | CT9: 0 | CU9: 0 | CV9: 0 | CW9: 0 | CX9: 08/05/2026 @ 7:33 AM | DA9: 05.00.00-05.05.30 | DC9: Reserved Not Recd N | DD9: 0 | DE9: 0 | DF9: 0 | DG9: 0 | DH9: 0 | DI9: 0 | DJ9: 0 | DK9: 0 | DL9: 0 | DM9: 0 | DN9: 0 | DO9: 0 | DP9: 0 | DQ9: 0 | DR9: 0 | DS9: 0 | DT9: 0 | DU9: 0 | DV9: 0 | DW9: 0 | DX9: 0 | DY9: 0 | DZ9: 0 | EA9: 0 | EB9: 0 | EC9: 08/05/2026 @ 7:33 AM | FA9: 05.00.00-05.05.30 | FC9: Reserved Not Recd N | FD9: 0 | FE9: 0 | FF9: 0 | FG9: 0 | FH9: 0 | FI9: 0 | FJ9: 0 | FK9: 0 | FL9: 0 | FM9: 0 | FN9: 0 | FO9: 0 | FP9: 0 | FQ9: 0 | FR9: 0 | FS9: 0 | FT9: 0 | FU9: 0 | FV9: 0 | FW9: 0 | FX9: 0 | FY9: 0 | FZ9: 0 | GA9: 0 | GB9: 0 | GC9: 0 | GD9: 0 | GE9: 0 | GF9: 0 | GG9: 08/05/2026 @ 7:33 AM
A10: 05.00.00-05.05.30 | C10: Total Assignments | D10: 10 | E10: 22 | F10: 39 | G10: 46 | H10: 0 | I10: 8 | J10: 15 | K10: 23 | L10: 15 | M10: 56 | N10: 29 | O10: 18 | P10: 44 | Q10: 26 | R10: 63 | S10: 54 | T10: 0 | U10: 117 | V10: 08/05/2026 @ 7:34 AM | AA10: 05.00.00-05.05.30 | AC10: Total Assignments | AD10: 1 | AE10: 0 | AF10: 4 | AG10: 3 | AH10: 0 | AI10: 1 | AJ10: 4 | AK10: 6 | AL10: 4 | AM10: 0 | AN10: 2 | AO10: 6 | AP10: 9 | AQ10: 6 | AR10: 0 | AS10: 4 | AT10: 3 | AU10: 3 | AV10: 5 | AW10: 0 | AX10: 2 | AY10: 9 | AZ10: 17 | BA10: 28 | BB10: 0 | BC10: 29 | BD10: 18 | BE10: 44 | BF10: 26 | BG10: 63 | BH10: 54 | BI10: 0 | BJ10: 117 | BK10: 08/05/2026 @ 7:34 AM | CA10: 05.00.00-05.05.30 | CC10: Total Assignments | CD10: 10 | CE10: 22 | CF10: 39 | CG10: 46 | CH10: 0 | CI10: 4 | CJ10: 4 | CK10: 8 | CL10: 7 | CM10: 12 | CN10: 11 | CO10: 6 | CP10: 9 | CQ10: 24 | CR10: 32 | CS10: 29 | CT10: 18 | CU10: 44 | CV10: 26 | CW10: 117 | CX10: 08/05/2026 @ 7:33 AM | DA10: 05.00.00-05.05.30 | DC10: Total Assignments | DD10: 4 | DE10: 11 | DF10: 25 | DG10: 23 | DH10: 0 | DI10: 6 | DJ10: 11 | DK10: 14 | DL10: 23 | DM10: 0 | DN10: 0 | DO10: 0 | DP10: 0 | DQ10: 0 | DR10: 0 | DS10: 8 | DT10: 15 | DU10: 23 | DV10: 15 | DW10: 56 | DX10: 29 | DY10: 18 | DZ10: 44 | EA10: 26 | EB10: 117 | EC10: 08/05/2026 @ 7:33 AM | FA10: 05.00.00-05.05.30 | FC10: Total Assignments | FD10: 10 | FE10: 22 | FF10: 39 | FG10: 46 | FH10: 0 | FI10: 1 | FJ10: 2 | FK10: 1 | FL10: 4 | FM10: 0 | FN10: 2 | FO10: 12 | FP10: 1 | FQ10: 2 | FR10: 3 | FS10: 10 | FT10: 8 | FU10: 6 | FV10: 1 | FW10: 4 | FX10: 4 | FY10: 20 | FZ10: 10 | GA10: 17 | GB10: 9 | GC10: 63 | GD10: 54 | GE10: 0 | GF10: 117 | GG10: 08/05/2026 @ 7:33 AM
A11: 05.00.00-05.05.30 | C11: Selected N | D11: 0 | E11: 0 | F11: 0 | G11: 0 | H11: 0 | I11: 0 | J11: 0 | K11: 0 | L11: 0 | M11: 0 | N11: 0 | O11: 0 | P11: 0 | Q11: 0 | R11: 0 | S11: 0 | T11: 0 | U11: 0 | V11: 08/05/2026 @ 7:34 AM | AA11: 05.00.00-05.05.30 | AC11: Selected N | AD11: 0 | AE11: 0 | AF11: 0 | AG11: 0 | AH11: 0 | AI11: 0 | AJ11: 0 | AK11: 0 | AL11: 0 | AM11: 0 | AN11: 0 | AO11: 0 | AP11: 0 | AQ11: 0 | AR11: 0 | AS11: 0 | AT11: 0 | AU11: 0 | AV11: 0 | AW11: 0 | AX11: 0 | AY11: 0 | AZ11: 0 | BA11: 0 | BB11: 0 | BC11: 0 | BD11: 0 | BE11: 0 | BF11: 0 | BG11: 0 | BH11: 0 | BI11: 0 | BJ11: 0 | BK11: 08/05/2026 @ 7:34 AM | CA11: 05.00.00-05.05.30 | CC11: Selected N | CD11: 0 | CE11: 0 | CF11: 0 | CG11: 0 | CH11: 0 | CI11: 0 | CJ11: 0 | CK11: 0 | CL11: 0 | CM11: 0 | CN11: 0 | CO11: 0 | CP11: 0 | CQ11: 0 | CR11: 0 | CS11: 0 | CT11: 0 | CU11: 0 | CV11: 0 | CW11: 0 | CX11: 08/05/2026 @ 7:33 AM | DA11: 05.00.00-05.05.30 | DC11: Selected N | DD11: 0 | DE11: 0 | DF11: 0 | DG11: 0 | DH11: 0 | DI11: 0 | DJ11: 0 | DK11: 0 | DL11: 0 | DM11: 0 | DN11: 0 | DO11: 0 | DP11: 0 | DQ11: 0 | DR11: 0 | DS11: 0 | DT11: 0 | DU11: 0 | DV11: 0 | DW11: 0 | DX11: 0 | DY11: 0 | DZ11: 0 | EA11: 0 | EB11: 0 | EC11: 08/05/2026 @ 7:33 AM | FA11: 05.00.00-05.05.30 | FC11: Selected N | FD11: 0 | FE11: 0 | FF11: 0 | FG11: 0 | FH11: 0 | FI11: 0 | FJ11: 0 | FK11: 0 | FL11: 0 | FM11: 0 | FN11: 0 | FO11: 0 | FP11: 0 | FQ11: 0 | FR11: 0 | FS11: 0 | FT11: 0 | FU11: 0 | FV11: 0 | FW11: 0 | FX11: 0 | FY11: 0 | FZ11: 0 | GA11: 0 | GB11: 0 | GC11: 0 | GD11: 0 | GE11: 0 | GF11: 0 | GG11: 08/05/2026 @ 7:33 AM
A12: 05.06.00-05.11.30 | C12: Target N | D12: 6.96 | E12: 19.98 | F12: 32.57 | G12: 40.48 | H12: 0 | I12: 4.58 | J12: 13.31 | K12: 23.1 | L12: 10.54 | M12: 48.47 | N12: 21.13 | O12: 15.8 | P12: 39.96 | Q12: 23.12 | R12: 50 | S12: 50 | T12: 0 | U12: 100 | V12: 08/05/2026 @ 7:34 AM | AA12: 05.06.00-05.11.30 | AC12: Target N | AD12: 0.24 | AE12: 0.42 | AF12: 0.77 | AG12: 3.15 | AH12: 0 | AI12: 1.24 | AJ12: 3.68 | AK12: 5.19 | AL12: 3.19 | AM12: 0 | AN12: 3.41 | AO12: 6.58 | AP12: 7.75 | AQ12: 5.36 | AR12: 0 | AS12: 0.51 | AT12: 1.94 | AU12: 3.47 | AV12: 4.62 | AW12: 0 | AX12: 1.55 | AY12: 7.37 | AZ12: 15.39 | BA12: 24.17 | BB12: 0 | BC12: 21.13 | BD12: 15.8 | BE12: 39.96 | BF12: 23.12 | BG12: 50 | BH12: 50 | BI12: 0 | BJ12: 100 | BK12: 08/05/2026 @ 7:34 AM | CA12: 05.06.00-05.11.30 | CC12: Target N | CD12: 6.96 | CE12: 19.98 | CF12: 32.57 | CG12: 40.48 | CH12: 0 | CI12: 2.29 | CJ12: 2.29 | CK12: 6.65 | CL12: 6.65 | CM12: 11.55 | CN12: 11.55 | CO12: 5.27 | CP12: 5.27 | CQ12: 24.23 | CR12: 24.23 | CS12: 21.13 | CT12: 15.8 | CU12: 39.96 | CV12: 23.12 | CW12: 100 | CX12: 08/05/2026 @ 7:33 AM | DA12: 05.06.00-05.11.30 | DC12: Target N | DD12: 3.48 | DE12: 9.99 | DF12: 16.29 | DG12: 20.24 | DH12: 0 | DI12: 3.48 | DJ12: 9.99 | DK12: 16.29 | DL12: 20.24 | DM12: 0 | DN12: 0 | DO12: 0 | DP12: 0 | DQ12: 0 | DR12: 0 | DS12: 4.58 | DT12: 13.31 | DU12: 23.1 | DV12: 10.54 | DW12: 48.47 | DX12: 21.13 | DY12: 15.8 | DZ12: 39.96 | EA12: 23.12 | EB12: 100 | EC12: 08/05/2026 @ 7:33 AM | FA12: 05.06.00-05.11.30 | FC12: Target N | FD12: 6.96 | FE12: 19.98 | FF12: 32.57 | FG12: 40.48 | FH12: 0 | FI12: 0.55 | FJ12: 0.88 | FK12: 1.25 | FL12: 1.9 | FM12: 2.62 | FN12: 1.74 | FO12: 8.06 | FP12: 0.89 | FQ12: 2.58 | FR12: 3.3 | FS12: 8.85 | FT12: 8.37 | FU12: 1.97 | FV12: 1.64 | FW12: 3.7 | FX12: 3.23 | FY12: 13.41 | FZ12: 8.24 | GA12: 18.09 | GB12: 8.72 | GC12: 50 | GD12: 50 | GE12: 0 | GF12: 100 | GG12: 08/05/2026 @ 7:33 AM
A13: 05.06.00-05.11.30 | C13: Stratified Usable N | D13: 6 | E13: 21 | F13: 29 | G13: 44 | H13: 0 | I13: 5 | J13: 14 | K13: 23 | L13: 10 | M13: 48 | N13: 22 | O13: 16 | P13: 41 | Q13: 21 | R13: 50 | S13: 50 | T13: 0 | U13: 100 | V13: 08/05/2026 @ 7:34 AM | AA13: 05.06.00-05.11.30 | AC13: Stratified Usable N | AD13: 0 | AE13: 1 | AF13: 1 | AG13: 3 | AH13: 0 | AI13: 1 | AJ13: 4 | AK13: 2 | AL13: 7 | AM13: 0 | AN13: 3 | AO13: 7 | AP13: 8 | AQ13: 5 | AR13: 0 | AS13: 0 | AT13: 2 | AU13: 3 | AV13: 5 | AW13: 0 | AX13: 2 | AY13: 7 | AZ13: 15 | BA13: 24 | BB13: 0 | BC13: 22 | BD13: 16 | BE13: 41 | BF13: 21 | BG13: 50 | BH13: 50 | BI13: 0 | BJ13: 100 | BK13: 08/05/2026 @ 7:34 AM | CA13: 05.06.00-05.11.30 | CC13: Stratified Usable N | CD13: 6 | CE13: 21 | CF13: 29 | CG13: 44 | CH13: 0 | CI13: 3 | CJ13: 2 | CK13: 7 | CL13: 7 | CM13: 8 | CN13: 15 | CO13: 6 | CP13: 4 | CQ13: 26 | CR13: 22 | CS13: 22 | CT13: 16 | CU13: 41 | CV13: 21 | CW13: 100 | CX13: 08/05/2026 @ 7:33 AM | DA13: 05.06.00-05.11.30 | DC13: Stratified Usable N | DD13: 1 | DE13: 11 | DF13: 17 | DG13: 21 | DH13: 0 | DI13: 5 | DJ13: 10 | DK13: 12 | DL13: 23 | DM13: 0 | DN13: 0 | DO13: 0 | DP13: 0 | DQ13: 0 | DR13: 0 | DS13: 5 | DT13: 14 | DU13: 23 | DV13: 10 | DW13: 48 | DX13: 22 | DY13: 16 | DZ13: 41 | EA13: 21 | EB13: 100 | EC13: 08/05/2026 @ 7:33 AM | FA13: 05.06.00-05.11.30 | FC13: Stratified Usable N | FD13: 6 | FE13: 21 | FF13: 29 | FG13: 44 | FH13: 0 | FI13: 1 | FJ13: 2 | FK13: 1 | FL13: 1 | FM13: 3 | FN13: 0 | FO13: 11 | FP13: 0 | FQ13: 2 | FR13: 3 | FS13: 12 | FT13: 6 | FU13: 2 | FV13: 3 | FW13: 2 | FX13: 3 | FY13: 14 | FZ13: 8 | GA13: 15 | GB13: 11 | GC13: 50 | GD13: 50 | GE13: 0 | GF13: 100 | GG13: 08/05/2026 @ 7:33 AM
A14: 05.06.00-05.11.30 | C14: Stratified Out Usable N | D14: 1 | E14: 5 | F14: 4 | G14: 5 | H14: 0 | I14: 1 | J14: 0 | K14: 3 | L14: 6 | M14: 5 | N14: 5 | O14: 0 | P14: 10 | Q14: 0 | R14: 11 | S14: 4 | T14: 0 | U14: 15 | V14: 08/05/2026 @ 7:34 AM | AA14: 05.06.00-05.11.30 | AC14: Stratified Out Usable N | AD14: 0 | AE14: 0 | AF14: 0 | AG14: 1 | AH14: 0 | AI14: 0 | AJ14: 0 | AK14: 0 | AL14: 0 | AM14: 0 | AN14: 1 | AO14: 2 | AP14: 0 | AQ14: 0 | AR14: 0 | AS14: 0 | AT14: 0 | AU14: 2 | AV14: 4 | AW14: 0 | AX14: 0 | AY14: 3 | AZ14: 2 | BA14: 0 | BB14: 0 | BC14: 5 | BD14: 0 | BE14: 10 | BF14: 0 | BG14: 11 | BH14: 4 | BI14: 0 | BJ14: 15 | BK14: 08/05/2026 @ 7:34 AM | CA14: 05.06.00-05.11.30 | CC14: Stratified Out Usable N | CD14: 1 | CE14: 5 | CF14: 4 | CG14: 5 | CH14: 0 | CI14: 1 | CJ14: 0 | CK14: 0 | CL14: 0 | CM14: 0 | CN14: 3 | CO14: 2 | CP14: 4 | CQ14: 1 | CR14: 4 | CS14: 5 | CT14: 0 | CU14: 10 | CV14: 0 | CW14: 15 | CX14: 08/05/2026 @ 7:33 AM | DA14: 05.06.00-05.11.30 | DC14: Stratified Out Usable N | DD14: 1 | DE14: 5 | DF14: 3 | DG14: 2 | DH14: 0 | DI14: 0 | DJ14: 0 | DK14: 1 | DL14: 3 | DM14: 0 | DN14: 0 | DO14: 0 | DP14: 0 | DQ14: 0 | DR14: 0 | DS14: 1 | DT14: 0 | DU14: 3 | DV14: 6 | DW14: 5 | DX14: 5 | DY14: 0 | DZ14: 10 | EA14: 0 | EB14: 15 | EC14: 08/05/2026 @ 7:33 AM | FA14: 05.06.00-05.11.30 | FC14: Stratified Out Usable N | FD14: 1 | FE14: 5 | FF14: 4 | FG14: 5 | FH14: 0 | FI14: 1 | FJ14: 0 | FK14: 0 | FL14: 0 | FM14: 0 | FN14: 0 | FO14: 0 | FP14: 0 | FQ14: 0 | FR14: 0 | FS14: 3 | FT14: 0 | FU14: 2 | FV14: 0 | FW14: 4 | FX14: 0 | FY14: 2 | FZ14: 0 | GA14: 3 | GB14: 0 | GC14: 11 | GD14: 4 | GE14: 0 | GF14: 15 | GG14: 08/05/2026 @ 7:33 AM
A15: 05.06.00-05.11.30 | C15: In Process N | D15: 0 | E15: 0 | F15: 0 | G15: 0 | H15: 0 | I15: 0 | J15: 0 | K15: 0 | L15: 0 | M15: 0 | N15: 0 | O15: 0 | P15: 0 | Q15: 0 | R15: 0 | S15: 0 | T15: 0 | U15: 0 | V15: 08/05/2026 @ 7:34 AM | AA15: 05.06.00-05.11.30 | AC15: In Process N | AD15: 0 | AE15: 0 | AF15: 0 | AG15: 0 | AH15: 0 | AI15: 0 | AJ15: 0 | AK15: 0 | AL15: 0 | AM15: 0 | AN15: 0 | AO15: 0 | AP15: 0 | AQ15: 0 | AR15: 0 | AS15: 0 | AT15: 0 | AU15: 0 | AV15: 0 | AW15: 0 | AX15: 0 | AY15: 0 | AZ15: 0 | BA15: 0 | BB15: 0 | BC15: 0 | BD15: 0 | BE15: 0 | BF15: 0 | BG15: 0 | BH15: 0 | BI15: 0 | BJ15: 0 | BK15: 08/05/2026 @ 7:34 AM | CA15: 05.06.00-05.11.30 | CC15: In Process N | CD15: 0 | CE15: 0 | CF15: 0 | CG15: 0 | CH15: 0 | CI15: 0 | CJ15: 0 | CK15: 0 | CL15: 0 | CM15: 0 | CN15: 0 | CO15: 0 | CP15: 0 | CQ15: 0 | CR15: 0 | CS15: 0 | CT15: 0 | CU15: 0 | CV15: 0 | CW15: 0 | CX15: 08/05/2026 @ 7:33 AM | DA15: 05.06.00-05.11.30 | DC15: In Process N | DD15: 0 | DE15: 0 | DF15: 0 | DG15: 0 | DH15: 0 | DI15: 0 | DJ15: 0 | DK15: 0 | DL15: 0 | DM15: 0 | DN15: 0 | DO15: 0 | DP15: 0 | DQ15: 0 | DR15: 0 | DS15: 0 | DT15: 0 | DU15: 0 | DV15: 0 | DW15: 0 | DX15: 0 | DY15: 0 | DZ15: 0 | EA15: 0 | EB15: 0 | EC15: 08/05/2026 @ 7:33 AM | FA15: 05.06.00-05.11.30 | FC15: In Process N | FD15: 0 | FE15: 0 | FF15: 0 | FG15: 0 | FH15: 0 | FI15: 0 | FJ15: 0 | FK15: 0 | FL15: 0 | FM15: 0 | FN15: 0 | FO15: 0 | FP15: 0 | FQ15: 0 | FR15: 0 | FS15: 0 | FT15: 0 | FU15: 0 | FV15: 0 | FW15: 0 | FX15: 0 | FY15: 0 | FZ15: 0 | GA15: 0 | GB15: 0 | GC15: 0 | GD15: 0 | GE15: 0 | GF15: 0 | GG15: 08/05/2026 @ 7:33 AM
... A59: Total | C59: Selected N | D59: 0 | E59: 0 | F59: 0 | G59: 0 | H59: 0 | I59: 0 | J59: 0 | K59: 0 | L59: 0 | M59: 0 | N59: 0 | O59: 0 | P59: 0 | Q59: 0 | R59: 0 | S59: 0 | T59: 0 | U59: 0 | V59: 08/05/2026 @ 7:34 AM | AA59: Total | AC59: Selected N | AD59: 0 | AE59: 0 | AF59: 0 | AG59: 0 | AH59: 0 | AI59: 0 | AJ59: 0 | AK59: 0 | AL59: 0 | AM59: 0 | AN59: 0 | AO59: 0 | AP59: 0 | AQ59: 0 | AR59: 0 | AS59: 0 | AT59: 0 | AU59: 0 | AV59: 0 | AW59: 0 | AX59: 0 | AY59: 0 | AZ59: 0 | BA59: 0 | BB59: 0 | BC59: 0 | BD59: 0 | BE59: 0 | BF59: 0 | BG59: 0 | BH59: 0 | BI59: 0 | BJ59: 0 | BK59: 08/05/2026 @ 7:34 AM | CA59: Total | CC59: Selected N | CD59: 0 | CE59: 0 | CF59: 0 | CG59: 0 | CH59: 0 | CI59: 0 | CJ59: 0 | CK59: 0 | CL59: 0 | CM59: 0 | CN59: 0 | CO59: 0 | CP59: 0 | CQ59: 0 | CR59: 0 | CS59: 0 | CT59: 0 | CU59: 0 | CV59: 0 | CW59: 0 | CX59: 08/05/2026 @ 7:33 AM | DA59: Total | DC59: Selected N | DD59: 0 | DE59: 0 | DF59: 0 | DG59: 0 | DH59: 0 | DI59: 0 | DJ59: 0 | DK59: 0 | DL59: 0 | DM59: 0 | DN59: 0 | DO59: 0 | DP59: 0 | DQ59: 0 | DR59: 0 | DS59: 0 | DT59: 0 | DU59: 0 | DV59: 0 | DW59: 0 | DX59: 0 | DY59: 0 | DZ59: 0 | EA59: 0 | EB59: 0 | EC59: 08/05/2026 @ 7:33 AM | FA59: Total | FC59: Selected N | FD59: 0 | FE59: 0 | FF59: 0 | FG59: 0 | FH59: 0 | FI59: 0 | FJ59: 0 | FK59: 0 | FL59: 0 | FM59: 0 | FN59: 0 | FO59: 0 | FP59: 0 | FQ59: 0 | FR59: 0 | FS59: 0 | FT59: 0 | FU59: 0 | FV59: 0 | FW59: 0 | FX59: 0 | FY59: 0 | FZ59: 0 | GA59: 0 | GB59: 0 | GC59: 0 | GD59: 0 | GE59: 0 | GF59: 0 | GG59: 08/05/2026 @ 7:33 AM
G128: CELF-6 Standardization Record Form 2 (Ages 9-21) - CELF6_RF2_STDZ | AK128: CELF6_STDZ_Eth_by_Ed | CJ128: CELF6_STDZ_Sex_by_Eth | DL128: CELF6_STDZ_Sex_by_Ed | FK128: CELF6_STDZ_Eth_by_Reg
A129: =setup!C17 -> 3726 | AA129: =setup!C17 -> 3726 | CA129: =setup!C17 -> 3726 | DA129: 3726 | FA129: 3726
A130: =_xlfn.CONCAT(setup!D17," - ",setup!E17) -> CELF-6 Standardization Record Form 2 (Ages 9-21) - CELF6_RF2_STDZ | AA130: =_xlfn.CONCAT(setup!D17," - ",setup!E17) -> CELF-6 Standardization Record Form 2 (Ages 9-21) - CELF6_RF2_STDZ | CA130: =_xlfn.CONCAT(setup!D17," - ",setup!E17) -> CELF-6 Standardization Record Form 2 (Ages 9-21) - CELF6_RF2_STDZ | DA130: CELF-6 Standardization Record Form 2 (Ages 9-21) - CELF6_RF2_STDZ | FA130: CELF-6 Standardization Record Form 2 (Ages 9-21) - CELF6_RF2_STDZ
A131: ageband | B131: gradeband | C131: report | D131: 1 | E131: 2 | F131: 3 | G131: 4 | H131: 5 | I131: AS | J131: BL | K131: HI | L131: OT | M131: WH | N131: MW | O131: NE | P131: SO | Q131: WE | R131: F | S131: M | T131: OTHER | U131: Total | V131: LastRefreshed | AA131: ageband | AB131: gradeband | AC131: report | AD131: AS1 | AE131: AS2 | AF131: AS3 | AG131: AS4 | AH131: AS5 | AI131: BL1 | AJ131: BL2 | AK131: BL3 | AL131: BL4 | AM131: BL5 | AN131: HI1 | AO131: HI2 | AP131: HI3 | AQ131: HI4 | AR131: HI5 | AS131: OT1 | AT131: OT2 | AU131: OT3 | AV131: OT4 | AW131: OT5 | AX131: WH1 | AY131: WH2 | AZ131: WH3 | BA131: WH4 | BB131: WH5 | BC131: MW | BD131: NE | BE131: SO | BF131: WE | BG131: F | BH131: M | BI131: OTHER | BJ131: Total | BK131: LastRefreshed | CA131: ageband | CB131: gradeband | CC131: report | CD131: 1 | CE131: 2 | CF131: 3 | CG131: 4 | CH131: 5 | CI131: MAS | CJ131: FAS | CK131: MBL | CL131: FBL | CM131: MHI | CN131: FHI | CO131: MOT | CP131: FOT | CQ131: MWH | CR131: FWH | CS131: MW | CT131: NE | CU131: SO | CV131: WE | CW131: Total | CX131: LastRefreshed | DA131: ageband | DB131: gradeband | DC131: report | DD131: F1 | DE131: F2 | DF131: F3 | DG131: F4 | DH131: F5 | DI131: M1 | DJ131: M2 | DK131: M3 | DL131: M4 | DM131: M5 | DN131: OTHER1 | DO131: OTHER2 | DP131: OTHER3 | DQ131: OTHER4 | DR131: OTHER5 | DS131: AS | DT131: BL | DU131: HI | DV131: OT | DW131: WH | DX131: MW | DY131: NE | DZ131: SO | EA131: WE | EB131: Total | EC131: LastRefreshed | FA131: ageband | FB131: gradeband | FC131: report | FD131: 1 | FE131: 2 | FF131: 3 | FG131: 4 | FH131: 5 | FI131: ASMW | FJ131: ASNE | FK131: ASSO | FL131: ASWE | FM131: BLMW | FN131: BLNE | FO131: BLSO | FP131: BLWE | FQ131: HIMW | FR131: HINE | FS131: HISO | FT131: HIWE | FU131: OTMW | FV131: OTNE | FW131: OTSO | FX131: OTWE | FY131: WHMW | FZ131: WHNE | GA131: WHSO | GB131: WHWE | GC131: F | GD131: M | GE131: OTHER | GF131: Total | GG131: LastRefreshed
A132: 09.00.00-09.11.30 | C132: Target N | D132: 8.29 | E132: 20.14 | F132: 31.94 | G132: 39.63 | H132: 0 | I132: 5.08 | J132: 12.66 | K132: 24 | L132: 9.92 | M132: 48.34 | N132: 21.61 | O132: 15.54 | P132: 39.7 | Q132: 23.16 | R132: 50 | S132: 50 | T132: 0 | U132: 100 | V132: 08/05/2026 @ 7:34 AM | AA132: 09.00.00-09.11.30 | AC132: Target N | AD132: 0.36 | AE132: 0.61 | AF132: 0.83 | AG132: 3.29 | AH132: 0 | AI132: 1.05 | AJ132: 3.73 | AK132: 4.79 | AL132: 3.08 | AM132: 0 | AN132: 4.78 | AO132: 6.73 | AP132: 7.33 | AQ132: 5.15 | AR132: 0 | AS132: 0.54 | AT132: 1.85 | AU132: 3.53 | AV132: 4.01 | AW132: 0 | AX132: 1.56 | AY132: 7.22 | AZ132: 15.46 | BA132: 24.1 | BB132: 0 | BC132: 21.61 | BD132: 15.54 | BE132: 39.7 | BF132: 23.16 | BG132: 50 | BH132: 50 | BI132: 0 | BJ132: 100 | BK132: 08/05/2026 @ 7:33 AM | CA132: 09.00.00-09.11.30 | CC132: Target N | CD132: 8.29 | CE132: 20.14 | CF132: 31.94 | CG132: 39.63 | CH132: 0 | CI132: 2.54 | CJ132: 2.54 | CK132: 6.33 | CL132: 6.33 | CM132: 12 | CN132: 12 | CO132: 4.96 | CP132: 4.96 | CQ132: 24.17 | CR132: 24.17 | CS132: 21.61 | CT132: 15.54 | CU132: 39.7 | CV132: 23.16 | CW132: 100 | CX132: 08/05/2026 @ 7:33 AM | DA132: 09.00.00-09.11.30 | DC132: Target N | DD132: 4.15 | DE132: 10.07 | DF132: 15.97 | DG132: 19.81 | DH132: 0 | DI132: 4.15 | DJ132: 10.07 | DK132: 15.97 | DL132: 19.81 | DM132: 0 | DN132: 0 | DO132: 0 | DP132: 0 | DQ132: 0 | DR132: 0 | DS132: 5.08 | DT132: 12.66 | DU132: 24 | DV132: 9.92 | DW132: 48.34 | DX132: 21.61 | DY132: 15.54 | DZ132: 39.7 | EA132: 23.16 | EB132: 100 | EC132: 08/05/2026 @ 7:33 AM | FA132: 09.00.00-09.11.30 | FC132: Target N | FD132: 8.29 | FE132: 20.14 | FF132: 31.94 | FG132: 39.63 | FH132: 0 | FI132: 0.69 | FJ132: 1.06 | FK132: 1.41 | FL132: 1.93 | FM132: 2.31 | FN132: 1.6 | FO132: 7.76 | FP132: 0.99 | FQ132: 2.91 | FR132: 3.24 | FS132: 9.12 | FT132: 8.72 | FU132: 1.96 | FV132: 1.33 | FW132: 3.66 | FX132: 2.97 | FY132: 13.73 | FZ132: 8.31 | GA132: 17.75 | GB132: 8.54 | GC132: 50 | GD132: 50 | GE132: 0 | GF132: 100 | GG132: 08/05/2026 @ 7:33 AM
A133: 09.00.00-09.11.30 | C133: Stratified Usable N | D133: 8 | E133: 21 | F133: 32 | G133: 39 | H133: 0 | I133: 6 | J133: 13 | K133: 24 | L133: 11 | M133: 46 | N133: 23 | O133: 14 | P133: 40 | Q133: 23 | R133: 50 | S133: 50 | T133: 0 | U133: 100 | V133: 08/05/2026 @ 7:34 AM | AA133: 09.00.00-09.11.30 | AC133: Stratified Usable N | AD133: 1 | AE133: 1 | AF133: 1 | AG133: 3 | AH133: 0 | AI133: 1 | AJ133: 4 | AK133: 5 | AL133: 3 | AM133: 0 | AN133: 5 | AO133: 7 | AP133: 7 | AQ133: 5 | AR133: 0 | AS133: 1 | AT133: 2 | AU133: 4 | AV133: 4 | AW133: 0 | AX133: 0 | AY133: 7 | AZ133: 15 | BA133: 24 | BB133: 0 | BC133: 23 | BD133: 14 | BE133: 40 | BF133: 23 | BG133: 50 | BH133: 50 | BI133: 0 | BJ133: 100 | BK133: 08/05/2026 @ 7:33 AM | CA133: 09.00.00-09.11.30 | CC133: Stratified Usable N | CD133: 8 | CE133: 21 | CF133: 32 | CG133: 39 | CH133: 0 | CI133: 3 | CJ133: 3 | CK133: 6 | CL133: 7 | CM133: 12 | CN133: 12 | CO133: 6 | CP133: 5 | CQ133: 23 | CR133: 23 | CS133: 23 | CT133: 14 | CU133: 40 | CV133: 23 | CW133: 100 | CX133: 08/05/2026 @ 7:33 AM | DA133: 09.00.00-09.11.30 | DC133: Stratified Usable N | DD133: 1 | DE133: 12 | DF133: 19 | DG133: 18 | DH133: 0 | DI133: 7 | DJ133: 9 | DK133: 13 | DL133: 21 | DM133: 0 | DN133: 0 | DO133: 0 | DP133: 0 | DQ133: 0 | DR133: 0 | DS133: 6 | DT133: 13 | DU133: 24 | DV133: 11 | DW133: 46 | DX133: 23 | DY133: 14 | DZ133: 40 | EA133: 23 | EB133: 100 | EC133: 08/05/2026 @ 7:33 AM | FA133: 09.00.00-09.11.30 | FC133: Stratified Usable N | FD133: 8 | FE133: 21 | FF133: 32 | FG133: 39 | FH133: 0 | FI133: 1 | FJ133: 0 | FK133: 2 | FL133: 3 | FM133: 2 | FN133: 3 | FO133: 7 | FP133: 1 | FQ133: 4 | FR133: 3 | FS133: 7 | FT133: 10 | FU133: 3 | FV133: 0 | FW133: 6 | FX133: 2 | FY133: 13 | FZ133: 8 | GA133: 18 | GB133: 7 | GC133: 50 | GD133: 50 | GE133: 0 | GF133: 100 | GG133: 08/05/2026 @ 7:33 AM
A134: 09.00.00-09.11.30 | C134: Stratified Out Usable N | D134: 2 | E134: 6 | F134: 13 | G134: 9 | H134: 0 | I134: 0 | J134: 5 | K134: 8 | L134: 1 | M134: 16 | N134: 7 | O134: 3 | P134: 13 | Q134: 7 | R134: 16 | S134: 14 | T134: 0 | U134: 30 | V134: 08/05/2026 @ 7:34 AM | AA134: 09.00.00-09.11.30 | AC134: Stratified Out Usable N | AD134: 0 | AE134: 0 | AF134: 0 | AG134: 0 | AH134: 0 | AI134: 0 | AJ134: 1 | AK134: 3 | AL134: 1 | AM134: 0 | AN134: 2 | AO134: 2 | AP134: 2 | AQ134: 2 | AR134: 0 | AS134: 0 | AT134: 0 | AU134: 0 | AV134: 1 | AW134: 0 | AX134: 0 | AY134: 3 | AZ134: 8 | BA134: 5 | BB134: 0 | BC134: 7 | BD134: 3 | BE134: 13 | BF134: 7 | BG134: 16 | BH134: 14 | BI134: 0 | BJ134: 30 | BK134: 08/05/2026 @ 7:33 AM | CA134: 09.00.00-09.11.30 | CC134: Stratified Out Usable N | CD134: 2 | CE134: 6 | CF134: 13 | CG134: 9 | CH134: 0 | CI134: 0 | CJ134: 0 | CK134: 3 | CL134: 2 | CM134: 4 | CN134: 4 | CO134: 0 | CP134: 1 | CQ134: 7 | CR134: 9 | CS134: 7 | CT134: 3 | CU134: 13 | CV134: 7 | CW134: 30 | CX134: 08/05/2026 @ 7:33 AM | DA134: 09.00.00-09.11.30 | DC134: Stratified Out Usable N | DD134: 1 | DE134: 3 | DF134: 5 | DG134: 7 | DH134: 0 | DI134: 1 | DJ134: 3 | DK134: 8 | DL134: 2 | DM134: 0 | DN134: 0 | DO134: 0 | DP134: 0 | DQ134: 0 | DR134: 0 | DS134: 0 | DT134: 5 | DU134: 8 | DV134: 1 | DW134: 16 | DX134: 7 | DY134: 3 | DZ134: 13 | EA134: 7 | EB134: 30 | EC134: 08/05/2026 @ 7:33 AM | FA134: 09.00.00-09.11.30 | FC134: Stratified Out Usable N | FD134: 2 | FE134: 6 | FF134: 13 | FG134: 9 | FH134: 0 | FI134: 0 | FJ134: 0 | FK134: 0 | FL134: 0 | FM134: 2 | FN134: 0 | FO134: 3 | FP134: 0 | FQ134: 1 | FR134: 0 | FS134: 4 | FT134: 3 | FU134: 0 | FV134: 1 | FW134: 0 | FX134: 0 | FY134: 4 | FZ134: 2 | GA134: 6 | GB134: 4 | GC134: 16 | GD134: 14 | GE134: 0 | GF134: 30 | GG134: 08/05/2026 @ 7:33 AM
A135: 09.00.00-09.11.30 | C135: In Process N | D135: 0 | E135: 0 | F135: 0 | G135: 0 | H135: 0 | I135: 0 | J135: 0 | K135: 0 | L135: 0 | M135: 0 | N135: 0 | O135: 0 | P135: 0 | Q135: 0 | R135: 0 | S135: 0 | T135: 0 | U135: 0 | V135: 08/05/2026 @ 7:34 AM | AA135: 09.00.00-09.11.30 | AC135: In Process N | AD135: 0 | AE135: 0 | AF135: 0 | AG135: 0 | AH135: 0 | AI135: 0 | AJ135: 0 | AK135: 0 | AL135: 0 | AM135: 0 | AN135: 0 | AO135: 0 | AP135: 0 | AQ135: 0 | AR135: 0 | AS135: 0 | AT135: 0 | AU135: 0 | AV135: 0 | AW135: 0 | AX135: 0 | AY135: 0 | AZ135: 0 | BA135: 0 | BB135: 0 | BC135: 0 | BD135: 0 | BE135: 0 | BF135: 0 | BG135: 0 | BH135: 0 | BI135: 0 | BJ135: 0 | BK135: 08/05/2026 @ 7:33 AM | CA135: 09.00.00-09.11.30 | CC135: In Process N | CD135: 0 | CE135: 0 | CF135: 0 | CG135: 0 | CH135: 0 | CI135: 0 | CJ135: 0 | CK135: 0 | CL135: 0 | CM135: 0 | CN135: 0 | CO135: 0 | CP135: 0 | CQ135: 0 | CR135: 0 | CS135: 0 | CT135: 0 | CU135: 0 | CV135: 0 | CW135: 0 | CX135: 08/05/2026 @ 7:33 AM | DA135: 09.00.00-09.11.30 | DC135: In Process N | DD135: 0 | DE135: 0 | DF135: 0 | DG135: 0 | DH135: 0 | DI135: 0 | DJ135: 0 | DK135: 0 | DL135: 0 | DM135: 0 | DN135: 0 | DO135: 0 | DP135: 0 | DQ135: 0 | DR135: 0 | DS135: 0 | DT135: 0 | DU135: 0 | DV135: 0 | DW135: 0 | DX135: 0 | DY135: 0 | DZ135: 0 | EA135: 0 | EB135: 0 | EC135: 08/05/2026 @ 7:33 AM | FA135: 09.00.00-09.11.30 | FC135: In Process N | FD135: 0 | FE135: 0 | FF135: 0 | FG135: 0 | FH135: 0 | FI135: 0 | FJ135: 0 | FK135: 0 | FL135: 0 | FM135: 0 | FN135: 0 | FO135: 0 | FP135: 0 | FQ135: 0 | FR135: 0 | FS135: 0 | FT135: 0 | FU135: 0 | FV135: 0 | FW135: 0 | FX135: 0 | FY135: 0 | FZ135: 0 | GA135: 0 | GB135: 0 | GC135: 0 | GD135: 0 | GE135: 0 | GF135: 0 | GG135: 08/05/2026 @ 7:33 AM
A136: 09.00.00-09.11.30 | C136: Assigned Not Recd N | D136: 0 | E136: 0 | F136: 0 | G136: 0 | H136: 0 | I136: 0 | J136: 0 | K136: 0 | L136: 0 | M136: 0 | N136: 0 | O136: 0 | P136: 0 | Q136: 0 | R136: 0 | S136: 0 | T136: 0 | U136: 0 | V136: 08/05/2026 @ 7:34 AM | AA136: 09.00.00-09.11.30 | AC136: Assigned Not Recd N | AD136: 0 | AE136: 0 | AF136: 0 | AG136: 0 | AH136: 0 | AI136: 0 | AJ136: 0 | AK136: 0 | AL136: 0 | AM136: 0 | AN136: 0 | AO136: 0 | AP136: 0 | AQ136: 0 | AR136: 0 | AS136: 0 | AT136: 0 | AU136: 0 | AV136: 0 | AW136: 0 | AX136: 0 | AY136: 0 | AZ136: 0 | BA136: 0 | BB136: 0 | BC136: 0 | BD136: 0 | BE136: 0 | BF136: 0 | BG136: 0 | BH136: 0 | BI136: 0 | BJ136: 0 | BK136: 08/05/2026 @ 7:33 AM | CA136: 09.00.00-09.11.30 | CC136: Assigned Not Recd N | CD136: 0 | CE136: 0 | CF136: 0 | CG136: 0 | CH136: 0 | CI136: 0 | CJ136: 0 | CK136: 0 | CL136: 0 | CM136: 0 | CN136: 0 | CO136: 0 | CP136: 0 | CQ136: 0 | CR136: 0 | CS136: 0 | CT136: 0 | CU136: 0 | CV136: 0 | CW136: 0 | CX136: 08/05/2026 @ 7:33 AM | DA136: 09.00.00-09.11.30 | DC136: Assigned Not Recd N | DD136: 0 | DE136: 0 | DF136: 0 | DG136: 0 | DH136: 0 | DI136: 0 | DJ136: 0 | DK136: 0 | DL136: 0 | DM136: 0 | DN136: 0 | DO136: 0 | DP136: 0 | DQ136: 0 | DR136: 0 | DS136: 0 | DT136: 0 | DU136: 0 | DV136: 0 | DW136: 0 | DX136: 0 | DY136: 0 | DZ136: 0 | EA136: 0 | EB136: 0 | EC136: 08/05/2026 @ 7:33 AM | FA136: 09.00.00-09.11.30 | FC136: Assigned Not Recd N | FD136: 0 | FE136: 0 | FF136: 0 | FG136: 0 | FH136: 0 | FI136: 0 | FJ136: 0 | FK136: 0 | FL136: 0 | FM136: 0 | FN136: 0 | FO136: 0 | FP136: 0 | FQ136: 0 | FR136: 0 | FS136: 0 | FT136: 0 | FU136: 0 | FV136: 0 | FW136: 0 | FX136: 0 | FY136: 0 | FZ136: 0 | GA136: 0 | GB136: 0 | GC136: 0 | GD136: 0 | GE136: 0 | GF136: 0 | GG136: 08/05/2026 @ 7:33 AM
A137: 09.00.00-09.11.30 | C137: Reserved Not Recd N | D137: 0 | E137: 0 | F137: 0 | G137: 0 | H137: 0 | I137: 0 | J137: 0 | K137: 0 | L137: 0 | M137: 0 | N137: 0 | O137: 0 | P137: 0 | Q137: 0 | R137: 0 | S137: 0 | T137: 0 | U137: 0 | V137: 08/05/2026 @ 7:34 AM | AA137: 09.00.00-09.11.30 | AC137: Reserved Not Recd N | AD137: 0 | AE137: 0 | AF137: 0 | AG137: 0 | AH137: 0 | AI137: 0 | AJ137: 0 | AK137: 0 | AL137: 0 | AM137: 0 | AN137: 0 | AO137: 0 | AP137: 0 | AQ137: 0 | AR137: 0 | AS137: 0 | AT137: 0 | AU137: 0 | AV137: 0 | AW137: 0 | AX137: 0 | AY137: 0 | AZ137: 0 | BA137: 0 | BB137: 0 | BC137: 0 | BD137: 0 | BE137: 0 | BF137: 0 | BG137: 0 | BH137: 0 | BI137: 0 | BJ137: 0 | BK137: 08/05/2026 @ 7:33 AM | CA137: 09.00.00-09.11.30 | CC137: Reserved Not Recd N | CD137: 0 | CE137: 0 | CF137: 0 | CG137: 0 | CH137: 0 | CI137: 0 | CJ137: 0 | CK137: 0 | CL137: 0 | CM137: 0 | CN137: 0 | CO137: 0 | CP137: 0 | CQ137: 0 | CR137: 0 | CS137: 0 | CT137: 0 | CU137: 0 | CV137: 0 | CW137: 0 | CX137: 08/05/2026 @ 7:33 AM | DA137: 09.00.00-09.11.30 | DC137: Reserved Not Recd N | DD137: 0 | DE137: 0 | DF137: 0 | DG137: 0 | DH137: 0 | DI137: 0 | DJ137: 0 | DK137: 0 | DL137: 0 | DM137: 0 | DN137: 0 | DO137: 0 | DP137: 0 | DQ137: 0 | DR137: 0 | DS137: 0 | DT137: 0 | DU137: 0 | DV137: 0 | DW137: 0 | DX137: 0 | DY137: 0 | DZ137: 0 | EA137: 0 | EB137: 0 | EC137: 08/05/2026 @ 7:33 AM | FA137: 09.00.00-09.11.30 | FC137: Reserved Not Recd N | FD137: 0 | FE137: 0 | FF137: 0 | FG137: 0 | FH137: 0 | FI137: 0 | FJ137: 0 | FK137: 0 | FL137: 0 | FM137: 0 | FN137: 0 | FO137: 0 | FP137: 0 | FQ137: 0 | FR137: 0 | FS137: 0 | FT137: 0 | FU137: 0 | FV137: 0 | FW137: 0 | FX137: 0 | FY137: 0 | FZ137: 0 | GA137: 0 | GB137: 0 | GC137: 0 | GD137: 0 | GE137: 0 | GF137: 0 | GG137: 08/05/2026 @ 7:33 AM
A138: 09.00.00-09.11.30 | C138: Total Assignments | D138: 10 | E138: 27 | F138: 45 | G138: 48 | H138: 0 | I138: 6 | J138: 18 | K138: 32 | L138: 12 | M138: 62 | N138: 30 | O138: 17 | P138: 53 | Q138: 30 | R138: 66 | S138: 64 | T138: 0 | U138: 130 | V138: 08/05/2026 @ 7:34 AM | AA138: 09.00.00-09.11.30 | AC138: Total Assignments | AD138: 1 | AE138: 1 | AF138: 1 | AG138: 3 | AH138: 0 | AI138: 1 | AJ138: 5 | AK138: 8 | AL138: 4 | AM138: 0 | AN138: 7 | AO138: 9 | AP138: 9 | AQ138: 7 | AR138: 0 | AS138: 1 | AT138: 2 | AU138: 4 | AV138: 5 | AW138: 0 | AX138: 0 | AY138: 10 | AZ138: 23 | BA138: 29 | BB138: 0 | BC138: 30 | BD138: 17 | BE138: 53 | BF138: 30 | BG138: 66 | BH138: 64 | BI138: 0 | BJ138: 130 | BK138: 08/05/2026 @ 7:33 AM | CA138: 09.00.00-09.11.30 | CC138: Total Assignments | CD138: 10 | CE138: 27 | CF138: 45 | CG138: 48 | CH138: 0 | CI138: 3 | CJ138: 3 | CK138: 9 | CL138: 9 | CM138: 16 | CN138: 16 | CO138: 6 | CP138: 6 | CQ138: 30 | CR138: 32 | CS138: 30 | CT138: 17 | CU138: 53 | CV138: 30 | CW138: 130 | CX138: 08/05/2026 @ 7:33 AM | DA138: 09.00.00-09.11.30 | DC138: Total Assignments | DD138: 2 | DE138: 15 | DF138: 24 | DG138: 25 | DH138: 0 | DI138: 8 | DJ138: 12 | DK138: 21 | DL138: 23 | DM138: 0 | DN138: 0 | DO138: 0 | DP138: 0 | DQ138: 0 | DR138: 0 | DS138: 6 | DT138: 18 | DU138: 32 | DV138: 12 | DW138: 62 | DX138: 30 | DY138: 17 | DZ138: 53 | EA138: 30 | EB138: 130 | EC138: 08/05/2026 @ 7:33 AM | FA138: 09.00.00-09.11.30 | FC138: Total Assignments | FD138: 10 | FE138: 27 | FF138: 45 | FG138: 48 | FH138: 0 | FI138: 1 | FJ138: 0 | FK138: 2 | FL138: 3 | FM138: 4 | FN138: 3 | FO138: 10 | FP138: 1 | FQ138: 5 | FR138: 3 | FS138: 11 | FT138: 13 | FU138: 3 | FV138: 1 | FW138: 6 | FX138: 2 | FY138: 17 | FZ138: 10 | GA138: 24 | GB138: 11 | GC138: 66 | GD138: 64 | GE138: 0 | GF138: 130 | GG138: 08/05/2026 @ 7:33 AM
A139: 09.00.00-09.11.30 | C139: Selected N | D139: 0 | E139: 0 | F139: 0 | G139: 0 | H139: 0 | I139: 0 | J139: 0 | K139: 0 | L139: 0 | M139: 0 | N139: 0 | O139: 0 | P139: 0 | Q139: 0 | R139: 0 | S139: 0 | T139: 0 | U139: 0 | V139: 08/05/2026 @ 7:34 AM | AA139: 09.00.00-09.11.30 | AC139: Selected N | AD139: 0 | AE139: 0 | AF139: 0 | AG139: 0 | AH139: 0 | AI139: 0 | AJ139: 0 | AK139: 0 | AL139: 0 | AM139: 0 | AN139: 0 | AO139: 0 | AP139: 0 | AQ139: 0 | AR139: 0 | AS139: 0 | AT139: 0 | AU139: 0 | AV139: 0 | AW139: 0 | AX139: 0 | AY139: 0 | AZ139: 0 | BA139: 0 | BB139: 0 | BC139: 0 | BD139: 0 | BE139: 0 | BF139: 0 | BG139: 0 | BH139: 0 | BI139: 0 | BJ139: 0 | BK139: 08/05/2026 @ 7:33 AM | CA139: 09.00.00-09.11.30 | CC139: Selected N | CD139: 0 | CE139: 0 | CF139: 0 | CG139: 0 | CH139: 0 | CI139: 0 | CJ139: 0 | CK139: 0 | CL139: 0 | CM139: 0 | CN139: 0 | CO139: 0 | CP139: 0 | CQ139: 0 | CR139: 0 | CS139: 0 | CT139: 0 | CU139: 0 | CV139: 0 | CW139: 0 | CX139: 08/05/2026 @ 7:33 AM | DA139: 09.00.00-09.11.30 | DC139: Selected N | DD139: 0 | DE139: 0 | DF139: 0 | DG139: 0 | DH139: 0 | DI139: 0 | DJ139: 0 | DK139: 0 | DL139: 0 | DM139: 0 | DN139: 0 | DO139: 0 | DP139: 0 | DQ139: 0 | DR139: 0 | DS139: 0 | DT139: 0 | DU139: 0 | DV139: 0 | DW139: 0 | DX139: 0 | DY139: 0 | DZ139: 0 | EA139: 0 | EB139: 0 | EC139: 08/05/2026 @ 7:33 AM | FA139: 09.00.00-09.11.30 | FC139: Selected N | FD139: 0 | FE139: 0 | FF139: 0 | FG139: 0 | FH139: 0 | FI139: 0 | FJ139: 0 | FK139: 0 | FL139: 0 | FM139: 0 | FN139: 0 | FO139: 0 | FP139: 0 | FQ139: 0 | FR139: 0 | FS139: 0 | FT139: 0 | FU139: 0 | FV139: 0 | FW139: 0 | FX139: 0 | FY139: 0 | FZ139: 0 | GA139: 0 | GB139: 0 | GC139: 0 | GD139: 0 | GE139: 0 | GF139: 0 | GG139: 08/05/2026 @ 7:33 AM
