Workbook

Sheet setup
B3: Phase Setup
B4: Phase Id | C4: 402
B6: Main Study Setup | H6: Stratification Types | K6: matrix sproc
C7: Stratification % | D7: (separate study ids by and exclamation point ! for more than one) | E7: Stratification Type | H7: 1 = 2 Cross | K7: call report_matrix(studyids, stratfication type, stratification%);
B8: StudyIDs (2Cross) | C8: 50 | D8: 3037 | E8: 1 | H8: 2 = 3 Cross ETH/ED
B9: StudyIDs (3Cross) | C9: 50 | D9: 3037 | E9: 2 | H9: 3 = 3 Cross SEX/ETH
B10: StudyIDs (2Cross) | C10: 100 | D10: 3037 | E10: 1
B11: StudyIDs (3Cross) | C11: 100 | D11: 3037 | E11: 2
B12: StudyIDs (3Cross alternate view) | C12: 100 | D12: 3037 | E12: 3
B13: Validity/Reliability Setup | H13: Total study count for this report | K13: =COUNTIF(M:M, "Active") - COUNTIFS(L:L, "OSEP*",M:M, "Active") - COUNTIFS(L:L,"C_*",M:M, "Active") +2 -> 18
B14: Reports will show based on the ordered list below | H14: Phase Study List
B15: Report Order (do not touch) | C15: Study Id (separate studyids by !) | D15: Study Name | E15: Study Acronym | F15: Total Assignment | H15: study_id | I15: study_type_description | J15: sort_order | K15: study_name | L15: study_acronym | M15: study_status
A16: =LEN(C16) - LEN(SUBSTITUTE(C16, "!", "")) + 1 -> 1 | B16: 1 | C16: 3739 | D16: CELF-6 RF 1 Clinical Language Disorder (Ages 5-8) | E16: C_LD_RF1 | F16: =aurora_data!U18 -> 50 | H16: 3726 | I16: Main | J16: 1 | K16: CELF-6 Standardization Record Form 2 (Ages 9-21) | L16: CELF6_RF2_STDZ_9-21 | M16: Active
A17: =LEN(C17) - LEN(SUBSTITUTE(C17, "!", "")) + 1 -> 1 | B17: 2 | C17: 3740 | D17: CELF-6 RF 2 Clinical Language Disorder (Ages 9-16) | E17: C_LD_RF2 | F17: =aurora_data!U146 -> 49 | H17: 3725 | I17: Main | J17: 1 | K17: CELF-6 Standardization Record Form 1 (Ages 5-8) | L17: CELF6_RF1_STDZ_5-8 | M17: Active
A18: =LEN(C18) - LEN(SUBSTITUTE(C18, "!", "")) + 1 -> 1 | B18: 3 | C18: 3741 | D18: CELF-6 RF 1 Clinical Hard of Hearing (Ages 5-8) | E18: C_HH_RF1 | F18: =aurora_data!U246 -> 29 | H18: 3757 | I18: Clinical | J18: 2 | K18: CELF-6 RF2 OSEP Gifted and Talented (Ages 9-21) | L18: OSEP_GT_RF2 | M18: Active
A19: =LEN(C19) - LEN(SUBSTITUTE(C19, "!", "")) + 1 -> 1 | B19: 4 | C19: 3742 | D19: CELF-6 RF 2 Clinical Hard of Hearing (Ages 9-16) | E19: C_HH_RF2 | F19: =aurora_data!U346 -> 35 | H19: 3756 | I19: Clinical | J19: 2 | K19: CELF-6 RF1 OSEP Gifted and Talented (Ages 5-8) | L19: OSEP_GT_RF1 | M19: Active
A20: =LEN(C20) - LEN(SUBSTITUTE(C20, "!", "")) + 1 -> 1 | B20: 5 | C20: 3743 | D20: CELF-6 RF 1 Clinical Autism Spectrum Disorder (Ages 5-8) | E20: C_ASDL_RF1 | F20: =aurora_data!U446 -> 30 | H20: 3755 | I20: Clinical | J20: 2 | K20: CELF-6 RF2 OSEP Speech Impairment (Ages 9-21) | L20: OSEP_SI_RF2 | M20: Active
A21: =LEN(C21) - LEN(SUBSTITUTE(C21, "!", "")) + 1 -> 1 | B21: 6 | C21: 3744 | D21: CELF-6 RF 2 Clinical Autism Spectrum Disorder (Ages 9-16) | E21: C_ASDL_RF2 | F21: =aurora_data!U546 -> 31 | H21: 3754 | I21: Clinical | J21: 2 | K21: CELF-6 RF1 OSEP Speech Impairment (Ages 5-8) | L21: OSEP_SI_RF1 | M21: Active
A22: =LEN(C22) - LEN(SUBSTITUTE(C22, "!", "")) + 1 -> 1 | B22: 7 | C22: 3745 | D22: CELF-6 RF 1 Clinical Specific Learning Disability in Reading and/or Writing (Age 8) | E22: C_SLDRW_RF1 | F22: =aurora_data!U646 -> 5 | H22: 3753 | I22: Clinical | J22: 2 | K22: CELF-6 RF2 OSEP Specific Learning Disability (Ages 9-21) | L22: OSEP_SLD_RF2 | M22: Active
A23: =LEN(C23) - LEN(SUBSTITUTE(C23, "!", "")) + 1 -> 1 | B23: 8 | C23: 3746 | D23: CELF-6 RF 2 Clinical Specific Learning Disability in Reading and/or Writing (Ages 9-21) | E23: C_SLDRW_RF2 | F23: =aurora_data!U746 -> 56 | H23: 3752 | I23: Clinical | J23: 2 | K23: CELF-6 RF1 OSEP Specific Learning Disability (Ages 5-8) | L23: OSEP_SLD_RF1 | M23: Active
A24: =LEN(#REF!) - LEN(SUBSTITUTE(#REF!, "!", "")) + 1 -> #REF! | B24: 9 | C24: 3747 | D24: CELF-6 RF1 OSEP Developmental Delay (Ages 5-8) | E24: OSEP_DD_RF1 | F24: =aurora_data!U1846 -> 16 | H24: 3751 | I24: Clinical | J24: 2 | K24: CELF-6 RF2 OSEP ADHD (Ages 9-17) | L24: OSEP_ADHD_RF2 | M24: Active
A25: =LEN(#REF!) - LEN(SUBSTITUTE(#REF!, "!", "")) + 1 -> #REF! | B25: 10 | C25: 3748 | D25: CELF-6 RF1 OSEP Intellectual Disability (Ages 5-8) | E25: OSEP_ID_RF1 | F25: =aurora_data!U846 -> 2 | H25: 3750 | I25: Clinical | J25: 2 | K25: CELF-6 RF1 OSEP ADHD (Ages 5-8) | L25: OSEP_ADHD_RF1 | M25: Active
A26: =LEN(#REF!) - LEN(SUBSTITUTE(#REF!, "!", "")) + 1 -> #REF! | B26: 11 | C26: 3749 | D26: CELF-6 RF2 OSEP Intellectual Disability (Ages 9-21) | E26: OSEP_ID_RF2 | F26: =aurora_data!U946 -> 4 | H26: 3749 | I26: Clinical | J26: 2 | K26: CELF-6 RF2 OSEP Intellectual Disability (Ages 9-21) | L26: OSEP_ID_RF2 | M26: Active
A27: =LEN(#REF!) - LEN(SUBSTITUTE(#REF!, "!", "")) + 1 -> #REF! | B27: 12 | C27: 3750 | D27: CELF-6 RF1 OSEP ADHD (Ages 5-8) | E27: OSEP_ADHD_RF1 | F27: =aurora_data!U1046 -> 14 | H27: 3748 | I27: Clinical | J27: 2 | K27: CELF-6 RF1 OSEP Intellectual Disability (Ages 5-8) | L27: OSEP_ID_RF1 | M27: Active
A28: =LEN(#REF!) - LEN(SUBSTITUTE(#REF!, "!", "")) + 1 -> #REF! | B28: 13 | C28: 3751 | D28: CELF-6 RF2 OSEP ADHD (Ages 9-17) | E28: OSEP_ADHD_RF2 | F28: =aurora_data!U1146 -> 21 | H28: 3747 | I28: Clinical | J28: 2 | K28: CELF-6 RF1 OSEP Developmental Delay (Ages 5-8) | L28: OSEP_DD_RF1 | M28: Active
A29: =LEN(#REF!) - LEN(SUBSTITUTE(#REF!, "!", "")) + 1 -> #REF! | B29: 14 | C29: 3752 | D29: CELF-6 RF1 OSEP Specific Learning Disability (Ages 5-8) | E29: OSEP_SLD_RF1 | F29: =aurora_data!U1246 -> 2 | H29: 3746 | I29: Clinical | J29: 2 | K29: CELF-6 RF 2 Clinical Specific Learning Disability in Reading and/or Writing (Ages 9-21) | L29: C_SLDRW_RF2 | M29: Active
A30: =LEN(#REF!) - LEN(SUBSTITUTE(#REF!, "!", "")) + 1 -> #REF! | B30: 15 | C30: 3753 | D30: CELF-6 RF2 OSEP Specific Learning Disability (Ages 9-21) | E30: OSEP_SLD_RF2 | F30: =aurora_data!U1354 -> 4 | H30: 3745 | I30: Clinical | J30: 2 | K30: CELF-6 RF 1 Clinical Specific Learning Disability in Reading and/or Writing (Age 8) | L30: C_SLDRW_RF1 | M30: Active
A31: =LEN(#REF!) - LEN(SUBSTITUTE(#REF!, "!", "")) + 1 -> #REF! | B31: 16 | C31: 3754 | D31: CELF-6 RF1 OSEP Speech Impairment (Ages 5-8) | E31: OSEP_SI_RF1 | F31: =aurora_data!U1446 -> 25 | H31: 3744 | I31: Clinical | J31: 2 | K31: CELF-6 RF 2 Clinical Autism Spectrum Disorder (Ages 9-16) | L31: C_ASDL_RF2 | M31: Active
A32: =LEN(#REF!) - LEN(SUBSTITUTE(#REF!, "!", "")) + 1 -> #REF! | B32: 17 | C32: 3755 | D32: CELF-6 RF2 OSEP Speech Impairment (Ages 9-21) | E32: OSEP_SI_RF2 | F32: =aurora_data!U1546 -> 20 | H32: 3743 | I32: Clinical | J32: 2 | K32: CELF-6 RF 1 Clinical Autism Spectrum Disorder (Ages 5-8) | L32: C_ASDL_RF1 | M32: Active
A33: =LEN(#REF!) - LEN(SUBSTITUTE(#REF!, "!", "")) + 1 -> #REF! | B33: 18 | C33: 3756 | D33: CELF-6 RF1 OSEP Gifted and Talented (Ages 5-8) | E33: OSEP_GT_RF1 | F33: =aurora_data!U1646 -> 1 | H33: 3741 | I33: Clinical | J33: 2 | K33: CELF-6 RF 1 Clinical Hard of Hearing (Ages 5-8) | L33: C_HH_RF1 | M33: Active
B34: 19 | C34: 3757 | D34: CELF-6 RF2 OSEP Gifted and Talented (Ages 9-21) | E34: OSEP_GT_RF2 | F34: =aurora_data!U1754 -> 20 | H34: 3740 | I34: Clinical | J34: 2 | K34: CELF-6 RF 2 Clinical Language Disorder (Ages 9-16) | L34: C_LD_RF2 | M34: Active
H35: 3739 | I35: Clinical | J35: 2 | K35: CELF-6 RF 1 Clinical Language Disorder (Ages 5-8) | L35: C_LD_RF1 | M35: Active
H36: 3742 | I36: Clinical | J36: 2 | K36: CELF-6 RF 2 Clinical Hard of Hearing (Ages 9-16) | L36: C_HH_RF2 | M36: Active
H37: 3727 | I37: Reliability | J37: 3 | K37: Retest CELF-6 Standardization Record Form 1 (Ages 5-8) | L37: R_CELF6_RF1_STDZ_5-8 | M37: Active
H38: 3728 | I38: Reliability | J38: 3 | K38: Retest CELF-6 Standardization Record Form 2 (Ages 9-16) | L38: R_CELF6_RF2_STDZ_9-16 | M38: Active
H39: 3732 | I39: Validity | J39: 4 | K39: Validity CELF-6 RF1/CELFP-3 (Ages 5-6) | L39: V_CELFP3_RF1 | M39: Active
H40: 3729 | I40: Validity | J40: 4 | K40: Validity CELF-6 RF1/CELF-5 (Ages 5-8) | L40: V_CELF5_RF1 | M40: Active
H41: 3730 | I41: Validity | J41: 4 | K41: Validity CELF-6 RF2/CELF-5 (Ages 9-16) | L41: V_CELF5_RF2 | M41: Active
H42: 3731 | I42: Validity | J42: 4 | K42: Validity CELF-6 RF2/CELF-5 Meta (Ages 9-21) | L42: V_META_RF2 | M42: Active
H43: 3733 | I43: Validity | J43: 4 | K43: Validity CELF-6 RF1/CCC-2 (Ages 5-8) | L43: V_CCC2_RF1 | M43: Active
...

Sheet aurora_data
A1: =setup!C16 -> 3739
A2: =_xlfn.CONCAT(setup!D16, " - ",setup!E16) -> CELF-6 RF 1 Clinical Language Disorder (Ages 5-8) - C_LD_RF1
A3: ageband | B3: gradeband | C3: report | D3: 1 | E3: 2 | F3: 3 | G3: 4 | H3: 5 | I3: AS | J3: BL | K3: HI | L3: OT | M3: WH | N3: MW | O3: NE | P3: SO | Q3: WE | R3: F | S3: M | T3: OTHER | U3: Total | V3: LastRefreshed
A4: 05.00.00-08.11.30 | C4: Target N | D4: 0 | E4: 0 | F4: 0 | G4: 0 | H4: 0 | I4: 0 | J4: 0 | K4: 0 | L4: 0 | M4: 0 | N4: 0 | O4: 0 | P4: 0 | Q4: 0 | R4: 0 | S4: 0 | T4: 0 | U4: 50 | V4: 08/06/2026 @ 7:19 AM
A5: 05.00.00-08.11.30 | C5: Stratified Usable N | D5: 3 | E5: 14 | F5: 19 | G5: 14 | H5: 0 | I5: 0 | J5: 10 | K5: 5 | L5: 8 | M5: 27 | N5: 16 | O5: 5 | P5: 28 | Q5: 1 | R5: 19 | S5: 31 | T5: 0 | U5: 50 | V5: 08/06/2026 @ 7:19 AM
A6: 05.00.00-08.11.30 | C6: Stratified Out Usable N | D6: 0 | E6: 0 | F6: 0 | G6: 0 | H6: 0 | I6: 0 | J6: 0 | K6: 0 | L6: 0 | M6: 0 | N6: 0 | O6: 0 | P6: 0 | Q6: 0 | R6: 0 | S6: 0 | T6: 0 | U6: 0 | V6: 08/06/2026 @ 7:19 AM
A7: 05.00.00-08.11.30 | C7: In Process N | D7: 0 | E7: 0 | F7: 0 | G7: 0 | H7: 0 | I7: 0 | J7: 0 | K7: 0 | L7: 0 | M7: 0 | N7: 0 | O7: 0 | P7: 0 | Q7: 0 | R7: 0 | S7: 0 | T7: 0 | U7: 0 | V7: 08/06/2026 @ 7:19 AM
A8: 05.00.00-08.11.30 | C8: Assigned Not Recd N | D8: 0 | E8: 0 | F8: 0 | G8: 0 | H8: 0 | I8: 0 | J8: 0 | K8: 0 | L8: 0 | M8: 0 | N8: 0 | O8: 0 | P8: 0 | Q8: 0 | R8: 0 | S8: 0 | T8: 0 | U8: 0 | V8: 08/06/2026 @ 7:19 AM
A9: 05.00.00-08.11.30 | C9: Reserved Not Recd N | D9: 0 | E9: 0 | F9: 0 | G9: 0 | H9: 0 | I9: 0 | J9: 0 | K9: 0 | L9: 0 | M9: 0 | N9: 0 | O9: 0 | P9: 0 | Q9: 0 | R9: 0 | S9: 0 | T9: 0 | U9: 0 | V9: 08/06/2026 @ 7:19 AM
A10: 05.00.00-08.11.30 | C10: Total Assignments | D10: 3 | E10: 14 | F10: 19 | G10: 14 | H10: 0 | I10: 0 | J10: 10 | K10: 5 | L10: 8 | M10: 27 | N10: 16 | O10: 5 | P10: 28 | Q10: 1 | R10: 19 | S10: 31 | T10: 0 | U10: 50 | V10: 08/06/2026 @ 7:19 AM
A11: 05.00.00-08.11.30 | C11: Selected N | D11: 0 | E11: 0 | F11: 0 | G11: 0 | H11: 0 | I11: 0 | J11: 0 | K11: 0 | L11: 0 | M11: 0 | N11: 0 | O11: 0 | P11: 0 | Q11: 0 | R11: 0 | S11: 0 | T11: 0 | U11: 0 | V11: 08/06/2026 @ 7:19 AM
A12: Total | C12: Target N | D12: 0 | E12: 0 | F12: 0 | G12: 0 | H12: 0 | I12: 0 | J12: 0 | K12: 0 | L12: 0 | M12: 0 | N12: 0 | O12: 0 | P12: 0 | Q12: 0 | R12: 0 | S12: 0 | T12: 0 | U12: 50 | V12: 08/06/2026 @ 7:19 AM
A13: Total | C13: Stratified Usable N | D13: 3 | E13: 14 | F13: 19 | G13: 14 | H13: 0 | I13: 0 | J13: 10 | K13: 5 | L13: 8 | M13: 27 | N13: 16 | O13: 5 | P13: 28 | Q13: 1 | R13: 19 | S13: 31 | T13: 0 | U13: 50 | V13: 08/06/2026 @ 7:19 AM
A14: Total | C14: Stratified Out Usable N | D14: 0 | E14: 0 | F14: 0 | G14: 0 | H14: 0 | I14: 0 | J14: 0 | K14: 0 | L14: 0 | M14: 0 | N14: 0 | O14: 0 | P14: 0 | Q14: 0 | R14: 0 | S14: 0 | T14: 0 | U14: 0 | V14: 08/06/2026 @ 7:19 AM
A15: Total | C15: In Process N | D15: 0 | E15: 0 | F15: 0 | G15: 0 | H15: 0 | I15: 0 | J15: 0 | K15: 0 | L15: 0 | M15: 0 | N15: 0 | O15: 0 | P15: 0 | Q15: 0 | R15: 0 | S15: 0 | T15: 0 | U15: 0 | V15: 08/06/2026 @ 7:19 AM
... A19: Total | C19: Selected N | D19: 0 | E19: 0 | F19: 0 | G19: 0 | H19: 0 | I19: 0 | J19: 0 | K19: 0 | L19: 0 | M19: 0 | N19: 0 | O19: 0 | P19: 0 | Q19: 0 | R19: 0 | S19: 0 | T19: 0 | U19: 0 | V19: 08/06/2026 @ 7:19 AM
A129: =setup!C17 -> 3740
A130: =_xlfn.CONCAT(setup!D17," - ",setup!E17) -> CELF-6 RF 2 Clinical Language Disorder (Ages 9-16) - C_LD_RF2
A131: ageband | B131: gradeband | C131: report | D131: 1 | E131: 2 | F131: 3 | G131: 4 | H131: 5 | I131: AS | J131: BL | K131: HI | L131: OT | M131: WH | N131: MW | O131: NE | P131: SO | Q131: WE | R131: F | S131: M | T131: OTHER | U131: Total | V131: LastRefreshed
A132: 09.00.00-16.11.30 | C132: Target N | D132: 0 | E132: 0 | F132: 0 | G132: 0 | H132: 0 | I132: 0 | J132: 0 | K132: 0 | L132: 0 | M132: 0 | N132: 0 | O132: 0 | P132: 0 | Q132: 0 | R132: 0 | S132: 0 | T132: 0 | U132: 50 | V132: 08/06/2026 @ 7:19 AM
A133: 09.00.00-16.11.30 | C133: Stratified Usable N | D133: 16 | E133: 18 | F133: 5 | G133: 10 | H133: 0 | I133: 1 | J133: 7 | K133: 24 | L133: 1 | M133: 16 | N133: 7 | O133: 6 | P133: 14 | Q133: 22 | R133: 18 | S133: 31 | T133: 0 | U133: 49 | V133: 08/06/2026 @ 7:19 AM
A134: 09.00.00-16.11.30 | C134: Stratified Out Usable N | D134: 0 | E134: 0 | F134: 0 | G134: 0 | H134: 0 | I134: 0 | J134: 0 | K134: 0 | L134: 0 | M134: 0 | N134: 0 | O134: 0 | P134: 0 | Q134: 0 | R134: 0 | S134: 0 | T134: 0 | U134: 0 | V134: 08/06/2026 @ 7:19 AM
A135: 09.00.00-16.11.30 | C135: In Process N | D135: 0 | E135: 0 | F135: 0 | G135: 0 | H135: 0 | I135: 0 | J135: 0 | K135: 0 | L135: 0 | M135: 0 | N135: 0 | O135: 0 | P135: 0 | Q135: 0 | R135: 0 | S135: 0 | T135: 0 | U135: 0 | V135: 08/06/2026 @ 7:19 AM
A136: 09.00.00-16.11.30 | C136: Assigned Not Recd N | D136: 0 | E136: 0 | F136: 0 | G136: 0 | H136: 0 | I136: 0 | J136: 0 | K136: 0 | L136: 0 | M136: 0 | N136: 0 | O136: 0 | P136: 0 | Q136: 0 | R136: 0 | S136: 0 | T136: 0 | U136: 0 | V136: 08/06/2026 @ 7:19 AM
A137: 09.00.00-16.11.30 | C137: Reserved Not Recd N | D137: 0 | E137: 0 | F137: 0 | G137: 0 | H137: 0 | I137: 0 | J137: 0 | K137: 0 | L137: 0 | M137: 0 | N137: 0 | O137: 0 | P137: 0 | Q137: 0 | R137: 0 | S137: 0 | T137: 0 | U137: 0 | V137: 08/06/2026 @ 7:19 AM
A138: 09.00.00-16.11.30 | C138: Total Assignments | D138: 16 | E138: 18 | F138: 5 | G138: 10 | H138: 0 | I138: 1 | J138: 7 | K138: 24 | L138: 1 | M138: 16 | N138: 7 | O138: 6 | P138: 14 | Q138: 22 | R138: 18 | S138: 31 | T138: 0 | U138: 49 | V138: 08/06/2026 @ 7:19 AM
A139: 09.00.00-16.11.30 | C139: Selected N | D139: 0 | E139: 0 | F139: 0 | G139: 0 | H139: 0 | I139: 0 | J139: 0 | K139: 0 | L139: 0 | M139: 0 | N139: 0 | O139: 0 | P139: 0 | Q139: 0 | R139: 0 | S139: 0 | T139: 0 | U139: 0 | V139: 08/06/2026 @ 7:19 AM
A140: Total | C140: Target N | D140: 0 | E140: 0 | F140: 0 | G140: 0 | H140: 0 | I140: 0 | J140: 0 | K140: 0 | L140: 0 | M140: 0 | N140: 0 | O140: 0 | P140: 0 | Q140: 0 | R140: 0 | S140: 0 | T140: 0 | U140: 50 | V140: 08/06/2026 @ 7:19 AM
A141: Total | C141: Stratified Usable N | D141: 16 | E141: 18 | F141: 5 | G141: 10 | H141: 0 | I141: 1 | J141: 7 | K141: 24 | L141: 1 | M141: 16 | N141: 7 | O141: 6 | P141: 14 | Q141: 22 | R141: 18 | S141: 31 | T141: 0 | U141: 49 | V141: 08/06/2026 @ 7:19 AM
A142: Total | C142: Stratified Out Usable N | D142: 0 | E142: 0 | F142: 0 | G142: 0 | H142: 0 | I142: 0 | J142: 0 | K142: 0 | L142: 0 | M142: 0 | N142: 0 | O142: 0 | P142: 0 | Q142: 0 | R142: 0 | S142: 0 | T142: 0 | U142: 0 | V142: 08/06/2026 @ 7:19 AM
A143: Total | C143: In Process N | D143: 0 | E143: 0 | F143: 0 | G143: 0 | H143: 0 | I143: 0 | J143: 0 | K143: 0 | L143: 0 | M143: 0 | N143: 0 | O143: 0 | P143: 0 | Q143: 0 | R143: 0 | S143: 0 | T143: 0 | U143: 0 | V143: 08/06/2026 @ 7:19 AM
... A147: Total | C147: Selected N | D147: 0 | E147: 0 | F147: 0 | G147: 0 | H147: 0 | I147: 0 | J147: 0 | K147: 0 | L147: 0 | M147: 0 | N147: 0 | O147: 0 | P147: 0 | Q147: 0 | R147: 0 | S147: 0 | T147: 0 | U147: 0 | V147: 08/06/2026 @ 7:19 AM
A229: =setup!C18 -> 3741
A230: =_xlfn.CONCAT(setup!D18," - ",setup!E18) -> CELF-6 RF 1 Clinical Hard of Hearing (Ages 5-8) - C_HH_RF1
A231: ageband | B231: gradeband | C231: report | D231: 1 | E231: 2 | F231: 3 | G231: 4 | H231: 5 | I231: AS | J231: BL | K231: HI | L231: OT | M231: WH | N231: MW | O231: NE | P231: SO | Q231: WE | R231: F | S231: M | T231: OTHER | U231: Total | V231: LastRefreshed
A232: 05.00.00-08.11.30 | C232: Target N | D232: 0 | E232: 0 | F232: 0 | G232: 0 | H232: 0 | I232: 0 | J232: 0 | K232: 0 | L232: 0 | M232: 0 | N232: 0 | O232: 0 | P232: 0 | Q232: 0 | R232: 0 | S232: 0 | T232: 0 | U232: 30 | V232: 08/06/2026 @ 7:19 AM
A233: 05.00.00-08.11.30 | C233: Stratified Usable N | D233: 3 | E233: 4 | F233: 4 | G233: 18 | H233: 0 | I233: 0 | J233: 0 | K233: 3 | L233: 1 | M233: 25 | N233: 9 | O233: 3 | P233: 12 | Q233: 5 | R233: 19 | S233: 10 | T233: 0 | U233: 29 | V233: 08/06/2026 @ 7:19 AM
A234: 05.00.00-08.11.30 | C234: Stratified Out Usable N | D234: 0 | E234: 0 | F234: 0 | G234: 0 | H234: 0 | I234: 0 | J234: 0 | K234: 0 | L234: 0 | M234: 0 | N234: 0 | O234: 0 | P234: 0 | Q234: 0 | R234: 0 | S234: 0 | T234: 0 | U234: 0 | V234: 08/06/2026 @ 7:19 AM
A235: 05.00.00-08.11.30 | C235: In Process N | D235: 0 | E235: 0 | F235: 0 | G235: 0 | H235: 0 | I235: 0 | J235: 0 | K235: 0 | L235: 0 | M235: 0 | N235: 0 | O235: 0 | P235: 0 | Q235: 0 | R235: 0 | S235: 0 | T235: 0 | U235: 0 | V235: 08/06/2026 @ 7:19 AM
A236: 05.00.00-08.11.30 | C236: Assigned Not Recd N | D236: 0 | E236: 0 | F236: 0 | G236: 0 | H236: 0 | I236: 0 | J236: 0 | K236: 0 | L236: 0 | M236: 0 | N236: 0 | O236: 0 | P236: 0 | Q236: 0 | R236: 0 | S236: 0 | T236: 0 | U236: 0 | V236: 08/06/2026 @ 7:19 AM
...

Sheet Summary
A1: =_xlfn.CONCAT("Last Refreshed at: ",F3) -> Last Refreshed at: 08/06/2026 @ 7:19 AM | H1: Assignment Information | L1: Total usable from all tabs | P1: Tptal in-Process
A2: study_id | B2: study | C2: Target | D2: usableCount | E2: Percentage | F2: Refreshed_Date | H2: Total Assigned | I2: Percentage | L2: =SUM(C_LD!W29,C_HH!W29,C_ASDL!W29,C_SLDRW!W29,OSEP_ID!W29,OSEP_DD!W21,OSEP_ADHD!W29,OSEP_SLD!W37,OSEP_SI!W29,OSEP_GT!W37) -> 402 | M2: =SUM(#REF!,#REF!,#REF!,#REF!,#REF!,#REF!,#REF!,#REF!,#REF!,#REF!,#REF!,#REF!,#REF!,#REF!,#REF!,#REF!,#REF!,#REF!,#REF!) -> #REF! | P2: =SUM(#REF!,#REF!,#REF!) -> #REF!
A3: 3740,3739 | B3: CELF-6 RF1 & 2 Clinical Language Disorder (Ages 5-16) | C3: 100 | D3: 99 | E3: 0.99 | F3: 08/06/2026 @ 7:19 AM | H3: =setup!F16+setup!F17 -> 99 | I3: =IFERROR(H3/C3,0) -> 0.99
A4: 3741,3742 | B4: CELF-6 RF1 & 2 Clinical Hard of Hearing (Ages 5-16) | C4: 60 | D4: 60 | E4: 1 | F4: 08/06/2026 @ 7:19 AM | H4: =setup!F18+setup!F19 -> 64 | I4: =IFERROR(H4/C4,0) -> 1.0666667
A5: 3743,3744 | B5: CELF-6 RF1 & 2 Clinical Autism Spectrum Disorder (Ages 5-16) | C5: 60 | D5: 60 | E5: 1 | F5: 08/06/2026 @ 7:19 AM | H5: =setup!F20+setup!F21 -> 61 | I5: =IFERROR(H5/C5,0) -> 1.0166667
A6: 3745,3746 | B6: CELF-6 RF1 & 2 Clinical Specific Learning Disability in Reading and/or Writing (Ages 8-21) | C6: 60 | D6: 60 | E6: 1 | F6: 08/06/2026 @ 7:19 AM | H6: =setup!F22 + setup!F23 -> 61 | I6: =IFERROR(H6/C6,0) -> 1.0166667
A7: 3747 | B7: CELF-6 RF1 OSEP Developmental Delay (Ages 5-8) | C7: 15 | D7: 15 | E7: 1 | F7: 08/06/2026 @ 7:19 AM | H7: =setup!F24 -> 16 | I7: =IFERROR(H7/C7,0) -> 1.0666667
A8: 3748,3749 | B8: CELF-6 RF1 & 2 OSEP Intellectual Disability (Ages 5-21) | C8: 12 | D8: 6 | E8: 0.5 | F8: 08/06/2026 @ 7:19 AM | H8: =setup!F25+setup!F26 -> 6 | I8: =IFERROR(H8/C8,0) -> 0.5
A9: 3750,3751 | B9: CELF-6 RF1 & 2 OSEP ADHD (Ages 5-17) | C9: 148 | D9: 35 | E9: 0.23648649 | F9: 08/06/2026 @ 7:19 AM | H9: =setup!F27+setup!F28 -> 35 | I9: =IFERROR(H9/C9,0) -> 0.23648649
A10: 3752,3753 | B10: CELF-6 RF1 & 2 OSEP Specific Learning Disability (Ages 5-21) | C10: 23 | D10: 6 | E10: 0.26086957 | F10: 08/06/2026 @ 7:19 AM | H10: =setup!F29+setup!F30 -> 6 | I10: =IFERROR(H10/C10,0) -> 0.26086957
A11: 3754,3755 | B11: CELF-6 RF1 & 2 OSEP Speech Impairment (Ages 5-21) | C11: 40 | D11: 40 | E11: 1 | F11: 08/06/2026 @ 7:19 AM | H11: =setup!F31+setup!F32 -> 45 | I11: =IFERROR(H11/C11,0) -> 1.125
A12: 3756,3757 | B12: CELF-6 RF1 & 2 OSEP Gifted and Talented (Ages 5-21) | C12: 45 | D12: 21 | E12: 0.46666667 | F12: 08/06/2026 @ 7:19 AM | H12: =setup!F33+setup!F34 -> 21 | I12: =IFERROR(H12/C12,0) -> 0.46666667
A13: All | B13: Total | C13: 563 | D13: 402 | E13: 0.71403197 | F13: 08/06/2026 @ 7:19 AM | H13: =SUM(H3:H12) -> 414 | I13: =IFERROR(H13/C13,0) -> 0.73534636

Sheet C_LD
A1: Total Assigments below Target | D1: Study Information | N1: Additional Information
A2: Usable greater/equal to target | D2: =_xlfn.CONCAT("Study Name: "," CELF-6 RF 1 & 2 Clinical Language Disorder (5-16) ") -> Study Name: CELF-6 RF 1 & 2 Clinical Language Disorder (5-16) | K2: Usable = case is available to Psychometrics for this study In Process = questionable, In Process Assigned Not Recd = Tests assigned to examiners, no tests received (required tests) Reserved not Received = Tests in reserved status, not received Total Assignments = sum of Usable, Received Non Final, Assigned Partial Received, Assigned Not Received Selected = default status for making an assignment
D3: =_xlfn.CONCAT("Study Acronym: "," C_LD_RF1/C_LD_RF2") -> Study Acronym: C_LD_RF1/C_LD_RF2 | F3: Study ID: 3739 & 3740
D5: Additional Requirements
D6: Collect some of each based on two age bands (ages 5-8, ages 9-16)
B8: =_xlfn.CONCAT("Last Refreshed at: ",aurora_data!V4) -> Last Refreshed at: 08/06/2026 @ 7:19 AM | E8: Demographic Variables | W8: Totals
D9: Variance Tolerance: | E9: 4 | J9: some of each, if possible | O9: some of each, if possible | S9: some of each, if possible
B10: Status | E10: Education Level | J10: Ethnicity | O10: Region | S10: SEX
C11: ageband | D11: report | E11: 1 | F11: 2 | G11: 3 | H11: 4 | I11: 5 | J11: AS | K11: BL | L11: HI | M11: OTH | N11: WH | O11: MW | P11: NE | Q11: SO | R11: WE | S11: F | T11: M | U11: INT
B12: CLOSED | C12: =aurora_data!A4 -> 05.00.00-08.11.30 | D12: Target | E12: =IFERROR(aurora_data!D4,0) -> 0 | F12: =IFERROR(aurora_data!E4,0) -> 0 | G12: =IFERROR(aurora_data!F4,0) -> 0 | H12: =IFERROR(aurora_data!G4,0) -> 0 | I12: =IFERROR(aurora_data!H4,0) -> 0 | J12: =IFERROR(aurora_data!I4,0) -> 0 | K12: =IFERROR(aurora_data!J4,0) -> 0 | L12: =IFERROR(aurora_data!K4,0) -> 0 | ... U12: =IFERROR(aurora_data!T4,0) -> 0 | W12: =IFERROR(aurora_data!U4,0) -> 50 | X12: =IFERROR(W12/$W$12,0) -> 1
D13: Usable | E13: =IFERROR(aurora_data!D5,0) -> 3 | F13: =IFERROR(aurora_data!E5,0) -> 14 | G13: =IFERROR(aurora_data!F5,0) -> 19 | H13: =IFERROR(aurora_data!G5,0) -> 14 | I13: =IFERROR(aurora_data!H5,0) -> 0 | J13: =IFERROR(aurora_data!I5,0) -> 0 | K13: =IFERROR(aurora_data!J5,0) -> 10 | L13: =IFERROR(aurora_data!K5,0) -> 5 | ... U13: =IFERROR(aurora_data!T5,0) -> 0 | W13: =IFERROR(aurora_data!U5,0) -> 50 | X13: =IFERROR(W13/$W$12,0) -> 1
D14: Stratified Out Usable N | E14: =IFERROR(aurora_data!D6,0) -> 0 | F14: =IFERROR(aurora_data!E6,0) -> 0 | G14: =IFERROR(aurora_data!F6,0) -> 0 | H14: =IFERROR(aurora_data!G6,0) -> 0 | I14: =IFERROR(aurora_data!H6,0) -> 0 | J14: =IFERROR(aurora_data!I6,0) -> 0 | K14: =IFERROR(aurora_data!J6,0) -> 0 | L14: =IFERROR(aurora_data!K6,0) -> 0 | ... U14: =IFERROR(aurora_data!T6,0) -> 0 | W14: =IFERROR(aurora_data!U6,0) -> 0 | X14: =IFERROR(W14/$W$12,0) -> 0
D15: In Process | E15: =IFERROR(aurora_data!D7,0) -> 0 | F15: =IFERROR(aurora_data!E7,0) -> 0 | G15: =IFERROR(aurora_data!F7,0) -> 0 | H15: =IFERROR(aurora_data!G7,0) -> 0 | I15: =IFERROR(aurora_data!H7,0) -> 0 | J15: =IFERROR(aurora_data!I7,0) -> 0 | K15: =IFERROR(aurora_data!J7,0) -> 0 | L15: =IFERROR(aurora_data!K7,0) -> 0 | ... U15: =IFERROR(aurora_data!T7,0) -> 0 | W15: =IFERROR(aurora_data!U7,0) -> 0 | X15: =IFERROR(W15/$W$12,0) -> 0
D16: Assigned Not Received | E16: =IFERROR(aurora_data!D8,0) -> 0 | F16: =IFERROR(aurora_data!E8,0) -> 0 | G16: =IFERROR(aurora_data!F8,0) -> 0 | H16: =IFERROR(aurora_data!G8,0) -> 0 | I16: =IFERROR(aurora_data!H8,0) -> 0 | J16: =IFERROR(aurora_data!I8,0) -> 0 | K16: =IFERROR(aurora_data!J8,0) -> 0 | L16: =IFERROR(aurora_data!K8,0) -> 0 | ... U16: =IFERROR(aurora_data!T8,0) -> 0 | W16: =IFERROR(aurora_data!U8,0) -> 0 | X16: =IFERROR(W16/$W$12,0) -> 0
D17: Reserved Not Received | E17: =IFERROR(aurora_data!D9,0) -> 0 | F17: =IFERROR(aurora_data!E9,0) -> 0 | G17: =IFERROR(aurora_data!F9,0) -> 0 | H17: =IFERROR(aurora_data!G9,0) -> 0 | I17: =IFERROR(aurora_data!H9,0) -> 0 | J17: =IFERROR(aurora_data!I9,0) -> 0 | K17: =IFERROR(aurora_data!J9,0) -> 0 | L17: =IFERROR(aurora_data!K9,0) -> 0 | ... U17: =IFERROR(aurora_data!T9,0) -> 0 | W17: =IFERROR(aurora_data!U9,0) -> 0 | X17: =IFERROR(W17/$W$12,0) -> 0
D18: Total Assignments | E18: =IFERROR(aurora_data!D10,0) -> 3 | F18: =IFERROR(aurora_data!E10,0) -> 14 | G18: =IFERROR(aurora_data!F10,0) -> 19 | H18: =IFERROR(aurora_data!G10,0) -> 14 | I18: =IFERROR(aurora_data!H10,0) -> 0 | J18: =IFERROR(aurora_data!I10,0) -> 0 | K18: =IFERROR(aurora_data!J10,0) -> 10 | L18: =IFERROR(aurora_data!K10,0) -> 5 | ... U18: =IFERROR(aurora_data!T10,0) -> 0 | W18: =IFERROR(aurora_data!U10,0) -> 50 | X18: =IFERROR(W18/$W$12,0) -> 1
D19: Selected | E19: =IFERROR(aurora_data!D11,0) -> 0 | F19: =IFERROR(aurora_data!E11,0) -> 0 | G19: =IFERROR(aurora_data!F11,0) -> 0 | H19: =IFERROR(aurora_data!G11,0) -> 0 | I19: =IFERROR(aurora_data!H11,0) -> 0 | J19: =IFERROR(aurora_data!I11,0) -> 0 | K19: =IFERROR(aurora_data!J11,0) -> 0 | L19: =IFERROR(aurora_data!K11,0) -> 0 | ... U19: =IFERROR(aurora_data!T11,0) -> 0 | W19: =IFERROR(aurora_data!U11,0) -> 0 | X19: =IFERROR(W19/$W$12,0) -> 0
B20: CLOSED | C20: =aurora_data!A132 -> 09.00.00-16.11.30 | D20: Target | E20: =IFERROR(aurora_data!D132,0) -> 0 | F20: =IFERROR(aurora_data!E132,0) -> 0 | G20: =IFERROR(aurora_data!F132,0) -> 0 | H20: =IFERROR(aurora_data!G132,0) -> 0 | I20: =IFERROR(aurora_data!H132,0) -> 0 | J20: =IFERROR(aurora_data!I132,0) -> 0 | K20: =IFERROR(aurora_data!J132,0) -> 0 | L20: =IFERROR(aurora_data!K132,0) -> 0 | ... U20: =IFERROR(aurora_data!T132,0) -> 0 | W20: =IFERROR(aurora_data!U132,0) -> 50 | X20: =IFERROR(W20/$W$20,0) -> 1
D21: Usable | E21: =IFERROR(aurora_data!D133,0) -> 16 | F21: =IFERROR(aurora_data!E133,0) -> 18 | G21: =IFERROR(aurora_data!F133,0) -> 5 | H21: =IFERROR(aurora_data!G133,0) -> 10 | I21: =IFERROR(aurora_data!H133,0) -> 0 | J21: =IFERROR(aurora_data!I133,0) -> 1 | K21: =IFERROR(aurora_data!J133,0) -> 7 | L21: =IFERROR(aurora_data!K133,0) -> 24 | ... U21: =IFERROR(aurora_data!T133,0) -> 0 | W21: =IFERROR(aurora_data!U133,0) -> 49 | X21: =IFERROR(W21/$W$20,0) -> 0.98
D22: Stratified Out Usable N | E22: =IFERROR(aurora_data!D134,0) -> 0 | F22: =IFERROR(aurora_data!E134,0) -> 0 | G22: =IFERROR(aurora_data!F134,0) -> 0 | H22: =IFERROR(aurora_data!G134,0) -> 0 | I22: =IFERROR(aurora_data!H134,0) -> 0 | J22: =IFERROR(aurora_data!I134,0) -> 0 | K22: =IFERROR(aurora_data!J134,0) -> 0 | L22: =IFERROR(aurora_data!K134,0) -> 0 | ... U22: =IFERROR(aurora_data!T134,0) -> 0 | W22: =IFERROR(aurora_data!U134,0) -> 0 | X22: =IFERROR(W22/$W$20,0) -> 0
D23: In Process | E23: =IFERROR(aurora_data!D135,0) -> 0 | F23: =IFERROR(aurora_data!E135,0) -> 0 | G23: =IFERROR(aurora_data!F135,0) -> 0 | H23: =IFERROR(aurora_data!G135,0) -> 0 | I23: =IFERROR(aurora_data!H135,0) -> 0 | J23: =IFERROR(aurora_data!I135,0) -> 0 | K23: =IFERROR(aurora_data!J135,0) -> 0 | L23: =IFERROR(aurora_data!K135,0) -> 0 | ... U23: =IFERROR(aurora_data!T135,0) -> 0 | W23: =IFERROR(aurora_data!U135,0) -> 0 | X23: =IFERROR(W23/$W$20,0) -> 0
D24: Assigned Not Received | E24: =IFERROR(aurora_data!D136,0) -> 0 | F24: =IFERROR(aurora_data!E136,0) -> 0 | G24: =IFERROR(aurora_data!F136,0) -> 0 | H24: =IFERROR(aurora_data!G136,0) -> 0 | I24: =IFERROR(aurora_data!H136,0) -> 0 | J24: =IFERROR(aurora_data!I136,0) -> 0 | K24: =IFERROR(aurora_data!J136,0) -> 0 | L24: =IFERROR(aurora_data!K136,0) -> 0 | ... U24: =IFERROR(aurora_data!T136,0) -> 0 | W24: =IFERROR(aurora_data!U136,0) -> 0 | X24: =IFERROR(W24/$W$20,0) -> 0
D25: Reserved Not Received | E25: =IFERROR(aurora_data!D137,0) -> 0 | F25: =IFERROR(aurora_data!E137,0) -> 0 | G25: =IFERROR(aurora_data!F137,0) -> 0 | H25: =IFERROR(aurora_data!G137,0) -> 0 | I25: =IFERROR(aurora_data!H137,0) -> 0 | J25: =IFERROR(aurora_data!I137,0) -> 0 | K25: =IFERROR(aurora_data!J137,0) -> 0 | L25: =IFERROR(aurora_data!K137,0) -> 0 | ... U25: =IFERROR(aurora_data!T137,0) -> 0 | W25: =IFERROR(aurora_data!U137,0) -> 0 | X25: =IFERROR(W25/$W$20,0) -> 0
D26: Total Assignments | E26: =IFERROR(aurora_data!D138,0) -> 16 | F26: =IFERROR(aurora_data!E138,0) -> 18 | G26: =IFERROR(aurora_data!F138,0) -> 5 | H26: =IFERROR(aurora_data!G138,0) -> 10 | I26: =IFERROR(aurora_data!H138,0) -> 0 | J26: =IFERROR(aurora_data!I138,0) -> 1 | K26: =IFERROR(aurora_data!J138,0) -> 7 | L26: =IFERROR(aurora_data!K138,0) -> 24 | ... U26: =IFERROR(aurora_data!T138,0) -> 0 | W26: =IFERROR(aurora_data!U138,0) -> 49 | X26: =IFERROR(W26/$W$20,0) -> 0.98
D27: Selected | E27: =IFERROR(aurora_data!D139,0) -> 0 | F27: =IFERROR(aurora_data!E139,0) -> 0 | G27: =IFERROR(aurora_data!F139,0) -> 0 | H27: =IFERROR(aurora_data!G139,0) -> 0 | I27: =IFERROR(aurora_data!H139,0) -> 0 | J27: =IFERROR(aurora_data!I139,0) -> 0 | K27: =IFERROR(aurora_data!J139,0) -> 0 | L27: =IFERROR(aurora_data!K139,0) -> 0 | ... U27: =IFERROR(aurora_data!T139,0) -> 0 | W27: =IFERROR(aurora_data!U139,0) -> 0 | X27: =IFERROR(W27/$W$20,0) -> 0
B28: CLOSED | C28: Total | D28: Target | E28: =IFERROR(aurora_data!D12+aurora_data!D140,0) -> 0 | F28: =IFERROR(aurora_data!E12+aurora_data!E140,0) -> 0 | G28: =IFERROR(aurora_data!F12+aurora_data!F140,0) -> 0 | H28: =IFERROR(aurora_data!G12+aurora_data!G140,0) -> 0 | I28: =IFERROR(aurora_data!H12+aurora_data!H140,0) -> 0 | J28: =IFERROR(aurora_data!I12+aurora_data!I140,0) -> 0 | K28: =IFERROR(aurora_data!J12+aurora_data!J140,0) -> 0 | L28: =IFERROR(aurora_data!K12+aurora_data!K140,0) -> 0 | ... U28: =IFERROR(aurora_data!T12+aurora_data!T140,0) -> 0 | W28: =IFERROR(aurora_data!U12+aurora_data!U140,0) -> 100 | X28: =IFERROR(W28/$W$28,0) -> 1
D29: Usable | E29: =IFERROR(aurora_data!D13+aurora_data!D141,0) -> 19 | F29: =IFERROR(aurora_data!E13+aurora_data!E141,0) -> 32 | G29: =IFERROR(aurora_data!F13+aurora_data!F141,0) -> 24 | H29: =IFERROR(aurora_data!G13+aurora_data!G141,0) -> 24 | I29: =IFERROR(aurora_data!H13+aurora_data!H141,0) -> 0 | J29: =IFERROR(aurora_data!I13+aurora_data!I141,0) -> 1 | K29: =IFERROR(aurora_data!J13+aurora_data!J141,0) -> 17 | L29: =IFERROR(aurora_data!K13+aurora_data!K141,0) -> 29 | ... U29: =IFERROR(aurora_data!T13+aurora_data!T141,0) -> 0 | W29: =IFERROR(aurora_data!U13+aurora_data!U141,0) -> 99 | X29: =IFERROR(W29/$W$28,0) -> 0.99
D30: Stratified Out Usable N | E30: =IFERROR(aurora_data!D14+aurora_data!D142,0) -> 0 | F30: =IFERROR(aurora_data!E14+aurora_data!E142,0) -> 0 | G30: =IFERROR(aurora_data!F14+aurora_data!F142,0) -> 0 | H30: =IFERROR(aurora_data!G14+aurora_data!G142,0) -> 0 | I30: =IFERROR(aurora_data!H14+aurora_data!H142,0) -> 0 | J30: =IFERROR(aurora_data!I14+aurora_data!I142,0) -> 0 | K30: =IFERROR(aurora_data!J14+aurora_data!J142,0) -> 0 | L30: =IFERROR(aurora_data!K14+aurora_data!K142,0) -> 0 | ... U30: =IFERROR(aurora_data!T14+aurora_data!T142,0) -> 0 | W30: =IFERROR(aurora_data!U14+aurora_data!U142,0) -> 0 | X30: =IFERROR(W30/$W$28,0) -> 0
D31: In Process | E31: =IFERROR(aurora_data!D15+aurora_data!D143,0) -> 0 | F31: =IFERROR(aurora_data!E15+aurora_data!E143,0) -> 0 | G31: =IFERROR(aurora_data!F15+aurora_data!F143,0) -> 0 | H31: =IFERROR(aurora_data!G15+aurora_data!G143,0) -> 0 | I31: =IFERROR(aurora_data!H15+aurora_data!H143,0) -> 0 | J31: =IFERROR(aurora_data!I15+aurora_data!I143,0) -> 0 | K31: =IFERROR(aurora_data!J15+aurora_data!J143,0) -> 0 | L31: =IFERROR(aurora_data!K15+aurora_data!K143,0) -> 0 | ... U31: =IFERROR(aurora_data!T15+aurora_data!T143,0) -> 0 | W31: =IFERROR(aurora_data!U15+aurora_data!U143,0) -> 0 | X31: =IFERROR(W31/$W$28,0) -> 0
D32: Assigned Not Received | E32: =IFERROR(aurora_data!D16+aurora_data!D144,0) -> 0 | F32: =IFERROR(aurora_data!E16+aurora_data!E144,0) -> 0 | G32: =IFERROR(aurora_data!F16+aurora_data!F144,0) -> 0 | H32: =IFERROR(aurora_data!G16+aurora_data!G144,0) -> 0 | I32: =IFERROR(aurora_data!H16+aurora_data!H144,0) -> 0 | J32: =IFERROR(aurora_data!I16+aurora_data!I144,0) -> 0 | K32: =IFERROR(aurora_data!J16+aurora_data!J144,0) -> 0 | L32: =IFERROR(aurora_data!K16+aurora_data!K144,0) -> 0 | ... U32: =IFERROR(aurora_data!T16+aurora_data!T144,0) -> 0 | W32: =IFERROR(aurora_data!U16+aurora_data!U144,0) -> 0 | X32: =IFERROR(W32/$W$28,0) -> 0
D33: Reserved Not Received | E33: =IFERROR(aurora_data!D17+aurora_data!D145,0) -> 0 | F33: =IFERROR(aurora_data!E17+aurora_data!E145,0) -> 0 | G33: =IFERROR(aurora_data!F17+aurora_data!F145,0) -> 0 | H33: =IFERROR(aurora_data!G17+aurora_data!G145,0) -> 0 | I33: =IFERROR(aurora_data!H17+aurora_data!H145,0) -> 0 | J33: =IFERROR(aurora_data!I17+aurora_data!I145,0) -> 0 | K33: =IFERROR(aurora_data!J17+aurora_data!J145,0) -> 0 | L33: =IFERROR(aurora_data!K17+aurora_data!K145,0) -> 0 | ... U33: =IFERROR(aurora_data!T17+aurora_data!T145,0) -> 0 | W33: =IFERROR(aurora_data!U17+aurora_data!U145,0) -> 0 | X33: =IFERROR(W33/$W$28,0) -> 0
D34: Total Assignments | E34: =IFERROR(aurora_data!D18+aurora_data!D146,0) -> 19 | F34: =IFERROR(aurora_data!E18+aurora_data!E146,0) -> 32 | G34: =IFERROR(aurora_data!F18+aurora_data!F146,0) -> 24 | H34: =IFERROR(aurora_data!G18+aurora_data!G146,0) -> 24 | I34: =IFERROR(aurora_data!H18+aurora_data!H146,0) -> 0 | J34: =IFERROR(aurora_data!I18+aurora_data!I146,0) -> 1 | K34: =IFERROR(aurora_data!J18+aurora_data!J146,0) -> 17 | L34: =IFERROR(aurora_data!K18+aurora_data!K146,0) -> 29 | ... U34: =IFERROR(aurora_data!T18+aurora_data!T146,0) -> 0 | W34: =IFERROR(aurora_data!U18+aurora_data!U146,0) -> 99 | X34: =IFERROR(W34/$W$28,0) -> 0.99
D35: Selected | E35: =IFERROR(aurora_data!D19+aurora_data!D147,0) -> 0 | F35: =IFERROR(aurora_data!E19+aurora_data!E147,0) -> 0 | G35: =IFERROR(aurora_data!F19+aurora_data!F147,0) -> 0 | H35: =IFERROR(aurora_data!G19+aurora_data!G147,0) -> 0 | I35: =IFERROR(aurora_data!H19+aurora_data!H147,0) -> 0 | J35: =IFERROR(aurora_data!I19+aurora_data!I147,0) -> 0 | K35: =IFERROR(aurora_data!J19+aurora_data!J147,0) -> 0 | L35: =IFERROR(aurora_data!K19+aurora_data!K147,0) -> 0 | ... U35: =IFERROR(aurora_data!T19+aurora_data!T147,0) -> 0 | W35: =IFERROR(aurora_data!U19+aurora_data!U147,0) -> 0 | X35: =IFERROR(W35/$W$28,0) -> 0

Sheet C_HH
A1: Total Assigments below Target | D1: Study Information | N1: Additional Information
A2: Usable greater/equal to target | D2: =_xlfn.CONCAT("Study Name: "," CELF-6 RF 1 & 2 Clinical Hard of Hearing (5-16) ") -> Study Name: CELF-6 RF 1 & 2 Clinical Hard of Hearing (5-16) | K2: Usable = case is available to Psychometrics for this study In Process = questionable, In Process Assigned Not Recd = Tests assigned to examiners, no tests received (required tests) Reserved not Received = Tests in reserved status, not received Total Assignments = sum of Usable, Received Non Final, Assigned Partial Received, Assigned Not Received Selected = default status for making an assignment
D3: =_xlfn.CONCAT("Study Acronym: "," C_HH_RF1/C_HH_RF2") -> Study Acronym: C_HH_RF1/C_HH_RF2 | F3: Study ID: 3741 & 3742
D5: Additional Requirements
D6: Collect some of each based on two age bands (ages 5-8, ages 9-16)
B8: =_xlfn.CONCAT("Last Refreshed at: ",aurora_data!V232) -> Last Refreshed at: 08/06/2026 @ 7:19 AM | E8: Demographic Variables | W8: Totals
D9: Variance Tolerance: | E9: some of each, if possible | J9: some of each, if possible | O9: some of each, if possible | S9: some of each, if possible
B10: Status | E10: Education Level | J10: Ethnicity | O10: Region | S10: SEX
C11: ageband | D11: report | E11: 1 | F11: 3 | G11: 3 | H11: 4 | I11: 5 | J11: AS | K11: BL | L11: HI | M11: OTH | N11: WH | O11: MW | P11: NE | Q11: SO | R11: WE | S11: F | T11: M | U11: INT
B12: CLOSED | C12: =aurora_data!A232 -> 05.00.00-08.11.30 | D12: Target | E12: =IFERROR(aurora_data!D232,0) -> 0 | F12: =IFERROR(aurora_data!E232,0) -> 0 | G12: =IFERROR(aurora_data!F232,0) -> 0 | H12: =IFERROR(aurora_data!G232,0) -> 0 | I12: =IFERROR(aurora_data!H232,0) -> 0 | J12: =IFERROR(aurora_data!I232,0) -> 0 | K12: =IFERROR(aurora_data!J232,0) -> 0 | L12: =IFERROR(aurora_data!K232,0) -> 0 | ... U12: =IFERROR(aurora_data!T232,0) -> 0 | W12: =IFERROR(aurora_data!U232,0) -> 30 | X12: =IFERROR(W12/$W$12,0) -> 1
D13: Usable | E13: =IFERROR(aurora_data!D233,0) -> 3 | F13: =IFERROR(aurora_data!E233,0) -> 4 | G13: =IFERROR(aurora_data!F233,0) -> 4 | H13: =IFERROR(aurora_data!G233,0) -> 18 | I13: =IFERROR(aurora_data!H233,0) -> 0 | J13: =IFERROR(aurora_data!I233,0) -> 0 | K13: =IFERROR(aurora_data!J233,0) -> 0 | L13: =IFERROR(aurora_data!K233,0) -> 3 | ... U13: =IFERROR(aurora_data!T233,0) -> 0 | W13: =IFERROR(aurora_data!U233,0) -> 29 | X13: =IFERROR(W13/$W$12,0) -> 0.96666667
D14: Stratified Out Usable N | E14: =IFERROR(aurora_data!D234,0) -> 0 | F14: =IFERROR(aurora_data!E234,0) -> 0 | G14: =IFERROR(aurora_data!F234,0) -> 0 | H14: =IFERROR(aurora_data!G234,0) -> 0 | I14: =IFERROR(aurora_data!H234,0) -> 0 | J14: =IFERROR(aurora_data!I234,0) -> 0 | K14: =IFERROR(aurora_data!J234,0) -> 0 | L14: =IFERROR(aurora_data!K234,0) -> 0 | ... U14: =IFERROR(aurora_data!T234,0) -> 0 | W14: =IFERROR(aurora_data!U234,0) -> 0 | X14: =IFERROR(W14/$W$12,0) -> 0
D15: In Process | E15: =IFERROR(aurora_data!D235,0) -> 0 | F15: =IFERROR(aurora_data!E235,0) -> 0 | G15: =IFERROR(aurora_data!F235,0) -> 0 | H15: =IFERROR(aurora_data!G235,0) -> 0 | I15: =IFERROR(aurora_data!H235,0) -> 0 | J15: =IFERROR(aurora_data!I235,0) -> 0 | K15: =IFERROR(aurora_data!J235,0) -> 0 | L15: =IFERROR(aurora_data!K235,0) -> 0 | ... U15: =IFERROR(aurora_data!T235,0) -> 0 | W15: =IFERROR(aurora_data!U235,0) -> 0 | X15: =IFERROR(W15/$W$12,0) -> 0
D16: Assigned Not Received | E16: =IFERROR(aurora_data!D236,0) -> 0 | F16: =IFERROR(aurora_data!E236,0) -> 0 | G16: =IFERROR(aurora_data!F236,0) -> 0 | H16: =IFERROR(aurora_data!G236,0) -> 0 | I16: =IFERROR(aurora_data!H236,0) -> 0 | J16: =IFERROR(aurora_data!I236,0) -> 0 | K16: =IFERROR(aurora_data!J236,0) -> 0 | L16: =IFERROR(aurora_data!K236,0) -> 0 | ... U16: =IFERROR(aurora_data!T236,0) -> 0 | W16: =IFERROR(aurora_data!U236,0) -> 0 | X16: =IFERROR(W16/$W$12,0) -> 0
D17: Reserved Not Received | E17: =IFERROR(aurora_data!D237,0) -> 0 | F17: =IFERROR(aurora_data!E237,0) -> 0 | G17: =IFERROR(aurora_data!F237,0) -> 0 | H17: =IFERROR(aurora_data!G237,0) -> 0 | I17: =IFERROR(aurora_data!H237,0) -> 0 | J17: =IFERROR(aurora_data!I237,0) -> 0 | K17: =IFERROR(aurora_data!J237,0) -> 0 | L17: =IFERROR(aurora_data!K237,0) -> 0 | ... U17: =IFERROR(aurora_data!T237,0) -> 0 | W17: =IFERROR(aurora_data!U237,0) -> 0 | X17: =IFERROR(W17/$W$12,0) -> 0
D18: Total Assignments | E18: =IFERROR(aurora_data!D238,0) -> 3 | F18: =IFERROR(aurora_data!E238,0) -> 4 | G18: =IFERROR(aurora_data!F238,0) -> 4 | H18: =IFERROR(aurora_data!G238,0) -> 18 | I18: =IFERROR(aurora_data!H238,0) -> 0 | J18: =IFERROR(aurora_data!I238,0) -> 0 | K18: =IFERROR(aurora_data!J238,0) -> 0 | L18: =IFERROR(aurora_data!K238,0) -> 3 | ... U18: =IFERROR(aurora_data!T238,0) -> 0 | W18: =IFERROR(aurora_data!U238,0) -> 29 | X18: =IFERROR(W18/$W$12,0) -> 0.96666667
D19: Selected | E19: =IFERROR(aurora_data!D239,0) -> 0 | F19: =IFERROR(aurora_data!E239,0) -> 0 | G19: =IFERROR(aurora_data!F239,0) -> 0 | H19: =IFERROR(aurora_data!G239,0) -> 0 | I19: =IFERROR(aurora_data!H239,0) -> 0 | J19: =IFERROR(aurora_data!I239,0) -> 0 | K19: =IFERROR(aurora_data!J239,0) -> 0 | L19: =IFERROR(aurora_data!K239,0) -> 0 | ... U19: =IFERROR(aurora_data!T239,0) -> 0 | W19: =IFERROR(aurora_data!U239,0) -> 0 | X19: =IFERROR(W19/$W$12,0) -> 0
B20: CLOSED | C20: =aurora_data!A332 -> 09.00.00-16.11.30 | D20: Target | E20: =IFERROR(aurora_data!D332,0) -> 0 | F20: =IFERROR(aurora_data!E332,0) -> 0 | G20: =IFERROR(aurora_data!F332,0) -> 0 | H20: =IFERROR(aurora_data!G332,0) -> 0 | I20: =IFERROR(aurora_data!H332,0) -> 0 | J20: =IFERROR(aurora_data!I332,0) -> 0 | K20: =IFERROR(aurora_data!J332,0) -> 0 | L20: =IFERROR(aurora_data!K332,0) -> 0 | ... U20: =IFERROR(aurora_data!T332,0) -> 0 | W20: =IFERROR(aurora_data!U332,0) -> 30 | X20: =IFERROR(W20/$W$20,0) -> 1
D21: Usable | E21: =IFERROR(aurora_data!D333,0) -> 1 | F21: =IFERROR(aurora_data!E333,0) -> 1 | G21: =IFERROR(aurora_data!F333,0) -> 5 | H21: =IFERROR(aurora_data!G333,0) -> 24 | I21: =IFERROR(aurora_data!H333,0) -> 0 | J21: =IFERROR(aurora_data!I333,0) -> 0 | K21: =IFERROR(aurora_data!J333,0) -> 0 | L21: =IFERROR(aurora_data!K333,0) -> 2 | ... U21: =IFERROR(aurora_data!T333,0) -> 0 | W21: =IFERROR(aurora_data!U333,0) -> 31 | X21: =IFERROR(W21/$W$20,0) -> 1.0333333
D22: Stratified Out Usable N | E22: =IFERROR(aurora_data!D334,0) -> 0 | F22: =IFERROR(aurora_data!E334,0) -> 0 | G22: =IFERROR(aurora_data!F334,0) -> 0 | H22: =IFERROR(aurora_data!G334,0) -> 4 | I22: =IFERROR(aurora_data!H334,0) -> 0 | J22: =IFERROR(aurora_data!I334,0) -> 0 | K22: =IFERROR(aurora_data!J334,0) -> 0 | L22: =IFERROR(aurora_data!K334,0) -> 0 | ... U22: =IFERROR(aurora_data!T334,0) -> 0 | W22: =IFERROR(aurora_data!U334,0) -> 4 | X22: =IFERROR(W22/$W$20,0) -> 0.13333333
D23: In Process | E23: =IFERROR(aurora_data!D335,0) -> 0 | F23: =IFERROR(aurora_data!E335,0) -> 0 | G23: =IFERROR(aurora_data!F335,0) -> 0 | H23: =IFERROR(aurora_data!G335,0) -> 0 | I23: =IFERROR(aurora_data!H335,0) -> 0 | J23: =IFERROR(aurora_data!I335,0) -> 0 | K23: =IFERROR(aurora_data!J335,0) -> 0 | L23: =IFERROR(aurora_data!K335,0) -> 0 | ... U23: =IFERROR(aurora_data!T335,0) -> 0 | W23: =IFERROR(aurora_data!U335,0) -> 0 | X23: =IFERROR(W23/$W$20,0) -> 0
D24: Assigned Not Received | E24: =IFERROR(aurora_data!D336,0) -> 0 | F24: =IFERROR(aurora_data!E336,0) -> 0 | G24: =IFERROR(aurora_data!F336,0) -> 0 | H24: =IFERROR(aurora_data!G336,0) -> 0 | I24: =IFERROR(aurora_data!H336,0) -> 0 | J24: =IFERROR(aurora_data!I336,0) -> 0 | K24: =IFERROR(aurora_data!J336,0) -> 0 | L24: =IFERROR(aurora_data!K336,0) -> 0 | ... U24: =IFERROR(aurora_data!T336,0) -> 0 | W24: =IFERROR(aurora_data!U336,0) -> 0 | X24: =IFERROR(W24/$W$20,0) -> 0
D25: Reserved Not Received | E25: =IFERROR(aurora_data!D337,0) -> 0 | F25: =IFERROR(aurora_data!E337,0) -> 0 | G25: =IFERROR(aurora_data!F337,0) -> 0 | H25: =IFERROR(aurora_data!G337,0) -> 0 | I25: =IFERROR(aurora_data!H337,0) -> 0 | J25: =IFERROR(aurora_data!I337,0) -> 0 | K25: =IFERROR(aurora_data!J337,0) -> 0 | L25: =IFERROR(aurora_data!K337,0) -> 0 | ... U25: =IFERROR(aurora_data!T337,0) -> 0 | W25: =IFERROR(aurora_data!U337,0) -> 0 | X25: =IFERROR(W25/$W$20,0) -> 0
D26: Total Assignments | E26: =IFERROR(aurora_data!D338,0) -> 1 | F26: =IFERROR(aurora_data!E338,0) -> 1 | G26: =IFERROR(aurora_data!F338,0) -> 5 | H26: =IFERROR(aurora_data!G338,0) -> 28 | I26: =IFERROR(aurora_data!H338,0) -> 0 | J26: =IFERROR(aurora_data!I338,0) -> 0 | K26: =IFERROR(aurora_data!J338,0) -> 0 | L26: =IFERROR(aurora_data!K338,0) -> 2 | ... U26: =IFERROR(aurora_data!T338,0) -> 0 | W26: =IFERROR(aurora_data!U338,0) -> 35 | X26: =IFERROR(W26/$W$20,0) -> 1.1666667
D27: Selected | E27: =IFERROR(aurora_data!D339,0) -> 0 | F27: =IFERROR(aurora_data!E339,0) -> 0 | G27: =IFERROR(aurora_data!F339,0) -> 0 | H27: =IFERROR(aurora_data!G339,0) -> 0 | I27: =IFERROR(aurora_data!H339,0) -> 0 | J27: =IFERROR(aurora_data!I339,0) -> 0 | K27: =IFERROR(aurora_data!J339,0) -> 0 | L27: =IFERROR(aurora_data!K339,0) -> 0 | ... U27: =IFERROR(aurora_data!T339,0) -> 0 | W27: =IFERROR(aurora_data!U339,0) -> 0 | X27: =IFERROR(W27/$W$20,0) -> 0
B28: CLOSED | C28: Total | D28: Target | E28: =IFERROR(aurora_data!D240+aurora_data!D340,0) -> 0 | F28: =IFERROR(aurora_data!E240+aurora_data!E340,0) -> 0 | G28: =IFERROR(aurora_data!F240+aurora_data!F340,0) -> 0 | H28: =IFERROR(aurora_data!G240+aurora_data!G340,0) -> 0 | I28: =IFERROR(aurora_data!H240+aurora_data!H340,0) -> 0 | J28: =IFERROR(aurora_data!I240+aurora_data!I340,0) -> 0 | K28: =IFERROR(aurora_data!J240+aurora_data!J340,0) -> 0 | L28: =IFERROR(aurora_data!K240+aurora_data!K340,0) -> 0 | ... U28: =IFERROR(aurora_data!T240+aurora_data!T340,0) -> 0 | W28: =IFERROR(aurora_data!U240+aurora_data!U340,0) -> 60 | X28: =IFERROR(W28/$W$28,0) -> 1
D29: Usable | E29: =IFERROR(aurora_data!D241+aurora_data!D341,0) -> 4 | F29: =IFERROR(aurora_data!E241+aurora_data!E341,0) -> 5 | G29: =IFERROR(aurora_data!F241+aurora_data!F341,0) -> 9 | H29: =IFERROR(aurora_data!G241+aurora_data!G341,0) -> 42 | I29: =IFERROR(aurora_data!H241+aurora_data!H341,0) -> 0 | J29: =IFERROR(aurora_data!I241+aurora_data!I341,0) -> 0 | K29: =IFERROR(aurora_data!J241+aurora_data!J341,0) -> 0 | L29: =IFERROR(aurora_data!K241+aurora_data!K341,0) -> 5 | ... U29: =IFERROR(aurora_data!T241+aurora_data!T341,0) -> 0 | W29: =IFERROR(aurora_data!U241+aurora_data!U341,0) -> 60 | X29: =IFERROR(W29/$W$28,0) -> 1
D30: Stratified Out Usable N | E30: =IFERROR(aurora_data!D242+aurora_data!D342,0) -> 0 | F30: =IFERROR(aurora_data!E242+aurora_data!E342,0) -> 0 | G30: =IFERROR(aurora_data!F242+aurora_data!F342,0) -> 0 | H30: =IFERROR(aurora_data!G242+aurora_data!G342,0) -> 4 | I30: =IFERROR(aurora_data!H242+aurora_data!H342,0) -> 0 | J30: =IFERROR(aurora_data!I242+aurora_data!I342,0) -> 0 | K30: =IFERROR(aurora_data!J242+aurora_data!J342,0) -> 0 | L30: =IFERROR(aurora_data!K242+aurora_data!K342,0) -> 0 | ... U30: =IFERROR(aurora_data!T242+aurora_data!T342,0) -> 0 | W30: =IFERROR(aurora_data!U242+aurora_data!U342,0) -> 4 | X30: =IFERROR(W30/$W$28,0) -> 0.066666667
D31: In Process | E31: =IFERROR(aurora_data!D243+aurora_data!D343,0) -> 0 | F31: =IFERROR(aurora_data!E243+aurora_data!E343,0) -> 0 | G31: =IFERROR(aurora_data!F243+aurora_data!F343,0) -> 0 | H31: =IFERROR(aurora_data!G243+aurora_data!G343,0) -> 0 | I31: =IFERROR(aurora_data!H243+aurora_data!H343,0) -> 0 | J31: =IFERROR(aurora_data!I243+aurora_data!I343,0) -> 0 | K31: =IFERROR(aurora_data!J243+aurora_data!J343,0) -> 0 | L31: =IFERROR(aurora_data!K243+aurora_data!K343,0) -> 0 | ... U31: =IFERROR(aurora_data!T243+aurora_data!T343,0) -> 0 | W31: =IFERROR(aurora_data!U243+aurora_data!U343,0) -> 0 | X31: =IFERROR(W31/$W$28,0) -> 0
D32: Assigned Not Received | E32: =IFERROR(aurora_data!D244+aurora_data!D344,0) -> 0 | F32: =IFERROR(aurora_data!E244+aurora_data!E344,0) -> 0 | G32: =IFERROR(aurora_data!F244+aurora_data!F344,0) -> 0 | H32: =IFERROR(aurora_data!G244+aurora_data!G344,0) -> 0 | I32: =IFERROR(aurora_data!H244+aurora_data!H344,0) -> 0 | J32: =IFERROR(aurora_data!I244+aurora_data!I344,0) -> 0 | K32: =IFERROR(aurora_data!J244+aurora_data!J344,0) -> 0 | L32: =IFERROR(aurora_data!K244+aurora_data!K344,0) -> 0 | ... U32: =IFERROR(aurora_data!T244+aurora_data!T344,0) -> 0 | W32: =IFERROR(aurora_data!U244+aurora_data!U344,0) -> 0 | X32: =IFERROR(W32/$W$28,0) -> 0
D33: Reserved Not Received | E33: =IFERROR(aurora_data!D245+aurora_data!D345,0) -> 0 | F33: =IFERROR(aurora_data!E245+aurora_data!E345,0) -> 0 | G33: =IFERROR(aurora_data!F245+aurora_data!F345,0) -> 0 | H33: =IFERROR(aurora_data!G245+aurora_data!G345,0) -> 0 | I33: =IFERROR(aurora_data!H245+aurora_data!H345,0) -> 0 | J33: =IFERROR(aurora_data!I245+aurora_data!I345,0) -> 0 | K33: =IFERROR(aurora_data!J245+aurora_data!J345,0) -> 0 | L33: =IFERROR(aurora_data!K245+aurora_data!K345,0) -> 0 | ... U33: =IFERROR(aurora_data!T245+aurora_data!T345,0) -> 0 | W33: =IFERROR(aurora_data!U245+aurora_data!U345,0) -> 0 | X33: =IFERROR(W33/$W$28,0) -> 0
D34: Total Assignments | E34: =IFERROR(aurora_data!D246+aurora_data!D346,0) -> 4 | F34: =IFERROR(aurora_data!E246+aurora_data!E346,0) -> 5 | G34: =IFERROR(aurora_data!F246+aurora_data!F346,0) -> 9 | H34: =IFERROR(aurora_data!G246+aurora_data!G346,0) -> 46 | I34: =IFERROR(aurora_data!H246+aurora_data!H346,0) -> 0 | J34: =IFERROR(aurora_data!I246+aurora_data!I346,0) -> 0 | K34: =IFERROR(aurora_data!J246+aurora_data!J346,0) -> 0 | L34: =IFERROR(aurora_data!K246+aurora_data!K346,0) -> 5 | ... U34: =IFERROR(aurora_data!T246+aurora_data!T346,0) -> 0 | W34: =IFERROR(aurora_data!U246+aurora_data!U346,0) -> 64 | X34: =IFERROR(W34/$W$28,0) -> 1.0666667
D35: Selected | E35: =IFERROR(aurora_data!D247+aurora_data!D347,0) -> 0 | F35: =IFERROR(aurora_data!E247+aurora_data!E347,0) -> 0 | G35: =IFERROR(aurora_data!F247+aurora_data!F347,0) -> 0 | H35: =IFERROR(aurora_data!G247+aurora_data!G347,0) -> 0 | I35: =IFERROR(aurora_data!H247+aurora_data!H347,0) -> 0 | J35: =IFERROR(aurora_data!I247+aurora_data!I347,0) -> 0 | K35: =IFERROR(aurora_data!J247+aurora_data!J347,0) -> 0 | L35: =IFERROR(aurora_data!K247+aurora_data!K347,0) -> 0 | ... U35: =IFERROR(aurora_data!T247+aurora_data!T347,0) -> 0 | W35: =IFERROR(aurora_data!U247+aurora_data!U347,0) -> 0 | X35: =IFERROR(W35/$W$28,0) -> 0

Sheet C_ASDL
A1: 30 | D1: Study Information | N1: Additional Information
A2: Usable greater/equal to target | D2: =_xlfn.CONCAT("Study Name: "," CELF-6 RF 1 & 2 Clinical Autism Spectrum Disorder (5-16) ") -> Study Name: CELF-6 RF 1 & 2 Clinical Autism Spectrum Disorder (5-16) | K2: Usable = case is available to Psychometrics for this study In Process = questionable, In Process Assigned Not Recd = Tests assigned to examiners, no tests received (required tests) Reserved not Received = Tests in reserved status, not received Total Assignments = sum of Usable, Received Non Final, Assigned Partial Received, Assigned Not Received Selected = default status for making an assignment
D3: =_xlfn.CONCAT("Study Acronym: "," C_ASDL_RF1/C_ASDL_RF2") -> Study Acronym: C_ASDL_RF1/C_ASDL_RF2 | F3: Study ID: 3743 & 3744
D5: Additional Requirements
D6: Collect some of each based on two age bands (ages 5-8, ages 9-16)
B8: =_xlfn.CONCAT("Last Refreshed at: ",aurora_data!V432) -> Last Refreshed at: 08/06/2026 @ 7:19 AM | E8: Demographic Variables | W8: Totals
D9: Variance Tolerance: | E9: some of each, if possible | J9: some of each, if possible | O9: some of each, if possible | S9: some of each, if possible
B10: Status | E10: Education Level | J10: Ethnicity | O10: Region | S10: SEX
C11: ageband | D11: report | E11: 1 | F11: 2 | G11: 3 | H11: 4 | I11: 5 | J11: AS | K11: BL | L11: HI | M11: OTH | N11: WH | O11: MW | P11: NE | Q11: SO | R11: WE | S11: F | T11: M | U11: INT
B12: CLOSED | C12: =aurora_data!A432 -> 05.00.00-08.11.30 | D12: Target | E12: =IFERROR(aurora_data!D432,0) -> 0 | F12: =IFERROR(aurora_data!E432,0) -> 0 | G12: =IFERROR(aurora_data!F432,0) -> 0 | H12: =IFERROR(aurora_data!G432,0) -> 0 | I12: =IFERROR(aurora_data!H432,0) -> 0 | J12: =IFERROR(aurora_data!I432,0) -> 0 | K12: =IFERROR(aurora_data!J432,0) -> 0 | L12: =IFERROR(aurora_data!K432,0) -> 0 | ... U12: =IFERROR(aurora_data!T432,0) -> 0 | W12: =IFERROR(aurora_data!U432,0) -> 30 | X12: =IFERROR(W12/$W$12,0) -> 1
D13: Usable | E13: =IFERROR(aurora_data!D433,0) -> 0 | F13: =IFERROR(aurora_data!E433,0) -> 6 | G13: =IFERROR(aurora_data!F433,0) -> 8 | H13: =IFERROR(aurora_data!G433,0) -> 16 | I13: =IFERROR(aurora_data!H433,0) -> 0 | J13: =IFERROR(aurora_data!I433,0) -> 2 | K13: =IFERROR(aurora_data!J433,0) -> 2 | L13: =IFERROR(aurora_data!K433,0) -> 6 | ... U13: =IFERROR(aurora_data!T433,0) -> 0 | W13: =IFERROR(aurora_data!U433,0) -> 30 | X13: =IFERROR(W13/$W$12,0) -> 1
D14: Stratified Out Usable N | E14: =IFERROR(aurora_data!D434,0) -> 0 | F14: =IFERROR(aurora_data!E434,0) -> 0 | G14: =IFERROR(aurora_data!F434,0) -> 0 | H14: =IFERROR(aurora_data!G434,0) -> 0 | I14: =IFERROR(aurora_data!H434,0) -> 0 | J14: =IFERROR(aurora_data!I434,0) -> 0 | K14: =IFERROR(aurora_data!J434,0) -> 0 | L14: =IFERROR(aurora_data!K434,0) -> 0 | ... U14: =IFERROR(aurora_data!T434,0) -> 0 | W14: =IFERROR(aurora_data!U434,0) -> 0 | X14: =IFERROR(W14/$W$12,0) -> 0
D15: In Process | E15: =IFERROR(aurora_data!D435,0) -> 0 | F15: =IFERROR(aurora_data!E435,0) -> 0 | G15: =IFERROR(aurora_data!F435,0) -> 0 | H15: =IFERROR(aurora_data!G435,0) -> 0 | I15: =IFERROR(aurora_data!H435,0) -> 0 | J15: =IFERROR(aurora_data!I435,0) -> 0 | K15: =IFERROR(aurora_data!J435,0) -> 0 | L15: =IFERROR(aurora_data!K435,0) -> 0 | ... U15: =IFERROR(aurora_data!T435,0) -> 0 | W15: =IFERROR(aurora_data!U435,0) -> 0 | X15: =IFERROR(W15/$W$12,0) -> 0
D16: Assigned Not Received | E16: =IFERROR(aurora_data!D436,0) -> 0 | F16: =IFERROR(aurora_data!E436,0) -> 0 | G16: =IFERROR(aurora_data!F436,0) -> 0 | H16: =IFERROR(aurora_data!G436,0) -> 0 | I16: =IFERROR(aurora_data!H436,0) -> 0 | J16: =IFERROR(aurora_data!I436,0) -> 0 | K16: =IFERROR(aurora_data!J436,0) -> 0 | L16: =IFERROR(aurora_data!K436,0) -> 0 | ... U16: =IFERROR(aurora_data!T436,0) -> 0 | W16: =IFERROR(aurora_data!U436,0) -> 0 | X16: =IFERROR(W16/$W$12,0) -> 0
D17: Reserved Not Received | E17: =IFERROR(aurora_data!D437,0) -> 0 | F17: =IFERROR(aurora_data!E437,0) -> 0 | G17: =IFERROR(aurora_data!F437,0) -> 0 | H17: =IFERROR(aurora_data!G437,0) -> 0 | I17: =IFERROR(aurora_data!H437,0) -> 0 | J17: =IFERROR(aurora_data!I437,0) -> 0 | K17: =IFERROR(aurora_data!J437,0) -> 0 | L17: =IFERROR(aurora_data!K437,0) -> 0 | ... U17: =IFERROR(aurora_data!T437,0) -> 0 | W17: =IFERROR(aurora_data!U437,0) -> 0 | X17: =IFERROR(W17/$W$12,0) -> 0
D18: Total Assignments | E18: =IFERROR(aurora_data!D438,0) -> 0 | F18: =IFERROR(aurora_data!E438,0) -> 6 | G18: =IFERROR(aurora_data!F438,0) -> 8 | H18: =IFERROR(aurora_data!G438,0) -> 16 | I18: =IFERROR(aurora_data!H438,0) -> 0 | J18: =IFERROR(aurora_data!I438,0) -> 2 | K18: =IFERROR(aurora_data!J438,0) -> 2 | L18: =IFERROR(aurora_data!K438,0) -> 6 | ... U18: =IFERROR(aurora_data!T438,0) -> 0 | W18: =IFERROR(aurora_data!U438,0) -> 30 | X18: =IFERROR(W18/$W$12,0) -> 1
D19: Selected | E19: =IFERROR(aurora_data!D439,0) -> 0 | F19: =IFERROR(aurora_data!E439,0) -> 0 | G19: =IFERROR(aurora_data!F439,0) -> 0 | H19: =IFERROR(aurora_data!G439,0) -> 0 | I19: =IFERROR(aurora_data!H439,0) -> 0 | J19: =IFERROR(aurora_data!I439,0) -> 0 | K19: =IFERROR(aurora_data!J439,0) -> 0 | L19: =IFERROR(aurora_data!K439,0) -> 0 | ... U19: =IFERROR(aurora_data!T439,0) -> 0 | W19: =IFERROR(aurora_data!U439,0) -> 0 | X19: =IFERROR(W19/$W$12,0) -> 0
B20: CLOSED | C20: =aurora_data!A532 -> 09.00.00-16.11.30 | D20: Target | E20: =IFERROR(aurora_data!D532,0) -> 0 | F20: =IFERROR(aurora_data!E532,0) -> 0 | G20: =IFERROR(aurora_data!F532,0) -> 0 | H20: =IFERROR(aurora_data!G532,0) -> 0 | I20: =IFERROR(aurora_data!H532,0) -> 0 | J20: =IFERROR(aurora_data!I532,0) -> 0 | K20: =IFERROR(aurora_data!J532,0) -> 0 | L20: =IFERROR(aurora_data!K532,0) -> 0 | ... U20: =IFERROR(aurora_data!T532,0) -> 0 | W20: =IFERROR(aurora_data!U532,0) -> 30 | X20: =IFERROR(W20/$W$20,0) -> 1
D21: Usable | E21: =IFERROR(aurora_data!D533,0) -> 0 | F21: =IFERROR(aurora_data!E533,0) -> 5 | G21: =IFERROR(aurora_data!F533,0) -> 10 | H21: =IFERROR(aurora_data!G533,0) -> 15 | I21: =IFERROR(aurora_data!H533,0) -> 0 | J21: =IFERROR(aurora_data!I533,0) -> 4 | K21: =IFERROR(aurora_data!J533,0) -> 0 | L21: =IFERROR(aurora_data!K533,0) -> 7 | ... U21: =IFERROR(aurora_data!T533,0) -> 0 | W21: =IFERROR(aurora_data!U533,0) -> 30 | X21: =IFERROR(W21/$W$20,0) -> 1
D22: Stratified Out Usable N | E22: =IFERROR(aurora_data!D534,0) -> 0 | F22: =IFERROR(aurora_data!E534,0) -> 0 | G22: =IFERROR(aurora_data!F534,0) -> 0 | H22: =IFERROR(aurora_data!G534,0) -> 1 | I22: =IFERROR(aurora_data!H534,0) -> 0 | J22: =IFERROR(aurora_data!I534,0) -> 0 | K22: =IFERROR(aurora_data!J534,0) -> 0 | L22: =IFERROR(aurora_data!K534,0) -> 0 | ... U22: =IFERROR(aurora_data!T534,0) -> 0 | W22: =IFERROR(aurora_data!U534,0) -> 1 | X22: =IFERROR(W22/$W$20,0) -> 0.033333333
D23: In Process | E23: =IFERROR(aurora_data!D535,0) -> 0 | F23: =IFERROR(aurora_data!E535,0) -> 0 | G23: =IFERROR(aurora_data!F535,0) -> 0 | H23: =IFERROR(aurora_data!G535,0) -> 0 | I23: =IFERROR(aurora_data!H535,0) -> 0 | J23: =IFERROR(aurora_data!I535,0) -> 0 | K23: =IFERROR(aurora_data!J535,0) -> 0 | L23: =IFERROR(aurora_data!K535,0) -> 0 | ... U23: =IFERROR(aurora_data!T535,0) -> 0 | W23: =IFERROR(aurora_data!U535,0) -> 0 | X23: =IFERROR(W23/$W$20,0) -> 0
D24: Assigned Not Received | E24: =IFERROR(aurora_data!D536,0) -> 0 | F24: =IFERROR(aurora_data!E536,0) -> 0 | G24: =IFERROR(aurora_data!F536,0) -> 0 | H24: =IFERROR(aurora_data!G536,0) -> 0 | I24: =IFERROR(aurora_data!H536,0) -> 0 | J24: =IFERROR(aurora_data!I536,0) -> 0 | K24: =IFERROR(aurora_data!J536,0) -> 0 | L24: =IFERROR(aurora_data!K536,0) -> 0 | ... U24: =IFERROR(aurora_data!T536,0) -> 0 | W24: =IFERROR(aurora_data!U536,0) -> 0 | X24: =IFERROR(W24/$W$20,0) -> 0
D25: Reserved Not Received | E25: =IFERROR(aurora_data!D537,0) -> 0 | F25: =IFERROR(aurora_data!E537,0) -> 0 | G25: =IFERROR(aurora_data!F537,0) -> 0 | H25: =IFERROR(aurora_data!G537,0) -> 0 | I25: =IFERROR(aurora_data!H537,0) -> 0 | J25: =IFERROR(aurora_data!I537,0) -> 0 | K25: =IFERROR(aurora_data!J537,0) -> 0 | L25: =IFERROR(aurora_data!K537,0) -> 0 | ... U25: =IFERROR(aurora_data!T537,0) -> 0 | W25: =IFERROR(aurora_data!U537,0) -> 0 | X25: =IFERROR(W25/$W$20,0) -> 0
D26: Total Assignments | E26: =IFERROR(aurora_data!D538,0) -> 0 | F26: =IFERROR(aurora_data!E538,0) -> 5 | G26: =IFERROR(aurora_data!F538,0) -> 10 | H26: =IFERROR(aurora_data!G538,0) -> 16 | I26: =IFERROR(aurora_data!H538,0) -> 0 | J26: =IFERROR(aurora_data!I538,0) -> 4 | K26: =IFERROR(aurora_data!J538,0) -> 0 | L26: =IFERROR(aurora_data!K538,0) -> 7 | ... U26: =IFERROR(aurora_data!T538,0) -> 0 | W26: =IFERROR(aurora_data!U538,0) -> 31 | X26: =IFERROR(W26/$W$20,0) -> 1.0333333
D27: Selected | E27: =IFERROR(aurora_data!D539,0) -> 0 | F27: =IFERROR(aurora_data!E539,0) -> 0 | G27: =IFERROR(aurora_data!F539,0) -> 0 | H27: =IFERROR(aurora_data!G539,0) -> 0 | I27: =IFERROR(aurora_data!H539,0) -> 0 | J27: =IFERROR(aurora_data!I539,0) -> 0 | K27: =IFERROR(aurora_data!J539,0) -> 0 | L27: =IFERROR(aurora_data!K539,0) -> 0 | ... U27: =IFERROR(aurora_data!T539,0) -> 0 | W27: =IFERROR(aurora_data!U539,0) -> 0 | X27: =IFERROR(W27/$W$20,0) -> 0
B28: CLOSED | C28: Total | D28: Target | E28: =IFERROR(aurora_data!D440+aurora_data!D540,0) -> 0 | F28: =IFERROR(aurora_data!E440+aurora_data!E540,0) -> 0 | G28: =IFERROR(aurora_data!F440+aurora_data!F540,0) -> 0 | H28: =IFERROR(aurora_data!G440+aurora_data!G540,0) -> 0 | I28: =IFERROR(aurora_data!H440+aurora_data!H540,0) -> 0 | J28: =IFERROR(aurora_data!I440+aurora_data!I540,0) -> 0 | K28: =IFERROR(aurora_data!J440+aurora_data!J540,0) -> 0 | L28: =IFERROR(aurora_data!K440+aurora_data!K540,0) -> 0 | ... U28: =IFERROR(aurora_data!T440+aurora_data!T540,0) -> 0 | W28: =IFERROR(aurora_data!U440+aurora_data!U540,0) -> 60 | X28: =IFERROR(W28/$W$28,0) -> 1
D29: Usable | E29: =IFERROR(aurora_data!D441+aurora_data!D541,0) -> 0 | F29: =IFERROR(aurora_data!E441+aurora_data!E541,0) -> 11 | G29: =IFERROR(aurora_data!F441+aurora_data!F541,0) -> 18 | H29: =IFERROR(aurora_data!G441+aurora_data!G541,0) -> 31 | I29: =IFERROR(aurora_data!H441+aurora_data!H541,0) -> 0 | J29: =IFERROR(aurora_data!I441+aurora_data!I541,0) -> 6 | K29: =IFERROR(aurora_data!J441+aurora_data!J541,0) -> 2 | L29: =IFERROR(aurora_data!K441+aurora_data!K541,0) -> 13 | ... U29: =IFERROR(aurora_data!T441+aurora_data!T541,0) -> 0 | W29: =IFERROR(aurora_data!U441+aurora_data!U541,0) -> 60 | X29: =IFERROR(W29/$W$28,0) -> 1
D30: Stratified Out Usable N | E30: =IFERROR(aurora_data!D442+aurora_data!D542,0) -> 0 | F30: =IFERROR(aurora_data!E442+aurora_data!E542,0) -> 0 | G30: =IFERROR(aurora_data!F442+aurora_data!F542,0) -> 0 | H30: =IFERROR(aurora_data!G442+aurora_data!G542,0) -> 1 | I30: =IFERROR(aurora_data!H442+aurora_data!H542,0) -> 0 | J30: =IFERROR(aurora_data!I442+aurora_data!I542,0) -> 0 | K30: =IFERROR(aurora_data!J442+aurora_data!J542,0) -> 0 | L30: =IFERROR(aurora_data!K442+aurora_data!K542,0) -> 0 | ... U30: =IFERROR(aurora_data!T442+aurora_data!T542,0) -> 0 | W30: =IFERROR(aurora_data!U442+aurora_data!U542,0) -> 1 | X30: =IFERROR(W30/$W$28,0) -> 0.016666667
D31: In Process | E31: =IFERROR(aurora_data!D443+aurora_data!D543,0) -> 0 | F31: =IFERROR(aurora_data!E443+aurora_data!E543,0) -> 0 | G31: =IFERROR(aurora_data!F443+aurora_data!F543,0) -> 0 | H31: =IFERROR(aurora_data!G443+aurora_data!G543,0) -> 0 | I31: =IFERROR(aurora_data!H443+aurora_data!H543,0) -> 0 | J31: =IFERROR(aurora_data!I443+aurora_data!I543,0) -> 0 | K31: =IFERROR(aurora_data!J443+aurora_data!J543,0) -> 0 | L31: =IFERROR(aurora_data!K443+aurora_data!K543,0) -> 0 | ... U31: =IFERROR(aurora_data!T443+aurora_data!T543,0) -> 0 | W31: =IFERROR(aurora_data!U443+aurora_data!U543,0) -> 0 | X31: =IFERROR(W31/$W$28,0) -> 0
