Workbook

Sheet Open Cells
A8: =setup!C16 -> 3766
A9: =setup!D16 -> WISC-6 Standardization - Paper
A10: status | B10: day | C10: Yr | D10: Wk | E10: WeekOf | F10: ageband | G10: variable_type | H10: variable_value | I10: target | J10: targetRounded | K10: AssignDay | L10: AssignCounts | M10: totalCells | N10: cummAssingCount | O10: openCells | P10: reportSession | Q10: last_refreshed
A11: Total Assignments | B11: 07/18/2025 | C11: 2025 | D11: 29 | E11: 07/14/2025 | F11: 05.00.00-05.05.30 | G11: ETH | H11: AS | I11: 4.58 | J11: 5 | K11: 07/18/2025 | L11: 0 | M11: 2400 | N11: 0 | O11: 5 | P11: 0 | Q11: 07/18/2025 @ 6:55 AM
A12: Total Assignments | B12: 07/18/2025 | C12: 2025 | D12: 29 | E12: 07/14/2025 | F12: 05.00.00-05.05.30 | G12: ETH | H12: HI | I12: 23.1 | J12: 23 | K12: 07/18/2025 | L12: 0 | M12: 2400 | N12: 0 | O12: 23 | P12: 0 | Q12: 07/18/2025 @ 6:55 AM
A13: Total Assignments | B13: 07/18/2025 | C13: 2025 | D13: 29 | E13: 07/14/2025 | F13: 05.00.00-05.05.30 | G13: SEX | H13: OTHER | I13: 0 | J13: 0 | K13: 07/18/2025 | L13: 0 | M13: 2400 | N13: 0 | O13: 0 | P13: 0 | Q13: 07/18/2025 @ 6:55 AM
A14: Total Assignments | B14: 07/18/2025 | C14: 2025 | D14: 29 | E14: 07/14/2025 | F14: 05.06.00-05.11.30 | G14: ED | H14: 1 | I14: 6.96 | J14: 7 | K14: 01/01/2024 | L14: 1 | M14: 2400 | N14: 1 | O14: 6 | P14: 0 | Q14: 07/18/2025 @ 6:55 AM
A15: Total Assignments | B15: 07/18/2025 | C15: 2025 | D15: 29 | E15: 07/14/2025 | F15: 05.06.00-05.11.30 | G15: ETH | H15: HI | I15: 23.1 | J15: 23 | K15: 01/01/2024 | L15: 1 | M15: 2400 | N15: 1 | O15: 22 | P15: 0 | Q15: 07/18/2025 @ 6:55 AM
A16: Total Assignments | B16: 07/18/2025 | C16: 2025 | D16: 29 | E16: 07/14/2025 | F16: 05.06.00-05.11.30 | G16: ETH | H16: OT | I16: 10.54 | J16: 11 | K16: 07/18/2025 | L16: 0 | M16: 2400 | N16: 0 | O16: 11 | P16: 0 | Q16: 07/18/2025 @ 6:55 AM
A17: Total Assignments | B17: 07/18/2025 | C17: 2025 | D17: 29 | E17: 07/14/2025 | F17: 05.06.00-05.11.30 | G17: REGION | H17: SO | I17: 39.96 | J17: 40 | K17: 01/01/2024 | L17: 1 | M17: 2400 | N17: 1 | O17: 39 | P17: 0 | Q17: 07/18/2025 @ 6:55 AM
A18: Total Assignments | B18: 07/18/2025 | C18: 2025 | D18: 29 | E18: 07/14/2025 | F18: 05.06.00-05.11.30 | G18: SEX | H18: M | I18: 50 | J18: 50 | K18: 01/01/2024 | L18: 1 | M18: 2400 | N18: 1 | O18: 49 | P18: 0 | Q18: 07/18/2025 @ 6:55 AM
A19: Total Assignments | B19: 07/18/2025 | C19: 2025 | D19: 29 | E19: 07/14/2025 | F19: 05.06.00-05.11.30 | G19: SEX | H19: OTHER | I19: 0 | J19: 0 | K19: 07/18/2025 | L19: 0 | M19: 2400 | N19: 0 | O19: 0 | P19: 0 | Q19: 07/18/2025 @ 6:55 AM
A20: Total Assignments | B20: 07/18/2025 | C20: 2025 | D20: 29 | E20: 07/14/2025 | F20: 06.00.00-06.05.30 | G20: ED | H20: 1 | I20: 7.57 | J20: 8 | K20: 07/18/2025 | L20: 0 | M20: 2400 | N20: 0 | O20: 8 | P20: 0 | Q20: 07/18/2025 @ 6:55 AM
A21: Total Assignments | B21: 07/18/2025 | C21: 2025 | D21: 29 | E21: 07/14/2025 | F21: 06.00.00-06.05.30 | G21: ETH | H21: BL | I21: 12.25 | J21: 12 | K21: 07/18/2025 | L21: 0 | M21: 2400 | N21: 0 | O21: 12 | P21: 0 | Q21: 07/18/2025 @ 6:55 AM
A22: Total Assignments | B22: 07/18/2025 | C22: 2025 | D22: 29 | E22: 07/14/2025 | F22: 06.00.00-06.05.30 | G22: SEX | H22: OTHER | I22: 0 | J22: 0 | K22: 07/18/2025 | L22: 0 | M22: 2400 | N22: 0 | O22: 0 | P22: 0 | Q22: 07/18/2025 @ 6:55 AM
... A28: Total Assignments | B28: 07/18/2025 | C28: 2025 | D28: 29 | E28: 07/14/2025 | F28: 08.00.00-08.11.30 | G28: SEX | H28: OTHER | I28: 0 | J28: 0 | K28: 07/18/2025 | L28: 0 | M28: 2400 | N28: 0 | O28: 0 | P28: 0 | Q28: 07/18/2025 @ 6:55 AM
A80: =setup!C17 -> 3767
A81: =setup!D17 -> WISC-6 Standardization - Digital
A82: status | B82: day | C82: Yr | D82: Wk | E82: WeekOf | F82: ageband | G82: variable_type | H82: variable_value | I82: target | J82: targetRounded | K82: AssignDay | L82: AssignCounts | M82: totalCells | N82: cummAssingCount | O82: openCells | P82: reportSession | Q82: last_refreshed
A83: Total Assignments | B83: 07/17/2025 | C83: 2025 | D83: 29 | E83: 07/14/2025 | F83: 09.00.00-09.11.30 | G83: ED | H83: 1 | I83: 8.29 | J83: 8 | K83: 01/01/2024 | L83: 1 | M83: 3600 | N83: 1 | O83: 7 | P83: 0 | Q83: 07/17/2025 @ 10:36 AM
A84: Total Assignments | B84: 07/17/2025 | C84: 2025 | D84: 29 | E84: 07/14/2025 | F84: 09.00.00-09.11.30 | G84: ETH | H84: HI | I84: 24 | J84: 24 | K84: 01/01/2024 | L84: 1 | M84: 3600 | N84: 1 | O84: 23 | P84: 0 | Q84: 07/17/2025 @ 10:36 AM
A85: Total Assignments | B85: 07/17/2025 | C85: 2025 | D85: 29 | E85: 07/14/2025 | F85: 09.00.00-09.11.30 | G85: ETH | H85: OT | I85: 9.92 | J85: 10 | K85: 07/17/2025 | L85: 0 | M85: 3600 | N85: 0 | O85: 10 | P85: 0 | Q85: 07/17/2025 @ 10:36 AM
A86: Total Assignments | B86: 07/17/2025 | C86: 2025 | D86: 29 | E86: 07/14/2025 | F86: 09.00.00-09.11.30 | G86: REGION | H86: SO | I86: 39.7 | J86: 40 | K86: 01/01/2024 | L86: 1 | M86: 3600 | N86: 1 | O86: 39 | P86: 0 | Q86: 07/17/2025 @ 10:36 AM
A87: Total Assignments | B87: 07/17/2025 | C87: 2025 | D87: 29 | E87: 07/14/2025 | F87: 09.00.00-09.11.30 | G87: SEX | H87: F | I87: 50 | J87: 50 | K87: 01/01/2024 | L87: 1 | M87: 3600 | N87: 1 | O87: 49 | P87: 0 | Q87: 07/17/2025 @ 10:36 AM
A88: Total Assignments | B88: 07/17/2025 | C88: 2025 | D88: 29 | E88: 07/14/2025 | F88: 09.00.00-09.11.30 | G88: SEX | H88: OTHER | I88: 0 | J88: 0 | K88: 07/17/2025 | L88: 0 | M88: 3600 | N88: 0 | O88: 0 | P88: 0 | Q88: 07/17/2025 @ 10:36 AM
A89: Total Assignments | B89: 07/17/2025 | C89: 2025 | D89: 29 | E89: 07/14/2025 | F89: 10.00.00-10.11.30 | G89: ED | H89: 1 | I89: 8.85 | J89: 9 | K89: 01/01/2024 | L89: 1 | M89: 3600 | N89: 1 | O89: 8 | P89: 0 | Q89: 07/17/2025 @ 10:36 AM
A90: Total Assignments | B90: 07/17/2025 | C90: 2025 | D90: 29 | E90: 07/14/2025 | F90: 10.00.00-10.11.30 | G90: ETH | H90: AS | I90: 5.17 | J90: 5 | K90: 01/01/2024 | L90: 1 | M90: 3600 | N90: 1 | O90: 4 | P90: 0 | Q90: 07/17/2025 @ 10:36 AM
A91: Total Assignments | B91: 07/17/2025 | C91: 2025 | D91: 29 | E91: 07/14/2025 | F91: 10.00.00-10.11.30 | G91: REGION | H91: NE | I91: 15.25 | J91: 15 | K91: 01/01/2024 | L91: 1 | M91: 3600 | N91: 1 | O91: 14 | P91: 0 | Q91: 07/17/2025 @ 10:36 AM
A92: Total Assignments | B92: 07/17/2025 | C92: 2025 | D92: 29 | E92: 07/14/2025 | F92: 10.00.00-10.11.30 | G92: SEX | H92: F | I92: 50 | J92: 50 | K92: 01/01/2024 | L92: 1 | M92: 3600 | N92: 1 | O92: 49 | P92: 0 | Q92: 07/17/2025 @ 10:36 AM
A93: Total Assignments | B93: 07/17/2025 | C93: 2025 | D93: 29 | E93: 07/14/2025 | F93: 10.00.00-10.11.30 | G93: SEX | H93: OTHER | I93: 0 | J93: 0 | K93: 07/17/2025 | L93: 0 | M93: 3600 | N93: 0 | O93: 0 | P93: 0 | Q93: 07/17/2025 @ 10:36 AM
A94: Total Assignments | B94: 07/17/2025 | C94: 2025 | D94: 29 | E94: 07/14/2025 | F94: 11.00.00-11.11.30 | G94: SEX | H94: OTHER | I94: 0 | J94: 0 | K94: 07/17/2025 | L94: 0 | M94: 3600 | N94: 0 | O94: 0 | P94: 0 | Q94: 07/17/2025 @ 10:36 AM
... A130: Total Assignments | B130: 07/17/2025 | C130: 2025 | D130: 29 | E130: 07/14/2025 | F130: 17.00.00-21.11.30 | G130: SEX | H130: OTHER | I130: 0 | J130: 0 | K130: 07/17/2025 | L130: 0 | M130: 3600 | N130: 0 | O130: 0 | P130: 0 | Q130: 07/17/2025 @ 10:36 AM
A182: =setup!C18 -> 3768
A183: =setup!D18 -> Retest WISC-6 Standardization - Paper
A184: status | B184: day | C184: Yr | D184: Wk | E184: WeekOf | F184: ageband | G184: variable_type | H184: variable_value | I184: target | J184: targetRounded | K184: AssignDay | L184: AssignCounts | M184: totalCells | N184: cummAssingCount | O184: openCells | P184: reportSession | Q184: last_refreshed
A185: Total Assignments | B185: 07/17/2025 | C185: 2025 | D185: 29 | E185: 07/14/2025 | F185: 05.00.00-06.11.30 | H185: 5 | I185: 1 | J185: 1 | K185: 07/17/2025 | L185: 0 | M185: 32 | N185: 0 | O185: 1 | P185: 0 | Q185: 07/17/2025 @ 10:36 AM
A186: Total Assignments | B186: 07/17/2025 | C186: 2025 | D186: 29 | E186: 07/14/2025 | F186: 05.00.00-06.11.30 | G186: ED | H186: 1 | I186: 1 | J186: 1 | K186: 07/17/2025 | L186: 0 | M186: 32 | N186: 0 | O186: 1 | P186: 0 | Q186: 07/17/2025 @ 10:36 AM
A187: Total Assignments | B187: 07/17/2025 | C187: 2025 | D187: 29 | E187: 07/14/2025 | F187: 05.00.00-06.11.30 | G187: ED | H187: 2 | I187: 1 | J187: 1 | K187: 07/17/2025 | L187: 0 | M187: 32 | N187: 0 | O187: 1 | P187: 0 | Q187: 07/17/2025 @ 10:36 AM
A188: Total Assignments | B188: 07/17/2025 | C188: 2025 | D188: 29 | E188: 07/14/2025 | F188: 05.00.00-06.11.30 | G188: ED | H188: 3 | I188: 1 | J188: 1 | K188: 07/17/2025 | L188: 0 | M188: 32 | N188: 0 | O188: 1 | P188: 0 | Q188: 07/17/2025 @ 10:36 AM
A189: Total Assignments | B189: 07/17/2025 | C189: 2025 | D189: 29 | E189: 07/14/2025 | F189: 05.00.00-06.11.30 | G189: ED | H189: 4 | I189: 1 | J189: 1 | K189: 07/17/2025 | L189: 0 | M189: 32 | N189: 0 | O189: 1 | P189: 0 | Q189: 07/17/2025 @ 10:36 AM
...

Sheet setup
B3: Phase Setup
B4: Phase Id | C4: 405
B6: Main Study Setup | H6: Stratification Types | K6: matrix sproc
C7: Stratification % | D7: (separate study ids by and exclamation point ! for more than one) | E7: Stratification Type | H7: 1 = 2 Cross | K7: call report_matrix(studyids, stratfication type, stratification%);
B8: StudyIDs (2Cross) | C8: 50 | D8: 3037 | E8: 1 | H8: 2 = 3 Cross ETH/ED
B9: StudyIDs (3Cross) | C9: 50 | D9: 3037 | E9: 2 | H9: 3 = 3 Cross SEX/ETH
B10: StudyIDs (2Cross) | C10: 100 | D10: 3037 | E10: 1
B11: StudyIDs (3Cross) | C11: 100 | D11: 3037 | E11: 2
B12: StudyIDs (3Cross alternate view) | C12: 100 | D12: 3037 | E12: 3
B13: Validity/Reliability Setup | H13: Total study count for this report | K13: =COUNTIF(M:M, "Active") - COUNTIFS(L:L, "OSEP*",M:M, "Active") - COUNTIFS(L:L,"C_*",M:M, "Active") +2 -> 37
B14: Reports will show based on the ordered list below | H14: Phase Study List
B15: Report Order (do not touch) | C15: Study Id (separate studyids by !) | D15: Study Name | E15: Study Acronym | F15: Total Assignment | H15: study_id | I15: study_type_description | J15: sort_order | K15: study_name | L15: study_acronym | M15: study_status
A16: =LEN(C16) - LEN(SUBSTITUTE(C16, "!", "")) + 1 -> 1 | B16: 1 | C16: 3766 | D16: WISC-6 Standardization - Paper | E16: WISC6_STDZ_P | F16: =aurora_data!AJ98 -> 2523 | H16: 3767 | I16: Main | J16: 1 | K16: WISC-6 Standardization - Digital | L16: WISC6_STDZ_D | M16: Active
A17: =LEN(C17) - LEN(SUBSTITUTE(C17, "!", "")) + 1 -> 1 | B17: 2 | C17: 3767 | D17: WISC-6 Standardization - Digital | E17: WISC6_STDZ_D | F17: =aurora_data!AJ226 -> 568 | H17: 3766 | I17: Main | J17: 1 | K17: WISC-6 Standardization - Paper | L17: WISC6_STDZ_P | M17: Active
A18: =LEN(C18) - LEN(SUBSTITUTE(C18, "!", "")) + 1 -> 1 | B18: 3 | C18: 3768 | D18: Retest WISC-6 Standardization - Paper | E18: R_WISC6_STDZ_P | F18: =aurora_data!U438 -> 235 | H18: 3814 | I18: Clinical | J18: 2 | K18: WISC-6 Clinical Validity Motor Impairment - Paper | L18: CV_MI_VINE3_P | M18: Active
A19: =LEN(C19) - LEN(SUBSTITUTE(C19, "!", "")) + 1 -> 1 | B19: 4 | C19: 3769 | D19: Retest WISC-6 Standardization Digital | E19: R_WISC6_STDZ_D | F19: =aurora_data!U566 -> 93 | H19: 3822 | I19: Clinical | J19: 2 | K19: OSEP – Other Health Impairment - Paper | L19: OSEP_OHI_P | M19: Active
A20: =LEN(C20) - LEN(SUBSTITUTE(C20, "!", "")) + 1 -> 1 | B20: 5 | C20: 3770 | D20: Validity WISC-6/WISC-5 Plus - Paper | E20: V_WISC5P_P | F20: =aurora_data!U838 -> 137 | H20: 3821 | I20: Clinical | J20: 2 | K20: OSEP – Orthopedic Impairment - Paper | L20: OSEP_OI_P | M20: Active
A21: =LEN(C21) - LEN(SUBSTITUTE(C21, "!", "")) + 1 -> 1 | B21: 6 | C21: 3771 | D21: Validity WISC-6/WPPSI-4 - Paper | E21: V_WPPSI4_P | F21: =aurora_data!U957 -> 56 | H21: 3820 | I21: Clinical | J21: 2 | K21: OSEP – Multiple Disabilities - Paper | L21: OSEP_MD_P | M21: Active
A22: =LEN(C22) - LEN(SUBSTITUTE(C22, "!", "")) + 1 -> 1 | B22: 7 | C22: 3772 | D22: Validity WISC-6/WAIS-5 - Paper | E22: V_WAIS5_P | F22: =aurora_data!U1148 -> 51 | H22: 3819 | I22: Clinical | J22: 2 | K22: OSEP – Emotional Disturbance - Paper | L22: OSEP_ED_P | M22: Active
A23: =LEN(C23) - LEN(SUBSTITUTE(C23, "!", "")) + 1 -> 1 | B23: 8 | C23: 3773 | D23: Validity WISC-6/WIAT-4 - Paper | E23: V_WIAT4_P | F23: =aurora_data!U1438 -> 224 | H23: 3818 | I23: Clinical | J23: 2 | K23: OSEP – Developmental Delay - Paper | L23: OSEP_DD_P | M23: Active
A24: =LEN(C24) - LEN(SUBSTITUTE(C24, "!", "")) + 1 -> 1 | B24: 9 | C24: 3774 | D24: Validity WISC-6/KTEA-3 – Paper Form A | E24: V_KTEA3_P | F24: =aurora_data!U1638 -> 221 | H24: 3817 | I24: Clinical | J24: 2 | K24: OSEP – Autism - Paper | L24: OSEP_AUT_P | M24: Active
A25: =LEN(C25) - LEN(SUBSTITUTE(C25, "!", "")) + 1 -> 1 | B25: 10 | C25: 3775 | D25: Counterbalance WISC-5 Plus/WISC-6 - Paper | E25: CB_WISC5P_P | F25: =aurora_data!U1838 -> 136 | H25: 3816 | I25: Clinical | J25: 2 | K25: WISC-6 Clinical Validity Traumatic Brain Injury - Paper | L25: CV_TBI_VINE3_P | M25: Active
A26: =LEN(C26) - LEN(SUBSTITUTE(C26, "!", "")) + 1 -> 1 | B26: 11 | C26: 3777 | D26: Counterbalance WPPSI-4/WISC-6 -Paper | E26: CB_WPPSI4_P | F26: =aurora_data!U1957 -> 56 | H26: 3815 | I26: Clinical | J26: 2 | K26: WISC-6 Clinical Traumatic Brain Injury - Paper | L26: C_TBI_P | M26: Active
A27: =LEN(C27) - LEN(SUBSTITUTE(C27, "!", "")) + 1 -> 1 | B27: 12 | C27: 3778 | D27: Counterbalance WAIS-5/WISC-6 - Paper | E27: CB_WAIS5_P | F27: =aurora_data!U2048 -> 59 | H27: 3823 | I27: Clinical | J27: 2 | K27: OSEP – Specific Learning Disability - Paper | L27: OSEP_SLD_P | M27: Active
H28: 3813 | I28: Clinical | J28: 2 | K28: WISC-6 Clinical Motor Impairment - Paper | L28: C_MI_P | M28: Active
H29: 3812 | I29: Clinical | J29: 2 | K29: WISC-6 Clinical Validity Language Disorder with Expressive Impairment (Ages 9-16) - Paper | L29: CV_LDE_CELF5_RF2_P | M29: Active
B30: Total | C30: =SUM(A16:A36) -> 12 | H30: 3811 | I30: Clinical | J30: 2 | K30: WISC-6 Clinical Language Disorder with Expressive Impairment (Ages 9-16) - Paper | L30: C_LDE_9-16_P | M30: Active
H31: 3810 | I31: Clinical | J31: 2 | K31: WISC-6 Clinical Validity Language Disorder with Expressive Impairment (Ages 6-8) - Paper | L31: CV_LDE_CELF5_RF1_P | M31: Active
H32: 3809 | I32: Clinical | J32: 2 | K32: WISC-6 Clinical Language Disorder with Expressive Impairment (Ages 6-8) - Paper | L32: C_LDE_6-8_P | M32: Active
H33: 3808 | I33: Clinical | J33: 2 | K33: WISC-6 Clinical Validity Language Disorder with Receptive Impairment (Ages 9-16) - Paper | L33: CV_LDR_CELF5_RF2_P | M33: Active
H34: 3807 | I34: Clinical | J34: 2 | K34: WISC-6 Clinical Language Disorder with Receptive Impairment (Ages 9-16) - Paper | L34: C_LDR_9-16_P | M34: Active
H35: 3806 | I35: Clinical | J35: 2 | K35: WISC-6 Clinical Validity Language Disorder with Receptive Impairment (Ages 6-8) - Paper | L35: CV_LDR_CELF5_RF1_P | M35: Active
H36: 3834 | I36: Clinical | J36: 2 | K36: OSEP – Other Health Impairment - Digital | L36: OSEP_OHI_D | M36: Active
H37: 3842 | I37: Clinical | J37: 2 | K37: WISC-6 Clinical Validity Autism spectrum disorder with no language impairment - (Adolescent) Paper | L37: CV_ASD_NO_LI_BASC3_ADOL_P | M37: Active
H38: 3841 | I38: Clinical | J38: 2 | K38: WISC-6 Clinical Validity Autism spectrum disorder with language impairment - (Adolescent) Paper | L38: CV_ASD_LI_BASC3_ADOL_P | M38: Active
H39: 3840 | I39: Clinical | J39: 2 | K39: WISC-6 Clinical Validity ADHD – (Adolescent) Digital | L39: CV_ADHD_BASC3_ADOL_D | M39: Active
H40: 3839 | I40: Clinical | J40: 2 | K40: WISC-6 Clinical Validity ADHD - (Adolescent) Paper | L40: CV_ADHD_BASC3_ADOL_P | M40: Active
H41: 3838 | I41: Clinical | J41: 2 | K41: OSEP – ADHD - Digital | L41: OSEP_ADHD_D | M41: Active
H42: 3837 | I42: Clinical | J42: 2 | K42: OSEP – Traumatic Brain Injury - Digital | L42: OSEP_TBI_D | M42: Active
... H91: 3844 | I91: Other | J91: 7 | K91: Quali_WISC5 – Paper | L91: Q_WISC5_P | M91: Inactive

Sheet aurora_data
A1: =setup!C16 -> 3766 | BA1: =A1 -> 3766
A2: =_xlfn.CONCAT(setup!D16, " - ",setup!E16) -> WISC-6 Standardization - Paper - WISC6_STDZ_P | BA2: =A2 -> WISC-6 Standardization - Paper - WISC6_STDZ_P
A3: ageband | B3: gradeband | C3: report | D3: AS1 | E3: AS2 | F3: AS3 | G3: AS4 | H3: AS5 | I3: BL1 | J3: BL2 | K3: BL3 | L3: BL4 | M3: BL5 | N3: HI1 | O3: HI2 | P3: HI3 | Q3: HI4 | R3: HI5 | S3: OT1 | T3: OT2 | U3: OT3 | V3: OT4 | W3: OT5 | X3: WH1 | Y3: WH2 | Z3: WH3 | AA3: WH4 | AB3: WH5 | AC3: MW | AD3: NE | AE3: SO | AF3: WE | AG3: F | AH3: M | AI3: OTHER | AJ3: Total | AK3: LastRefreshed | BA3: ageband | BB3: gradeband | BC3: report | BD3: 1 | BE3: 2 | BF3: 3 | BG3: 4 | BH3: 5 | BI3: AS | BJ3: BL | BK3: HI | BL3: OT | BM3: WH | BN3: MW | BO3: NE | BP3: SO | BQ3: WE | BR3: F | BS3: M | BT3: OTHER | BU3: Total | BV3: LastRefreshed
A4: 06.00.00-06.11.30 | C4: Target N | D4: 0.41 | E4: 0.42 | F4: 0.98 | G4: 1.8 | H4: 6.7 | I4: 0.39 | J4: 1.48 | K4: 7.01 | L4: 9.06 | M4: 6.58 | N4: 2.9 | O4: 5.43 | P4: 13.3 | Q4: 15.73 | R4: 11 | S4: 0.42 | T4: 0.82 | U4: 3.66 | V4: 6.65 | W4: 8.63 | X4: 1.12 | Y4: 1.76 | Z4: 14.7 | AA4: 31.08 | AB4: 47.97 | AC4: 44.3 | AD4: 30.53 | AE4: 80 | AF4: 45.17 | AG4: 100 | AH4: 100 | AI4: 0 | AJ4: 200 | AK4: 09/17/2026 @ 7:18 AM | BA4: 06.00.00-06.11.30 | BC4: Target N | BD4: 5.24 | BE4: 9.9 | BF4: 39.65 | BG4: 64.32 | BH4: 80.88 | BI4: 10.31 | BJ4: 24.51 | BK4: 48.37 | BL4: 20.18 | BM4: 96.64 | BN4: 44.3 | BO4: 30.53 | BP4: 80 | BQ4: 45.17 | BR4: 100 | BS4: 100 | BT4: 0 | BU4: 200 | BV4: 09/17/2026 @ 7:18 AM
A5: 06.00.00-06.11.30 | C5: Stratified Usable N | D5: 0 | E5: 0 | F5: 0 | G5: 2 | H5: 7 | I5: 0 | J5: 1 | K5: 7 | L5: 9 | M5: 7 | N5: 3 | O5: 4 | P5: 13 | Q5: 16 | R5: 10 | S5: 1 | T5: 1 | U5: 3 | V5: 7 | W5: 8 | X5: 0 | Y5: 0 | Z5: 13 | AA5: 31 | AB5: 48 | AC5: 49 | AD5: 33 | AE5: 75 | AF5: 34 | AG5: 98 | AH5: 93 | AI5: 0 | AJ5: 191 | AK5: 09/17/2026 @ 7:18 AM | BA5: 06.00.00-06.11.30 | BC5: Stratified Usable N | BD5: 4 | BE5: 6 | BF5: 36 | BG5: 65 | BH5: 80 | BI5: 9 | BJ5: 24 | BK5: 46 | BL5: 20 | BM5: 92 | BN5: 49 | BO5: 33 | BP5: 75 | BQ5: 34 | BR5: 98 | BS5: 93 | BT5: 0 | BU5: 191 | BV5: 09/17/2026 @ 7:18 AM
A6: 06.00.00-06.11.30 | C6: Stratified Out Usable N | D6: 0 | E6: 0 | F6: 0 | G6: 0 | H6: 0 | I6: 0 | J6: 0 | K6: 0 | L6: 4 | M6: 0 | N6: 2 | O6: 0 | P6: 1 | Q6: 0 | R6: 0 | S6: 0 | T6: 0 | U6: 0 | V6: 3 | W6: 0 | X6: 0 | Y6: 0 | Z6: 0 | AA6: 0 | AB6: 15 | AC6: 15 | AD6: 6 | AE6: 3 | AF6: 1 | AG6: 10 | AH6: 15 | AI6: 0 | AJ6: 25 | AK6: 09/17/2026 @ 7:18 AM | BA6: 06.00.00-06.11.30 | BC6: Stratified Out Usable N | BD6: 2 | BE6: 0 | BF6: 1 | BG6: 7 | BH6: 15 | BI6: 0 | BJ6: 4 | BK6: 3 | BL6: 3 | BM6: 15 | BN6: 15 | BO6: 6 | BP6: 3 | BQ6: 1 | BR6: 10 | BS6: 15 | BT6: 0 | BU6: 25 | BV6: 09/17/2026 @ 7:18 AM
A7: 06.00.00-06.11.30 | C7: In Process N | D7: 0 | E7: 0 | F7: 0 | G7: 0 | H7: 0 | I7: 0 | J7: 0 | K7: 0 | L7: 0 | M7: 0 | N7: 0 | O7: 0 | P7: 0 | Q7: 0 | R7: 0 | S7: 0 | T7: 0 | U7: 0 | V7: 0 | W7: 0 | X7: 0 | Y7: 0 | Z7: 0 | AA7: 0 | AB7: 0 | AC7: 0 | AD7: 0 | AE7: 0 | AF7: 0 | AG7: 0 | AH7: 0 | AI7: 0 | AJ7: 0 | AK7: 09/17/2026 @ 7:18 AM | BA7: 06.00.00-06.11.30 | BC7: In Process N | BD7: 0 | BE7: 0 | BF7: 0 | BG7: 0 | BH7: 0 | BI7: 0 | BJ7: 0 | BK7: 0 | BL7: 0 | BM7: 0 | BN7: 0 | BO7: 0 | BP7: 0 | BQ7: 0 | BR7: 0 | BS7: 0 | BT7: 0 | BU7: 0 | BV7: 09/17/2026 @ 7:18 AM
A8: 06.00.00-06.11.30 | C8: Assigned Not Recd N | D8: 0 | E8: 0 | F8: 1 | G8: 0 | H8: 0 | I8: 2 | J8: 0 | K8: 0 | L8: 0 | M8: 0 | N8: 1 | O8: 0 | P8: 0 | Q8: 0 | R8: 1 | S8: 0 | T8: 0 | U8: 0 | V8: 0 | W8: 0 | X8: 1 | Y8: 3 | Z8: 0 | AA8: 0 | AB8: 1 | AC8: 3 | AD8: 1 | AE8: 3 | AF8: 3 | AG8: 5 | AH8: 5 | AI8: 0 | AJ8: 10 | AK8: 09/17/2026 @ 7:18 AM | BA8: 06.00.00-06.11.30 | BC8: Assigned Not Recd N | BD8: 4 | BE8: 3 | BF8: 1 | BG8: 0 | BH8: 2 | BI8: 1 | BJ8: 2 | BK8: 2 | BL8: 0 | BM8: 5 | BN8: 3 | BO8: 1 | BP8: 3 | BQ8: 3 | BR8: 5 | BS8: 5 | BT8: 0 | BU8: 10 | BV8: 09/17/2026 @ 7:18 AM
A9: 06.00.00-06.11.30 | C9: Reserved Not Recd N | D9: 0 | E9: 0 | F9: 0 | G9: 0 | H9: 0 | I9: 0 | J9: 0 | K9: 0 | L9: 0 | M9: 0 | N9: 0 | O9: 0 | P9: 0 | Q9: 0 | R9: 1 | S9: 0 | T9: 0 | U9: 1 | V9: 0 | W9: 1 | X9: 0 | Y9: 0 | Z9: 0 | AA9: 0 | AB9: 0 | AC9: 1 | AD9: 0 | AE9: 1 | AF9: 1 | AG9: 0 | AH9: 3 | AI9: 0 | AJ9: 3 | AK9: 09/17/2026 @ 7:18 AM | BA9: 06.00.00-06.11.30 | BC9: Reserved Not Recd N | BD9: 0 | BE9: 0 | BF9: 1 | BG9: 0 | BH9: 2 | BI9: 0 | BJ9: 0 | BK9: 1 | BL9: 2 | BM9: 0 | BN9: 1 | BO9: 0 | BP9: 1 | BQ9: 1 | BR9: 0 | BS9: 3 | BT9: 0 | BU9: 3 | BV9: 09/17/2026 @ 7:18 AM
A10: 06.00.00-06.11.30 | C10: Total Assignments | D10: 0 | E10: 0 | F10: 1 | G10: 2 | H10: 7 | I10: 2 | J10: 1 | K10: 7 | L10: 13 | M10: 7 | N10: 6 | O10: 4 | P10: 14 | Q10: 16 | R10: 12 | S10: 1 | T10: 1 | U10: 4 | V10: 10 | W10: 9 | X10: 1 | Y10: 3 | Z10: 13 | AA10: 31 | AB10: 64 | AC10: 68 | AD10: 40 | AE10: 82 | AF10: 39 | AG10: 113 | AH10: 116 | AI10: 0 | AJ10: 229 | AK10: 09/17/2026 @ 7:18 AM | BA10: 06.00.00-06.11.30 | BC10: Total Assignments | BD10: 10 | BE10: 9 | BF10: 39 | BG10: 72 | BH10: 99 | BI10: 10 | BJ10: 30 | BK10: 52 | BL10: 25 | BM10: 112 | BN10: 68 | BO10: 40 | BP10: 82 | BQ10: 39 | BR10: 113 | BS10: 116 | BT10: 0 | BU10: 229 | BV10: 09/17/2026 @ 7:18 AM
A11: 06.00.00-06.11.30 | C11: Selected N | D11: 0 | E11: 0 | F11: 0 | G11: 0 | H11: 0 | I11: 0 | J11: 0 | K11: 0 | L11: 0 | M11: 0 | N11: 0 | O11: 0 | P11: 1 | Q11: 2 | R11: 1 | S11: 0 | T11: 0 | U11: 0 | V11: 0 | W11: 1 | X11: 0 | Y11: 0 | Z11: 3 | AA11: 1 | AB11: 2 | AC11: 4 | AD11: 1 | AE11: 5 | AF11: 1 | AG11: 6 | AH11: 5 | AI11: 0 | AJ11: 11 | AK11: 09/17/2026 @ 7:18 AM | BA11: 06.00.00-06.11.30 | BC11: Selected N | BD11: 0 | BE11: 0 | BF11: 4 | BG11: 3 | BH11: 4 | BI11: 0 | BJ11: 0 | BK11: 4 | BL11: 1 | BM11: 6 | BN11: 4 | BO11: 1 | BP11: 5 | BQ11: 1 | BR11: 6 | BS11: 5 | BT11: 0 | BU11: 11 | BV11: 09/17/2026 @ 7:18 AM
A12: 07.00.00-07.11.30 | C12: Target N | D12: 0.28 | E12: 0.32 | F12: 0.94 | G12: 1.53 | H12: 6.48 | I12: 0.47 | J12: 1.61 | K12: 7.13 | L12: 9.03 | M12: 6.62 | N12: 3.25 | O12: 5.82 | P12: 13.94 | Q12: 15.76 | R12: 10.37 | S12: 0.4 | T12: 0.74 | U12: 3.2 | V12: 6.91 | W12: 8.07 | X12: 1.02 | Y12: 2.08 | Z12: 13.98 | AA12: 31.83 | AB12: 48.22 | AC12: 41.68 | AD12: 30.61 | AE12: 81 | AF12: 46.71 | AG12: 100 | AH12: 100 | AI12: 0 | AJ12: 200 | AK12: 09/17/2026 @ 7:18 AM | BA12: 07.00.00-07.11.30 | BC12: Target N | BD12: 5.42 | BE12: 10.57 | BF12: 39.18 | BG12: 65.06 | BH12: 79.76 | BI12: 9.56 | BJ12: 24.86 | BK12: 49.13 | BL12: 19.33 | BM12: 97.11 | BN12: 41.68 | BO12: 30.61 | BP12: 81 | BQ12: 46.71 | BR12: 100 | BS12: 100 | BT12: 0 | BU12: 200 | BV12: 09/17/2026 @ 7:18 AM
A13: 07.00.00-07.11.30 | C13: Stratified Usable N | D13: 0 | E13: 0 | F13: 2 | G13: 2 | H13: 6 | I13: 0 | J13: 2 | K13: 7 | L13: 9 | M13: 7 | N13: 3 | O13: 6 | P13: 12 | Q13: 16 | R13: 10 | S13: 1 | T13: 1 | U13: 3 | V13: 7 | W13: 8 | X13: 1 | Y13: 0 | Z13: 14 | AA13: 32 | AB13: 48 | AC13: 45 | AD13: 27 | AE13: 88 | AF13: 37 | AG13: 100 | AH13: 97 | AI13: 0 | AJ13: 197 | AK13: 09/17/2026 @ 7:18 AM | BA13: 07.00.00-07.11.30 | BC13: Stratified Usable N | BD13: 5 | BE13: 9 | BF13: 38 | BG13: 66 | BH13: 79 | BI13: 10 | BJ13: 25 | BK13: 47 | BL13: 20 | BM13: 95 | BN13: 45 | BO13: 27 | BP13: 88 | BQ13: 37 | BR13: 100 | BS13: 97 | BT13: 0 | BU13: 197 | BV13: 09/17/2026 @ 7:18 AM
A14: 07.00.00-07.11.30 | C14: Stratified Out Usable N | D14: 0 | E14: 0 | F14: 0 | G14: 0 | H14: 0 | I14: 2 | J14: 0 | K14: 2 | L14: 1 | M14: 0 | N14: 0 | O14: 0 | P14: 0 | Q14: 6 | R14: 1 | S14: 0 | T14: 0 | U14: 4 | V14: 0 | W14: 5 | X14: 0 | Y14: 0 | Z14: 0 | AA14: 1 | AB14: 8 | AC14: 26 | AD14: 1 | AE14: 3 | AF14: 0 | AG14: 25 | AH14: 5 | AI14: 0 | AJ14: 30 | AK14: 09/17/2026 @ 7:18 AM | BA14: 07.00.00-07.11.30 | BC14: Stratified Out Usable N | BD14: 2 | BE14: 0 | BF14: 6 | BG14: 8 | BH14: 14 | BI14: 0 | BJ14: 5 | BK14: 7 | BL14: 9 | BM14: 9 | BN14: 26 | BO14: 1 | BP14: 3 | BQ14: 0 | BR14: 25 | BS14: 5 | BT14: 0 | BU14: 30 | BV14: 09/17/2026 @ 7:18 AM
A15: 07.00.00-07.11.30 | C15: In Process N | D15: 0 | E15: 0 | F15: 0 | G15: 0 | H15: 0 | I15: 0 | J15: 0 | K15: 0 | L15: 0 | M15: 0 | N15: 0 | O15: 0 | P15: 0 | Q15: 0 | R15: 0 | S15: 0 | T15: 0 | U15: 0 | V15: 0 | W15: 0 | X15: 0 | Y15: 0 | Z15: 0 | AA15: 0 | AB15: 0 | AC15: 0 | AD15: 0 | AE15: 0 | AF15: 0 | AG15: 0 | AH15: 0 | AI15: 0 | AJ15: 0 | AK15: 09/17/2026 @ 7:18 AM | BA15: 07.00.00-07.11.30 | BC15: In Process N | BD15: 0 | BE15: 0 | BF15: 0 | BG15: 0 | BH15: 0 | BI15: 0 | BJ15: 0 | BK15: 0 | BL15: 0 | BM15: 0 | BN15: 0 | BO15: 0 | BP15: 0 | BQ15: 0 | BR15: 0 | BS15: 0 | BT15: 0 | BU15: 0 | BV15: 09/17/2026 @ 7:18 AM
... A99: Total | C99: Selected N | D99: 0 | E99: 0 | F99: 0 | G99: 0 | H99: 4 | I99: 0 | J99: 0 | K99: 1 | L99: 3 | M99: 3 | N99: 1 | O99: 2 | P99: 8 | Q99: 7 | R99: 1 | S99: 0 | T99: 2 | U99: 3 | V99: 1 | W99: 4 | X99: 1 | Y99: 1 | Z99: 7 | AA99: 13 | AB99: 17 | AC99: 13 | AD99: 21 | AE99: 37 | AF99: 8 | AG99: 36 | AH99: 43 | AI99: 0 | AJ99: 79 | AK99: 09/17/2026 @ 7:18 AM | BA99: Total | BC99: Selected N | BD99: 2 | BE99: 5 | BF99: 19 | BG99: 24 | BH99: 29 | BI99: 4 | BJ99: 7 | BK99: 19 | BL99: 10 | BM99: 39 | BN99: 13 | BO99: 21 | BP99: 37 | BQ99: 8 | BR99: 36 | BS99: 43 | BT99: 0 | BU99: 79 | BV99: 09/17/2026 @ 7:18 AM
A129: =setup!C17 -> 3767 | BA129: =A129 -> 3767
A130: =_xlfn.CONCAT(setup!D17, " - ",setup!E17) -> WISC-6 Standardization - Digital - WISC6_STDZ_D | BA130: =A130 -> WISC-6 Standardization - Digital - WISC6_STDZ_D
A131: ageband | B131: gradeband | C131: report | D131: AS1 | E131: AS2 | F131: AS3 | G131: AS4 | H131: AS5 | I131: BL1 | J131: BL2 | K131: BL3 | L131: BL4 | M131: BL5 | N131: HI1 | O131: HI2 | P131: HI3 | Q131: HI4 | R131: HI5 | S131: OT1 | T131: OT2 | U131: OT3 | V131: OT4 | W131: OT5 | X131: WH1 | Y131: WH2 | Z131: WH3 | AA131: WH4 | AB131: WH5 | AC131: MW | AD131: NE | AE131: SO | AF131: WE | AG131: F | AH131: M | AI131: OTHER | AJ131: Total | AK131: LastRefreshed | BA131: ageband | BB131: gradeband | BC131: report | BD131: 1 | BE131: 2 | BF131: 3 | BG131: 4 | BH131: 5 | BI131: AS | BJ131: BL | BK131: HI | BL131: OT | BM131: WH | BN131: MW | BO131: NE | BP131: SO | BQ131: WE | BR131: F | BS131: M | BT131: OTHER | BU131: Total | BV131: LastRefreshed
A132: 06.00.00-06.11.30 | C132: Target N | D132: 0.1 | E132: 0.1 | F132: 0.25 | G132: 0.45 | H132: 1.68 | I132: 0.1 | J132: 0.37 | K132: 1.75 | L132: 2.26 | M132: 1.64 | N132: 0.73 | O132: 1.36 | P132: 3.33 | Q132: 3.93 | R132: 2.75 | S132: 0.1 | T132: 0.2 | U132: 0.92 | V132: 1.66 | W132: 2.16 | X132: 0.28 | Y132: 0.44 | Z132: 3.68 | AA132: 7.77 | AB132: 11.99 | AC132: 11.08 | AD132: 7.63 | AE132: 20 | AF132: 11.29 | AG132: 25 | AH132: 25 | AI132: 0 | AJ132: 50 | AK132: 09/17/2026 @ 7:18 AM | BA132: 06.00.00-06.11.30 | BC132: Target N | BD132: 1.31 | BE132: 2.48 | BF132: 9.91 | BG132: 16.08 | BH132: 20.22 | BI132: 2.58 | BJ132: 6.13 | BK132: 12.09 | BL132: 5.04 | BM132: 24.16 | BN132: 11.08 | BO132: 7.63 | BP132: 20 | BQ132: 11.29 | BR132: 25 | BS132: 25 | BT132: 0 | BU132: 50 | BV132: 09/17/2026 @ 7:17 AM
A133: 06.00.00-06.11.30 | C133: Stratified Usable N | D133: 0 | E133: 0 | F133: 0 | G133: 0 | H133: 0 | I133: 0 | J133: 1 | K133: 1 | L133: 0 | M133: 2 | N133: 0 | O133: 0 | P133: 3 | Q133: 3 | R133: 2 | S133: 0 | T133: 0 | U133: 1 | V133: 1 | W133: 2 | X133: 0 | Y133: 0 | Z133: 4 | AA133: 9 | AB133: 12 | AC133: 10 | AD133: 7 | AE133: 14 | AF133: 10 | AG133: 20 | AH133: 21 | AI133: 0 | AJ133: 41 | AK133: 09/17/2026 @ 7:18 AM | BA133: 06.00.00-06.11.30 | BC133: Stratified Usable N | BD133: 0 | BE133: 1 | BF133: 9 | BG133: 13 | BH133: 18 | BI133: 0 | BJ133: 4 | BK133: 8 | BL133: 4 | BM133: 25 | BN133: 10 | BO133: 7 | BP133: 14 | BQ133: 10 | BR133: 20 | BS133: 21 | BT133: 0 | BU133: 41 | BV133: 09/17/2026 @ 7:17 AM
A134: 06.00.00-06.11.30 | C134: Stratified Out Usable N | D134: 0 | E134: 0 | F134: 0 | G134: 0 | H134: 0 | I134: 0 | J134: 0 | K134: 0 | L134: 0 | M134: 3 | N134: 0 | O134: 0 | P134: 0 | Q134: 0 | R134: 0 | S134: 0 | T134: 0 | U134: 0 | V134: 0 | W134: 1 | X134: 0 | Y134: 0 | Z134: 0 | AA134: 0 | AB134: 0 | AC134: 2 | AD134: 0 | AE134: 2 | AF134: 0 | AG134: 3 | AH134: 1 | AI134: 0 | AJ134: 4 | AK134: 09/17/2026 @ 7:18 AM | BA134: 06.00.00-06.11.30 | BC134: Stratified Out Usable N | BD134: 0 | BE134: 0 | BF134: 0 | BG134: 0 | BH134: 4 | BI134: 0 | BJ134: 3 | BK134: 0 | BL134: 1 | BM134: 0 | BN134: 2 | BO134: 0 | BP134: 2 | BQ134: 0 | BR134: 3 | BS134: 1 | BT134: 0 | BU134: 4 | BV134: 09/17/2026 @ 7:17 AM
A135: 06.00.00-06.11.30 | C135: In Process N | D135: 0 | E135: 0 | F135: 0 | G135: 0 | H135: 0 | I135: 0 | J135: 0 | K135: 1 | L135: 0 | M135: 0 | N135: 0 | O135: 0 | P135: 0 | Q135: 0 | R135: 0 | S135: 0 | T135: 0 | U135: 0 | V135: 0 | W135: 0 | X135: 0 | Y135: 0 | Z135: 0 | AA135: 0 | AB135: 0 | AC135: 1 | AD135: 0 | AE135: 0 | AF135: 0 | AG135: 1 | AH135: 0 | AI135: 0 | AJ135: 1 | AK135: 09/17/2026 @ 7:18 AM | BA135: 06.00.00-06.11.30 | BC135: In Process N | BD135: 0 | BE135: 0 | BF135: 1 | BG135: 0 | BH135: 0 | BI135: 0 | BJ135: 1 | BK135: 0 | BL135: 0 | BM135: 0 | BN135: 1 | BO135: 0 | BP135: 0 | BQ135: 0 | BR135: 1 | BS135: 0 | BT135: 0 | BU135: 1 | BV135: 09/17/2026 @ 7:17 AM
A136: 06.00.00-06.11.30 | C136: Assigned Not Recd N | D136: 0 | E136: 0 | F136: 0 | G136: 0 | H136: 1 | I136: 0 | J136: 0 | K136: 0 | L136: 2 | M136: 0 | N136: 0 | O136: 1 | P136: 0 | Q136: 1 | R136: 1 | S136: 0 | T136: 0 | U136: 0 | V136: 1 | W136: 0 | X136: 0 | Y136: 0 | Z136: 0 | AA136: 0 | AB136: 1 | AC136: 0 | AD136: 3 | AE136: 5 | AF136: 0 | AG136: 1 | AH136: 7 | AI136: 0 | AJ136: 8 | AK136: 09/17/2026 @ 7:18 AM | BA136: 06.00.00-06.11.30 | BC136: Assigned Not Recd N | BD136: 0 | BE136: 1 | BF136: 0 | BG136: 4 | BH136: 3 | BI136: 1 | BJ136: 2 | BK136: 3 | BL136: 1 | BM136: 1 | BN136: 0 | BO136: 3 | BP136: 5 | BQ136: 0 | BR136: 1 | BS136: 7 | BT136: 0 | BU136: 8 | BV136: 09/17/2026 @ 7:17 AM
A137: 06.00.00-06.11.30 | C137: Reserved Not Recd N | D137: 0 | E137: 0 | F137: 0 | G137: 0 | H137: 0 | I137: 0 | J137: 0 | K137: 0 | L137: 0 | M137: 0 | N137: 0 | O137: 0 | P137: 0 | Q137: 0 | R137: 0 | S137: 0 | T137: 0 | U137: 0 | V137: 0 | W137: 0 | X137: 0 | Y137: 0 | Z137: 0 | AA137: 0 | AB137: 0 | AC137: 0 | AD137: 0 | AE137: 0 | AF137: 0 | AG137: 0 | AH137: 0 | AI137: 0 | AJ137: 0 | AK137: 09/17/2026 @ 7:18 AM | BA137: 06.00.00-06.11.30 | BC137: Reserved Not Recd N | BD137: 0 | BE137: 0 | BF137: 0 | BG137: 0 | BH137: 0 | BI137: 0 | BJ137: 0 | BK137: 0 | BL137: 0 | BM137: 0 | BN137: 0 | BO137: 0 | BP137: 0 | BQ137: 0 | BR137: 0 | BS137: 0 | BT137: 0 | BU137: 0 | BV137: 09/17/2026 @ 7:17 AM
A138: 06.00.00-06.11.30 | C138: Total Assignments | D138: 0 | E138: 0 | F138: 0 | G138: 0 | H138: 1 | I138: 0 | J138: 1 | K138: 2 | L138: 2 | M138: 5 | N138: 0 | O138: 1 | P138: 3 | Q138: 4 | R138: 3 | S138: 0 | T138: 0 | U138: 1 | V138: 2 | W138: 3 | X138: 0 | Y138: 0 | Z138: 4 | AA138: 9 | AB138: 13 | AC138: 13 | AD138: 10 | AE138: 21 | AF138: 10 | AG138: 25 | AH138: 29 | AI138: 0 | AJ138: 54 | AK138: 09/17/2026 @ 7:18 AM | BA138: 06.00.00-06.11.30 | BC138: Total Assignments | BD138: 0 | BE138: 2 | BF138: 10 | BG138: 17 | BH138: 25 | BI138: 1 | BJ138: 10 | BK138: 11 | BL138: 6 | BM138: 26 | BN138: 13 | BO138: 10 | BP138: 21 | BQ138: 10 | BR138: 25 | BS138: 29 | BT138: 0 | BU138: 54 | BV138: 09/17/2026 @ 7:17 AM
A139: 06.00.00-06.11.30 | C139: Selected N | D139: 0 | E139: 0 | F139: 0 | G139: 0 | H139: 0 | I139: 0 | J139: 0 | K139: 0 | L139: 0 | M139: 0 | N139: 0 | O139: 0 | P139: 0 | Q139: 0 | R139: 0 | S139: 0 | T139: 0 | U139: 0 | V139: 0 | W139: 0 | X139: 0 | Y139: 0 | Z139: 0 | AA139: 0 | AB139: 0 | AC139: 0 | AD139: 0 | AE139: 0 | AF139: 0 | AG139: 0 | AH139: 0 | AI139: 0 | AJ139: 0 | AK139: 09/17/2026 @ 7:18 AM | BA139: 06.00.00-06.11.30 | BC139: Selected N | BD139: 0 | BE139: 0 | BF139: 0 | BG139: 0 | BH139: 0 | BI139: 0 | BJ139: 0 | BK139: 0 | BL139: 0 | BM139: 0 | BN139: 0 | BO139: 0 | BP139: 0 | BQ139: 0 | BR139: 0 | BS139: 0 | BT139: 0 | BU139: 0 | BV139: 09/17/2026 @ 7:17 AM
A140: 07.00.00-07.11.30 | C140: Target N | D140: 0.07 | E140: 0.08 | F140: 0.24 | G140: 0.38 | H140: 1.62 | I140: 0.12 | J140: 0.4 | K140: 1.78 | L140: 2.26 | M140: 1.66 | N140: 0.81 | O140: 1.46 | P140: 3.48 | Q140: 3.94 | R140: 2.59 | S140: 0.1 | T140: 0.19 | U140: 0.8 | V140: 1.73 | W140: 2.02 | X140: 0.25 | Y140: 0.52 | Z140: 3.49 | AA140: 7.96 | AB140: 12.05 | AC140: 10.42 | AD140: 7.65 | AE140: 20.25 | AF140: 11.68 | AG140: 25 | AH140: 25 | AI140: 0 | AJ140: 50 | AK140: 09/17/2026 @ 7:18 AM | BA140: 07.00.00-07.11.30 | BC140: Target N | BD140: 1.36 | BE140: 2.64 | BF140: 9.8 | BG140: 16.27 | BH140: 19.94 | BI140: 2.39 | BJ140: 6.22 | BK140: 12.28 | BL140: 4.83 | BM140: 24.28 | BN140: 10.42 | BO140: 7.65 | BP140: 20.25 | BQ140: 11.68 | BR140: 25 | BS140: 25 | BT140: 0 | BU140: 50 | BV140: 09/17/2026 @ 7:17 AM
A141: 07.00.00-07.11.30 | C141: Stratified Usable N | D141: 0 | E141: 0 | F141: 0 | G141: 0 | H141: 0 | I141: 0 | J141: 0 | K141: 2 | L141: 1 | M141: 2 | N141: 0 | O141: 0 | P141: 1 | Q141: 4 | R141: 2 | S141: 0 | T141: 0 | U141: 0 | V141: 1 | W141: 2 | X141: 1 | Y141: 0 | Z141: 0 | AA141: 6 | AB141: 12 | AC141: 11 | AD141: 8 | AE141: 9 | AF141: 6 | AG141: 18 | AH141: 16 | AI141: 0 | AJ141: 34 | AK141: 09/17/2026 @ 7:18 AM | BA141: 07.00.00-07.11.30 | BC141: Stratified Usable N | BD141: 1 | BE141: 0 | BF141: 3 | BG141: 12 | BH141: 18 | BI141: 0 | BJ141: 5 | BK141: 7 | BL141: 3 | BM141: 19 | BN141: 11 | BO141: 8 | BP141: 9 | BQ141: 6 | BR141: 18 | BS141: 16 | BT141: 0 | BU141: 34 | BV141: 09/17/2026 @ 7:17 AM
A142: 07.00.00-07.11.30 | C142: Stratified Out Usable N | D142: 0 | E142: 0 | F142: 0 | G142: 0 | H142: 0 | I142: 0 | J142: 0 | K142: 0 | L142: 0 | M142: 1 | N142: 0 | O142: 0 | P142: 0 | Q142: 0 | R142: 0 | S142: 0 | T142: 0 | U142: 0 | V142: 0 | W142: 0 | X142: 0 | Y142: 0 | Z142: 0 | AA142: 0 | AB142: 2 | AC142: 3 | AD142: 0 | AE142: 0 | AF142: 0 | AG142: 3 | AH142: 0 | AI142: 0 | AJ142: 3 | AK142: 09/17/2026 @ 7:18 AM | BA142: 07.00.00-07.11.30 | BC142: Stratified Out Usable N | BD142: 0 | BE142: 0 | BF142: 0 | BG142: 0 | BH142: 3 | BI142: 0 | BJ142: 1 | BK142: 0 | BL142: 0 | BM142: 2 | BN142: 3 | BO142: 0 | BP142: 0 | BQ142: 0 | BR142: 3 | BS142: 0 | BT142: 0 | BU142: 3 | BV142: 09/17/2026 @ 7:17 AM
A143: 07.00.00-07.11.30 | C143: In Process N | D143: 0 | E143: 0 | F143: 0 | G143: 0 | H143: 0 | I143: 0 | J143: 0 | K143: 0 | L143: 0 | M143: 0 | N143: 0 | O143: 0 | P143: 0 | Q143: 0 | R143: 0 | S143: 0 | T143: 0 | U143: 0 | V143: 0 | W143: 0 | X143: 0 | Y143: 0 | Z143: 0 | AA143: 0 | AB143: 0 | AC143: 0 | AD143: 0 | AE143: 0 | AF143: 0 | AG143: 0 | AH143: 0 | AI143: 0 | AJ143: 0 | AK143: 09/17/2026 @ 7:18 AM | BA143: 07.00.00-07.11.30 | BC143: In Process N | BD143: 0 | BE143: 0 | BF143: 0 | BG143: 0 | BH143: 0 | BI143: 0 | BJ143: 0 | BK143: 0 | BL143: 0 | BM143: 0 | BN143: 0 | BO143: 0 | BP143: 0 | BQ143: 0 | BR143: 0 | BS143: 0 | BT143: 0 | BU143: 0 | BV143: 09/17/2026 @ 7:17 AM
... A227: Total | C227: Selected N | D227: 0 | E227: 0 | F227: 0 | G227: 0 | H227: 0 | I227: 0 | J227: 0 | K227: 2 | L227: 0 | M227: 1 | N227: 0 | O227: 0 | P227: 0 | Q227: 0 | R227: 0 | S227: 0 | T227: 0 | U227: 0 | V227: 0 | W227: 0 | X227: 0 | Y227: 0 | Z227: 0 | AA227: 0 | AB227: 0 | AC227: 1 | AD227: 0 | AE227: 2 | AF227: 0 | AG227: 0 | AH227: 3 | AI227: 0 | AJ227: 3 | AK227: 09/17/2026 @ 7:18 AM | BA227: Total | BC227: Selected N | BD227: 0 | BE227: 0 | BF227: 2 | BG227: 0 | BH227: 1 | BI227: 0 | BJ227: 3 | BK227: 0 | BL227: 0 | BM227: 0 | BN227: 1 | BO227: 0 | BP227: 2 | BQ227: 0 | BR227: 0 | BS227: 3 | BT227: 0 | BU227: 3 | BV227: 09/17/2026 @ 7:17 AM
A329: =setup!C18 -> 3768 | BA329: =A329 -> 3768
A330: =_xlfn.CONCAT(setup!D18," - ",setup!E18) -> Retest WISC-6 Standardization - Paper - R_WISC6_STDZ_P | BA330: =A330 -> Retest WISC-6 Standardization - Paper - R_WISC6_STDZ_P
A331: ageband | B331: gradeband | C331: report | D331: 1 | E331: 2 | F331: 3 | G331: 4 | H331: 5 | I331: AS | J331: BL | K331: HI | L331: OT | M331: WH | N331: MW | O331: NE | P331: SO | Q331: WE | R331: F | S331: M | T331: OTHER | U331: Total | V331: LastRefreshed | BA331: ageband | BB331: gradeband | BC331: report | BD331: 1 | BE331: 2 | BF331: 3 | BG331: 4 | BH331: 5 | BI331: AS | BJ331: BL | BK331: HI | BL331: OT | BM331: WH | BN331: MW | BO331: NE | BP331: SO | BQ331: WE | BR331: F | BS331: M | BT331: OTHER | BU331: Total | BV331: LastRefreshed
A332: 06.00.00-06.11.30 | C332: Target N | D332: 0.52 | E332: 0.99 | F332: 3.97 | G332: 6.43 | H332: 8.09 | I332: 1 | J332: 1 | K332: 1 | L332: 1 | M332: 1 | N332: 1 | O332: 1 | P332: 1 | Q332: 1 | R332: 1 | S332: 1 | T332: 0 | U332: 20 | V332: 09/17/2026 @ 7:19 AM | BA332: 06.00.00-06.11.30 | BC332: Target N | BD332: 0.52 | BE332: 0.99 | BF332: 3.97 | BG332: 6.43 | BH332: 8.09 | BI332: 1 | BJ332: 1 | BK332: 1 | BL332: 1 | BM332: 1 | BN332: 1 | BO332: 1 | BP332: 1 | BQ332: 1 | BR332: 1 | BS332: 1 | BT332: 0 | BU332: 20 | BV332: 09/17/2026 @ 7:17 AM
A333: 06.00.00-06.11.30 | C333: Stratified Usable N | D333: 0 | E333: 1 | F333: 4 | G333: 6 | H333: 8 | I333: 2 | J333: 2 | K333: 2 | L333: 2 | M333: 11 | N333: 5 | O333: 4 | P333: 8 | Q333: 2 | R333: 10 | S333: 9 | T333: 0 | U333: 19 | V333: 09/17/2026 @ 7:19 AM | BA333: 06.00.00-06.11.30 | BC333: Stratified Usable N | BD333: 0 | BE333: 1 | BF333: 4 | BG333: 6 | BH333: 8 | BI333: 2 | BJ333: 2 | BK333: 2 | BL333: 2 | BM333: 11 | BN333: 5 | BO333: 4 | BP333: 8 | BQ333: 2 | BR333: 10 | BS333: 9 | BT333: 0 | BU333: 19 | BV333: 09/17/2026 @ 7:17 AM
A334: 06.00.00-06.11.30 | C334: Stratified Out Usable N | D334: 0 | E334: 0 | F334: 0 | G334: 0 | H334: 0 | I334: 0 | J334: 0 | K334: 0 | L334: 0 | M334: 0 | N334: 0 | O334: 0 | P334: 0 | Q334: 0 | R334: 0 | S334: 0 | T334: 0 | U334: 0 | V334: 09/17/2026 @ 7:19 AM | BA334: 06.00.00-06.11.30 | BC334: Stratified Out Usable N | BD334: 0 | BE334: 0 | BF334: 0 | BG334: 0 | BH334: 0 | BI334: 0 | BJ334: 0 | BK334: 0 | BL334: 0 | BM334: 0 | BN334: 0 | BO334: 0 | BP334: 0 | BQ334: 0 | BR334: 0 | BS334: 0 | BT334: 0 | BU334: 0 | BV334: 09/17/2026 @ 7:17 AM
A335: 06.00.00-06.11.30 | C335: In Process N | D335: 0 | E335: 0 | F335: 0 | G335: 0 | H335: 0 | I335: 0 | J335: 0 | K335: 0 | L335: 0 | M335: 0 | N335: 0 | O335: 0 | P335: 0 | Q335: 0 | R335: 0 | S335: 0 | T335: 0 | U335: 0 | V335: 09/17/2026 @ 7:19 AM | BA335: 06.00.00-06.11.30 | BC335: In Process N | BD335: 0 | BE335: 0 | BF335: 0 | BG335: 0 | BH335: 0 | BI335: 0 | BJ335: 0 | BK335: 0 | BL335: 0 | BM335: 0 | BN335: 0 | BO335: 0 | BP335: 0 | BQ335: 0 | BR335: 0 | BS335: 0 | BT335: 0 | BU335: 0 | BV335: 09/17/2026 @ 7:17 AM
A336: 06.00.00-06.11.30 | C336: Assigned Partial Recd N | D336: 0 | E336: 0 | F336: 0 | G336: 0 | H336: 0 | I336: 0 | J336: 0 | K336: 0 | L336: 0 | M336: 0 | N336: 0 | O336: 0 | P336: 0 | Q336: 0 | R336: 0 | S336: 0 | T336: 0 | U336: 0 | V336: 09/17/2026 @ 7:19 AM | BA336: 06.00.00-06.11.30 | BC336: Assigned Partial Recd N | BD336: 0 | BE336: 0 | BF336: 0 | BG336: 0 | BH336: 0 | BI336: 0 | BJ336: 0 | BK336: 0 | BL336: 0 | BM336: 0 | BN336: 0 | BO336: 0 | BP336: 0 | BQ336: 0 | BR336: 0 | BS336: 0 | BT336: 0 | BU336: 0 | BV336: 09/17/2026 @ 7:17 AM
...

Sheet Summary
A1: =_xlfn.CONCAT("Last Refreshed at: ",F3) -> Last Refreshed at: 09/17/2026 @ 7:19 AM | H1: Assignment Information | L1: Total usable from all tabs | P1: Tptal in-Process
A2: study_id | B2: study | C2: Target | D2: usableCount | E2: Percentage | F2: Refreshed_Date | H2: Total Assigned | I2: Percentage | L2: =SUM(WISC6_STDZ_P!AL158,R_WISC6_STDZ_P!W167,V_WISC5P_P!W167,V_WPPSI4_P!W41,V_WAIS5_P!W27,V_WIAT4_P!W167,V_KTEA3_P!W167,CB_WISC5P_P!W112,CB_WPPSI4_P!W31,CB_WAIS5_P!W22) -> 3130 | M2: =SUM(#REF!,#REF!,#REF!,#REF!,#REF!,#REF!,#REF!,#REF!,#REF!,#REF!,#REF!,#REF!,#REF!,#REF!,#REF!,#REF!,#REF!,#REF!,#REF!) -> #REF! | P2: =SUM(#REF!,#REF!,#REF!) -> #REF!
A3: 3766 | B3: WISC-6 Standardization - Paper | C3: 2200 | D3: 2149 | E3: 0.97681818 | F3: 09/17/2026 @ 7:19 AM | H3: =setup!F16 -> 2523 | I3: =IFERROR(H3/C3,0) -> 1.1468182
A4: 3767 | B4: WISC-6 Standardization - Digital | C4: 550 | D4: 437 | E4: 0.79454545 | F4: 09/17/2026 @ 7:19 AM | H4: =setup!F17 -> 568 | I4: =IFERROR(H4/C4,0) -> 1.0327273
A5: 3768 | B5: Retest WISC-6 Standardization - Paper | C5: 220 | D5: 219 | E5: 0.99545455 | F5: 09/17/2026 @ 7:19 AM | H5: =setup!F18 -> 235 | I5: =IFERROR(H5/C5,0) -> 1.0681818
A6: 3769 | B6: Retest WISC-6 Standardization Digital | C6: 90 | D6: 71 | E6: 0.78888889 | F6: 09/17/2026 @ 7:19 AM | H6: =setup!F19 -> 93 | I6: =IFERROR(H6/C6,0) -> 1.0333333
A7: 3770 | B7: Validity WISC-6/WISC-5 Plus - Paper | C7: 100 | D7: 97 | E7: 0.97 | F7: 09/17/2026 @ 7:19 AM | H7: =setup!F20 -> 137 | I7: =IFERROR(H7/C7,0) -> 1.37
A8: 3771 | B8: Validity WISC-6/WPPSI-4 - Paper | C8: 50 | D8: 49 | E8: 0.98 | F8: 09/17/2026 @ 7:19 AM | H8: =setup!F21 -> 56 | I8: =IFERROR(H8/C8,0) -> 1.12
A9: 3772 | B9: Validity WISC-6/WAIS-5 - Paper | C9: 50 | D9: 50 | E9: 1 | F9: 09/17/2026 @ 7:19 AM | H9: =setup!F22 -> 51 | I9: =IFERROR(H9/C9,0) -> 1.02
A10: 3773 | B10: Validity WISC-6/WIAT-4 - Paper | C10: 200 | D10: 197 | E10: 0.985 | F10: 09/17/2026 @ 7:19 AM | H10: =setup!F23 -> 224 | I10: =IFERROR(H10/C10,0) -> 1.12
A11: 3774 | B11: Validity WISC-6/KTEA-3 – Paper Form A | C11: 200 | D11: 192 | E11: 0.96 | F11: 09/17/2026 @ 7:19 AM | H11: =setup!F24 -> 221 | I11: =IFERROR(H11/C11,0) -> 1.105
A12: 3775 | B12: Counterbalance WISC-5 Plus/WISC-6 - Paper | C12: 100 | D12: 95 | E12: 0.95 | F12: 09/17/2026 @ 7:19 AM | H12: =setup!F25 -> 136 | I12: =IFERROR(H12/C12,0) -> 1.36
A13: 3777 | B13: Counterbalance WPPSI-4/WISC-6 -Paper | C13: 50 | D13: 43 | E13: 0.86 | F13: 09/17/2026 @ 7:19 AM | H13: =setup!F26 -> 56 | I13: =IFERROR(H13/C13,0) -> 1.12
A14: 3778 | B14: Counterbalance WAIS-5/WISC-6 - Paper | C14: 50 | D14: 39 | E14: 0.78 | F14: 09/17/2026 @ 7:19 AM | H14: =setup!F27 -> 59 | I14: =IFERROR(H14/C14,0) -> 1.18
A15: All | B15: Total | C15: 3860 | D15: 3638 | E15: 0.94248705 | F15: 09/17/2026 @ 7:19 AM | H15: =SUM(H3:H14) -> 4359 | I15: =H15/C15 -> 1.1292746

Sheet WISC6_STDZ_P
A1: Total Assigments below Target | D1: Study Information | N1: Additional Information
A2: Usable greater/equal to target | D2: =_xlfn.CONCAT("Study Name: ","WISC-6 Standardization - Paper") -> Study Name: WISC-6 Standardization - Paper | K2: Usable = case is available to Psychometrics for this study In Process = questionable, In Process Assigned Not Recd = Tests assigned to examiners, no tests received (required tests) Reserved not Received = Tests in reserved status, not received Total Assignments = sum of Usable, Received Non Final, Assigned Partial Received, Assigned Not Received Selected = default status for making an assignment
D3: =_xlfn.CONCAT("Study Acronym: "," WISC6_STDZ_P") -> Study Acronym: WISC6_STDZ_P | F3: Study ID: 3766
D5: Additional Requirements
D6: REG : A least some for each region within sampling band ETH : ±4% for White, up to +4% for any other group, cannot go lower than target for any group except White. Must also meet margin requirements for age x race/eth and age x PED but age x race/eth x PED is reported in manual. SEX : Within each sampling band must be exactly 50/50 M/F ED: Vary by +2% for any group, but cannot go lower than target for any group except PED 4 or 5 Each sampling band must be exactly N=200
B8: =_xlfn.CONCAT("Last Refreshed at: ",aurora_data!AK4) -> Last Refreshed at: 09/17/2026 @ 7:18 AM | E8: Demographic Variables
D9: Variance Tolerance: | E9: 0.02 | AD9: 0.1
B10: Status | E10: Ethnicity by Education Level | AD10: Region | AH10: SEX | AL10: Totals
C11: ageband | D11: report | E11: AS | J11: BL | O11: HI | T11: OT | Y11: WH | AD11: MW | AE11: NE | AF11: SO | AG11: WE | AH11: F | AI11: M
E12: 1 | F12: 2 | G12: 3 | H12: 4 | I12: 5 | J12: 1 | K12: 2 | L12: 3 | M12: 4 | N12: 5 | O12: 1 | P12: 2 | Q12: 3 | R12: 4 | S12: 5 | T12: 1 | U12: 2 | V12: 3 | W12: 4 | X12: 5 | Y12: 1 | Z12: 2 | AA12: 3 | AB12: 4 | AC12: 5
B13: Open | C13: =aurora_data!A4 -> 06.00.00-06.11.30 | D13: Target | E13: =aurora_data!D4 -> 0.41 | F13: =aurora_data!E4 -> 0.42 | G13: =aurora_data!F4 -> 0.98 | H13: =aurora_data!G4 -> 1.8 | I13: =aurora_data!H4 -> 6.7 | J13: =aurora_data!I4 -> 0.39 | K13: =aurora_data!J4 -> 1.48 | L13: =aurora_data!K4 -> 7.01 | ... AJ13: =aurora_data!AI4 -> 0 | AL13: =aurora_data!AJ4 -> 200 | AM13: =SUM(AL13)/$AL$13 -> 1 | BR13: 20
D14: Usable | E14: =aurora_data!D5 -> 0 | F14: =aurora_data!E5 -> 0 | G14: =aurora_data!F5 -> 0 | H14: =aurora_data!G5 -> 2 | I14: =aurora_data!H5 -> 7 | J14: =aurora_data!I5 -> 0 | K14: =aurora_data!J5 -> 1 | L14: =aurora_data!K5 -> 7 | ... AJ14: =aurora_data!AI5 -> 0 | AL14: =aurora_data!AJ5 -> 191 | AM14: =SUM(AL14)/$AL$13 -> 0.955 | BR14: 38
D15: Stratified Out Usable N | E15: =aurora_data!D6 -> 0 | F15: =aurora_data!E6 -> 0 | G15: =aurora_data!F6 -> 0 | H15: =aurora_data!G6 -> 0 | I15: =aurora_data!H6 -> 0 | J15: =aurora_data!I6 -> 0 | K15: =aurora_data!J6 -> 0 | L15: =aurora_data!K6 -> 0 | ... AJ15: =aurora_data!AI6 -> 0 | AL15: =aurora_data!AJ6 -> 25 | AM15: =SUM(AL15)/$AL$13 -> 0.125 | BR15: 39
D16: In Process | E16: =aurora_data!D7 -> 0 | F16: =aurora_data!E7 -> 0 | G16: =aurora_data!F7 -> 0 | H16: =aurora_data!G7 -> 0 | I16: =aurora_data!H7 -> 0 | J16: =aurora_data!I7 -> 0 | K16: =aurora_data!J7 -> 0 | L16: =aurora_data!K7 -> 0 | ... AJ16: =aurora_data!AI7 -> 0 | AL16: =aurora_data!AJ7 -> 0 | AM16: =SUM(AL16)/$AL$13 -> 0 | BR16: 42
D17: Assigned Not Received | E17: =aurora_data!D8 -> 0 | F17: =aurora_data!E8 -> 0 | G17: =aurora_data!F8 -> 1 | H17: =aurora_data!G8 -> 0 | I17: =aurora_data!H8 -> 0 | J17: =aurora_data!I8 -> 2 | K17: =aurora_data!J8 -> 0 | L17: =aurora_data!K8 -> 0 | ... AJ17: =aurora_data!AI8 -> 0 | AL17: =aurora_data!AJ8 -> 10 | AM17: =SUM(AL17)/$AL$13 -> 0.05
D18: Reserved Not Received | E18: =aurora_data!D9 -> 0 | F18: =aurora_data!E9 -> 0 | G18: =aurora_data!F9 -> 0 | H18: =aurora_data!G9 -> 0 | I18: =aurora_data!H9 -> 0 | J18: =aurora_data!I9 -> 0 | K18: =aurora_data!J9 -> 0 | L18: =aurora_data!K9 -> 0 | ... AJ18: =aurora_data!AI9 -> 0 | AL18: =aurora_data!AJ9 -> 3 | AM18: =SUM(AL18)/$AL$13 -> 0.015
D19: Total Assignments | E19: =aurora_data!D10 -> 0 | F19: =aurora_data!E10 -> 0 | G19: =aurora_data!F10 -> 1 | H19: =aurora_data!G10 -> 2 | I19: =aurora_data!H10 -> 7 | J19: =aurora_data!I10 -> 2 | K19: =aurora_data!J10 -> 1 | L19: =aurora_data!K10 -> 7 | ... AJ19: =aurora_data!AI10 -> 0 | AL19: =aurora_data!AJ10 -> 229 | AM19: =SUM(AL19)/$AL$13 -> 1.145
D20: Selected | E20: =aurora_data!D11 -> 0 | F20: =aurora_data!E11 -> 0 | G20: =aurora_data!F11 -> 0 | H20: =aurora_data!G11 -> 0 | I20: =aurora_data!H11 -> 0 | J20: =aurora_data!I11 -> 0 | K20: =aurora_data!J11 -> 0 | L20: =aurora_data!K11 -> 0 | ... AJ20: =aurora_data!AI11 -> 0 | AL20: =aurora_data!AJ11 -> 11 | AM20: =SUM(AL20)/$AL$13 -> 0.055
D21: Max N Variance | E21: =ROUNDDOWN((E23+$E$9)*($AL13),0) -> 4 | F21: =ROUNDDOWN((F23+$E$9)*($AL13),0) -> 4 | G21: =ROUNDDOWN((G23+$E$9)*($AL13),0) -> 4 | H21: =ROUNDDOWN((H23+$E$9)*($AL13),0) -> 5 | I21: =ROUNDDOWN((I23+$E$9)*($AL13),0) -> 10 | J21: =ROUNDDOWN((J23+$E$9)*($AL13),0) -> 4 | K21: =ROUNDDOWN((K23+$E$9)*($AL13),0) -> 5 | L21: =ROUNDDOWN((L23+$E$9)*($AL13),0) -> 11 | ... AC21: =ROUNDDOWN((AC23+$E$9)*($AL13),0) -> 51 | AD21: =ROUNDDOWN((AD23+$AD$9)*($AL13),0) -> 64 | AE21: =ROUNDDOWN((AE23+$AD$9)*($AL13),0) -> 50 | AF21: =ROUNDDOWN((AF23+$AD$9)*($AL13),0) -> 100 | AG21: =ROUNDDOWN((AG23+$AD$9)*($AL13),0) -> 65 | AH21: =ROUNDDOWN((AH23+$AH$9)*($AL13),0) -> 100 | AI21: =ROUNDDOWN((AI23+$AH$9)*($AL13),0) -> 100
D22: Min N Variance | E22: =IF(ROUND(((E23-$E$9)*($AL13))+0.25,0) <=0,1,((E23-$E$9)*($AL13))+0.25) -> 1 | F22: =IF(ROUND(((F23-$E$9)*($AL13))+0.25,0) <=0,1,((F23-$E$9)*($AL13))+0.25) -> 1 | G22: =IF(ROUND(((G23-$E$9)*($AL13))+0.25,0) <=0,1,((G23-$E$9)*($AL13))+0.25) -> 1 | H22: =IF(ROUND(((H23-$E$9)*($AL13))+0.25,0) <=0,1,((H23-$E$9)*($AL13))+0.25) -> 1 | I22: =IF(ROUND(((I23-$E$9)*($AL13))+0.25,0) <=0,1,((I23-$E$9)*($AL13))+0.25) -> 2.95 | J22: =IF(ROUND(((J23-$E$9)*($AL13))+0.25,0) <=0,1,((J23-$E$9)*($AL13))+0.25) -> 1 | K22: =IF(ROUND(((K23-$E$9)*($AL13))+0.25,0) <=0,1,((K23-$E$9)*($AL13))+0.25) -> 1 | L22: =IF(ROUND(((L23-$E$9)*($AL13))+0.25,0) <=0,1,((L23-$E$9)*($AL13))+0.25) -> 3.26 | ... AC22: =IF(ROUND(((AC23-$E$9)*($AL13))+0.25,0) <=0,1,((AC23-$E$9)*($AL13))+0.25) -> 44.22 | AD22: =IF(((AD23-$AD$9)*($AL13))+0.5 <0,1,((AD23-$AD$9)*($AL13))+0.5 ) -> 24.8 | AE22: =IF(((AE23-$AD$9)*($AL13))+0.5 <0,1,((AE23-$AD$9)*($AL13))+0.5 ) -> 11.03 | AF22: =IF(((AF23-$AD$9)*($AL13))+0.5 <0,1,((AF23-$AD$9)*($AL13))+0.5 ) -> 60.5 | AG22: =IF(((AG23-$AD$9)*($AL13))+0.5 <0,1,((AG23-$AD$9)*($AL13))+0.5 ) -> 25.67 | AH22: =IF(((AH23-$AH$9)*($AL13))+0.5 <0,1,((AH23-$AH$9)*($AL13)) ) -> 100 | AI22: =IF(((AI23-$AH$9)*($AL13))+0.5 <0,1,((AI23-$AH$9)*($AL13))) -> 100
D23: Census % | E23: =IFERROR(E13/$AL13,0) -> 0.00205 | F23: =IFERROR(F13/$AL13,0) -> 0.0021 | G23: =IFERROR(G13/$AL13,0) -> 0.0049 | H23: =IFERROR(H13/$AL13,0) -> 0.009 | I23: =IFERROR(I13/$AL13,0) -> 0.0335 | J23: =IFERROR(J13/$AL13,0) -> 0.00195 | K23: =IFERROR(K13/$AL13,0) -> 0.0074 | L23: =IFERROR(L13/$AL13,0) -> 0.03505 | ... AJ23: =IFERROR(AJ13/$AL13,0) -> 0
D24: Usable % | E24: =IFERROR(E14/$AL13,0) -> 0 | F24: =IFERROR(F14/$AL13,0) -> 0 | G24: =IFERROR(G14/$AL13,0) -> 0 | H24: =IFERROR(H14/$AL13,0) -> 0.01 | I24: =IFERROR(I14/$AL13,0) -> 0.035 | J24: =IFERROR(J14/$AL13,0) -> 0 | K24: =IFERROR(K14/$AL13,0) -> 0.005 | L24: =IFERROR(L14/$AL13,0) -> 0.035 | ... AJ24: =IFERROR(AJ14/$AL13,0) -> 0
D25: Difference % | E25: =E24-E23 -> -0.00205 | F25: =F24-F23 -> -0.0021 | G25: =G24-G23 -> -0.0049 | H25: =H24-H23 -> 0.001 | I25: =I24-I23 -> 0.0015 | J25: =J24-J23 -> -0.00195 | K25: =K24-K23 -> -0.0024 | L25: =L24-L23 -> -5e-05 | ... AJ25: =AJ24-AJ23 -> 0
B26: Open | C26: =aurora_data!A12 -> 07.00.00-07.11.30 | D26: Target | E26: =aurora_data!D12 -> 0.28 | F26: =aurora_data!E12 -> 0.32 | G26: =aurora_data!F12 -> 0.94 | H26: =aurora_data!G12 -> 1.53 | I26: =aurora_data!H12 -> 6.48 | J26: =aurora_data!I12 -> 0.47 | K26: =aurora_data!J12 -> 1.61 | L26: =aurora_data!K12 -> 7.13 | ... AJ26: =aurora_data!AI12 -> 0 | AL26: =aurora_data!AJ12 -> 200 | AM26: =SUM(AL26)/$AL$26 -> 1
D27: Usable | E27: =aurora_data!D13 -> 0 | F27: =aurora_data!E13 -> 0 | G27: =aurora_data!F13 -> 2 | H27: =aurora_data!G13 -> 2 | I27: =aurora_data!H13 -> 6 | J27: =aurora_data!I13 -> 0 | K27: =aurora_data!J13 -> 2 | L27: =aurora_data!K13 -> 7 | ... AJ27: =aurora_data!AI13 -> 0 | AL27: =aurora_data!AJ13 -> 197 | AM27: =SUM(AL27)/$AL$26 -> 0.985
D28: Stratified Out Usable N | E28: =aurora_data!D14 -> 0 | F28: =aurora_data!E14 -> 0 | G28: =aurora_data!F14 -> 0 | H28: =aurora_data!G14 -> 0 | I28: =aurora_data!H14 -> 0 | J28: =aurora_data!I14 -> 2 | K28: =aurora_data!J14 -> 0 | L28: =aurora_data!K14 -> 2 | ... AJ28: =aurora_data!AI14 -> 0 | AL28: =aurora_data!AJ14 -> 30 | AM28: =SUM(AL28)/$AL$26 -> 0.15
D29: In Process | E29: =aurora_data!D15 -> 0 | F29: =aurora_data!E15 -> 0 | G29: =aurora_data!F15 -> 0 | H29: =aurora_data!G15 -> 0 | I29: =aurora_data!H15 -> 0 | J29: =aurora_data!I15 -> 0 | K29: =aurora_data!J15 -> 0 | L29: =aurora_data!K15 -> 0 | ... AJ29: =aurora_data!AI15 -> 0 | AL29: =aurora_data!AJ15 -> 0 | AM29: =SUM(AL29)/$AL$26 -> 0
D30: Assigned Not Received | E30: =aurora_data!D16 -> 0 | F30: =aurora_data!E16 -> 0 | G30: =aurora_data!F16 -> 0 | H30: =aurora_data!G16 -> 0 | I30: =aurora_data!H16 -> 0 | J30: =aurora_data!I16 -> 0 | K30: =aurora_data!J16 -> 0 | L30: =aurora_data!K16 -> 0 | ... AJ30: =aurora_data!AI16 -> 0 | AL30: =aurora_data!AJ16 -> 7 | AM30: =SUM(AL30)/$AL$26 -> 0.035
D31: Reserved Not Received | E31: =aurora_data!D17 -> 0 | F31: =aurora_data!E17 -> 0 | G31: =aurora_data!F17 -> 0 | H31: =aurora_data!G17 -> 0 | I31: =aurora_data!H17 -> 0 | J31: =aurora_data!I17 -> 0 | K31: =aurora_data!J17 -> 0 | L31: =aurora_data!K17 -> 0 | ... AJ31: =aurora_data!AI17 -> 0 | AL31: =aurora_data!AJ17 -> 0 | AM31: =SUM(AL31)/$AL$26 -> 0
D32: Total Assignments | E32: =aurora_data!D18 -> 0 | F32: =aurora_data!E18 -> 0 | G32: =aurora_data!F18 -> 2 | H32: =aurora_data!G18 -> 2 | I32: =aurora_data!H18 -> 6 | J32: =aurora_data!I18 -> 2 | K32: =aurora_data!J18 -> 2 | L32: =aurora_data!K18 -> 9 | ... AJ32: =aurora_data!AI18 -> 0 | AL32: =aurora_data!AJ18 -> 234 | AM32: =SUM(AL32)/$AL$26 -> 1.17
D33: Selected | E33: =aurora_data!D19 -> 0 | F33: =aurora_data!E19 -> 0 | G33: =aurora_data!F19 -> 0 | H33: =aurora_data!G19 -> 0 | I33: =aurora_data!H19 -> 2 | J33: =aurora_data!I19 -> 0 | K33: =aurora_data!J19 -> 0 | L33: =aurora_data!K19 -> 0 | ... AJ33: =aurora_data!AI19 -> 0 | AL33: =aurora_data!AJ19 -> 12 | AM33: =SUM(AL33)/$AL$26 -> 0.06
D34: Max N Variance | E34: =ROUNDDOWN((E37+$E$9)*($AL26),0) -> 4 | F34: =ROUNDDOWN((F37+$E$9)*($AL26),0) -> 4 | G34: =ROUNDDOWN((G37+$E$9)*($AL26),0) -> 4 | H34: =ROUNDDOWN((H37+$E$9)*($AL26),0) -> 5 | I34: =ROUNDDOWN((I37+$E$9)*($AL26),0) -> 10 | J34: =ROUNDDOWN((J37+$E$9)*($AL26),0) -> 4 | K34: =ROUNDDOWN((K37+$E$9)*($AL26),0) -> 5 | L34: =ROUNDDOWN((L37+$E$9)*($AL26),0) -> 11 | ... AC34: =ROUNDDOWN((AC37+$E$9)*($AL26),0) -> 52 | AD34: =ROUNDDOWN((AD37+$AD$9)*($AL26),0) -> 61 | AE34: =ROUNDDOWN((AE37+$AD$9)*($AL26),0) -> 50 | AF34: =ROUNDDOWN((AF37+$AD$9)*($AL26),0) -> 101 | AG34: =ROUNDDOWN((AG37+$AD$9)*($AL26),0) -> 66 | AH34: =ROUNDDOWN((AH37+$AH$9)*($AL26),0) -> 100 | AI34: =ROUNDDOWN((AI37+$AH$9)*($AL26),0) -> 100
D35: Min N Variance | E35: =IF(ROUND(((E37-$E$9)*($AL26))+0.25,0) <=0,1,((E37-$E$9)*($AL26))+0.25) -> 1 | F35: =IF(ROUND(((F37-$E$9)*($AL26))+0.25,0) <=0,1,((F37-$E$9)*($AL26))+0.25) -> 1 | G35: =IF(ROUND(((G37-$E$9)*($AL26))+0.25,0) <=0,1,((G37-$E$9)*($AL26))+0.25) -> 1 | H35: =IF(ROUND(((H37-$E$9)*($AL26))+0.25,0) <=0,1,((H37-$E$9)*($AL26))+0.25) -> 1 | I35: =IF(ROUND(((I37-$E$9)*($AL26))+0.25,0) <=0,1,((I37-$E$9)*($AL26))+0.25) -> 2.73 | J35: =IF(ROUND(((J37-$E$9)*($AL26))+0.25,0) <=0,1,((J37-$E$9)*($AL26))+0.25) -> 1 | K35: =IF(ROUND(((K37-$E$9)*($AL26))+0.25,0) <=0,1,((K37-$E$9)*($AL26))+0.25) -> 1 | L35: =IF(ROUND(((L37-$E$9)*($AL26))+0.25,0) <=0,1,((L37-$E$9)*($AL26))+0.25) -> 3.38 | ... AC35: =IF(ROUND(((AC37-$E$9)*($AL26))+0.25,0) <=0,1,((AC37-$E$9)*($AL26))+0.25) -> 44.47 | AD35: =IF(((AD37-$AD$9)*($AL26))+0.5 <0,1,((AD37-$AD$9)*($AL26))+0.5 ) -> 22.18 | AE35: =IF(((AE37-$AD$9)*($AL26))+0.5 <0,1,((AE37-$AD$9)*($AL26))+0.5 ) -> 11.11 | AF35: =IF(((AF37-$AD$9)*($AL26))+0.5 <0,1,((AF37-$AD$9)*($AL26))+0.5 ) -> 61.5 | AG35: =IF(((AG37-$AD$9)*($AL26))+0.5 <0,1,((AG37-$AD$9)*($AL26))+0.5 ) -> 27.21 | AH35: =IF(((AH37-$AH$9)*($AL26))+0.5 <0,1,((AH37-$AH$9)*($AL26)) ) -> 100 | AI35: =IF(((AI37-$AH$9)*($AL26))+0.5 <0,1,((AI37-$AH$9)*($AL26))) -> 100
D37: Census % | E37: =IFERROR(E26/$AL26,0) -> 0.0014 | F37: =IFERROR(F26/$AL26,0) -> 0.0016 | G37: =IFERROR(G26/$AL26,0) -> 0.0047 | H37: =IFERROR(H26/$AL26,0) -> 0.00765 | I37: =IFERROR(I26/$AL26,0) -> 0.0324 | J37: =IFERROR(J26/$AL26,0) -> 0.00235 | K37: =IFERROR(K26/$AL26,0) -> 0.00805 | L37: =IFERROR(L26/$AL26,0) -> 0.03565 | ... AJ37: =IFERROR(AJ26/$AL26,0) -> 0
D38: Usable % | E38: =IFERROR(E27/$AL26,0) -> 0 | F38: =IFERROR(F27/$AL26,0) -> 0 | G38: =IFERROR(G27/$AL26,0) -> 0.01 | H38: =IFERROR(H27/$AL26,0) -> 0.01 | I38: =IFERROR(I27/$AL26,0) -> 0.03 | J38: =IFERROR(J27/$AL26,0) -> 0 | K38: =IFERROR(K27/$AL26,0) -> 0.01 | L38: =IFERROR(L27/$AL26,0) -> 0.035 | ... AJ38: =IFERROR(AJ27/$AL26,0) -> 0
D39: Difference % | E39: =E38-E37 -> -0.0014 | F39: =F38-F37 -> -0.0016 | G39: =G38-G37 -> 0.0053 | H39: =H38-H37 -> 0.00235 | I39: =I38-I37 -> -0.0024 | J39: =J38-J37 -> -0.00235 | K39: =K38-K37 -> 0.00195 | L39: =L38-L37 -> -0.00065 | ... AJ39: =AJ38-AJ37 -> 0
B40: Open | C40: =aurora_data!A20 -> 08.00.00-08.11.30 | D40: Target | E40: =aurora_data!D20 -> 0.31 | F40: =aurora_data!E20 -> 0.31 | G40: =aurora_data!F20 -> 1.18 | H40: =aurora_data!G20 -> 1.45 | I40: =aurora_data!H20 -> 6.38 | J40: =aurora_data!I20 -> 0.37 | K40: =aurora_data!J20 -> 1.72 | L40: =aurora_data!K20 -> 6.47 | ... AJ40: =aurora_data!AI20 -> 0 | AL40: =aurora_data!AJ20 -> 200 | AM40: =SUM(AL40)/$AL$40 -> 1
D41: Usable | E41: =aurora_data!D21 -> 0 | F41: =aurora_data!E21 -> 0 | G41: =aurora_data!F21 -> 2 | H41: =aurora_data!G21 -> 1 | I41: =aurora_data!H21 -> 6 | J41: =aurora_data!I21 -> 1 | K41: =aurora_data!J21 -> 2 | L41: =aurora_data!K21 -> 6 | ... AJ41: =aurora_data!AI21 -> 0 | AL41: =aurora_data!AJ21 -> 195 | AM41: =SUM(AL41)/$AL$40 -> 0.975
D42: Stratified Out Usable N | E42: =aurora_data!D22 -> 0 | F42: =aurora_data!E22 -> 0 | G42: =aurora_data!F22 -> 0 | H42: =aurora_data!G22 -> 3 | I42: =aurora_data!H22 -> 0 | J42: =aurora_data!I22 -> 0 | K42: =aurora_data!J22 -> 1 | L42: =aurora_data!K22 -> 3 | ... AJ42: =aurora_data!AI22 -> 0 | AL42: =aurora_data!AJ22 -> 20 | AM42: =SUM(AL42)/$AL$40 -> 0.1
D43: In Process | E43: =aurora_data!D23 -> 0 | F43: =aurora_data!E23 -> 0 | G43: =aurora_data!F23 -> 0 | H43: =aurora_data!G23 -> 0 | I43: =aurora_data!H23 -> 0 | J43: =aurora_data!I23 -> 0 | K43: =aurora_data!J23 -> 0 | L43: =aurora_data!K23 -> 0 | ... AJ43: =aurora_data!AI23 -> 0 | AL43: =aurora_data!AJ23 -> 0 | AM43: =SUM(AL43)/$AL$40 -> 0
...

Sheet WISC6_STDZ_P_2cross
B1: Total Assigments below Target | E1: Study Information | P1: Additional Information
B2: Usable greater/equal to target | E2: =_xlfn.CONCAT("Study Name: "," WISC-6 Standardization - Paper") -> Study Name: WISC-6 Standardization - Paper | M2: Usable = case is available to Psychometrics for this study In Process = questionable, In Process Assigned Not Recd = Tests assigned to examiners, no tests received (required tests) Reserved not Received = Tests in reserved status, not received Total Assignments = sum of Usable, Received Non Final, Assigned Partial Received, Assigned Not Received Selected = default status for making an assignment
E3: =_xlfn.CONCAT("Study Acronym: "," WISC6_STDZ_P") -> Study Acronym: WISC6_STDZ_P | H3: Study ID: 3766
E5: Additional Requirements
E6: REG : A least some for each region within sampling band ETH : ±4% for White, up to +4% for any other group, cannot go lower than target for any group except White. Must also meet margin requirements for age x race/eth and age x PED but age x race/eth x PED is reported in manual. SEX : Within each sampling band must be exactly 50/50 M/F ED: Vary by +2% for any group, but cannot go lower than target for any group except PED 4 or 5 Each sampling band must be exactly N=200
C9: =_xlfn.CONCAT("Last Refreshed at: ",aurora_data!BV4) -> Last Refreshed at: 09/17/2026 @ 7:18 AM | F9: Demographic Variables | X9: Totals
E10: Variance Tolerance: | F10: 0.02 | K10: 0.04 | P10: 0.1
C11: Status | F11: Education Level | K11: Ethnicity | P11: Region | T11: SEX
D12: ageband | E12: report | F12: 1 | G12: 2 | H12: 3 | I12: 4 | J12: 5 | K12: AS | L12: BL | M12: HI | N12: OTH | O12: WH | P12: MW | Q12: NE | R12: SO | S12: WE | T12: F | U12: M | V12: INT
C13: Open | D13: =aurora_data!BA4 -> 06.00.00-06.11.30 | E13: Target | F13: =IFERROR(aurora_data!BD4,0) -> 5.24 | G13: =IFERROR(aurora_data!BE4,0) -> 9.9 | H13: =IFERROR(aurora_data!BF4,0) -> 39.65 | I13: =IFERROR(aurora_data!BG4,0) -> 64.32 | J13: =IFERROR(aurora_data!BH4,0) -> 80.88 | K13: =IFERROR(aurora_data!BI4,0) -> 10.31 | L13: =IFERROR(aurora_data!BJ4,0) -> 24.51 | M13: =IFERROR(aurora_data!BK4,0) -> 48.37 | ... V13: =IFERROR(aurora_data!BT4,0) -> 0 | X13: =IFERROR(aurora_data!BU4,0) -> 200 | Y13: =IFERROR(X13/$X$13,0) -> 1
E14: Usable | F14: =IFERROR(aurora_data!BD5,0) -> 4 | G14: =IFERROR(aurora_data!BE5,0) -> 6 | H14: =IFERROR(aurora_data!BF5,0) -> 36 | I14: =IFERROR(aurora_data!BG5,0) -> 65 | J14: =IFERROR(aurora_data!BH5,0) -> 80 | K14: =IFERROR(aurora_data!BI5,0) -> 9 | L14: =IFERROR(aurora_data!BJ5,0) -> 24 | M14: =IFERROR(aurora_data!BK5,0) -> 46 | ... V14: =IFERROR(aurora_data!BT5,0) -> 0 | X14: =IFERROR(aurora_data!BU5,0) -> 191 | Y14: =IFERROR(X14/$X$13,0) -> 0.955
