Workbook

Sheet setup
B3: Phase Setup
B4: Phase Id | C4: 405
B6: Main Study Setup | H6: Stratification Types | K6: matrix sproc
C7: Stratification % | D7: (separate study ids by and exclamation point ! for more than one) | E7: Stratification Type | H7: 1 = 2 Cross | K7: call report_matrix(studyids, stratfication type, stratification%);
B8: StudyIDs (2Cross) | C8: 50 | D8: 3037 | E8: 1 | H8: 2 = 3 Cross ETH/ED
B9: StudyIDs (3Cross) | C9: 50 | D9: 3037 | E9: 2 | H9: 3 = 3 Cross SEX/ETH
B10: StudyIDs (2Cross) | C10: 100 | D10: 3037 | E10: 1
B11: StudyIDs (3Cross) | C11: 100 | D11: 3037 | E11: 2
B12: StudyIDs (3Cross alternate view) | C12: 100 | D12: 3037 | E12: 3
B13: Validity/Reliability Setup | H13: Total study count for this report | K13: =COUNTIF(M:M, "Active") - COUNTIFS(L:L, "OSEP*",M:M, "Active") - COUNTIFS(L:L,"C_*",M:M, "Active") +2 -> 36
B14: Reports will show based on the ordered list below | H14: Phase Study List
B15: Report Order (do not touch) | C15: Study Id (separate studyids by !) | D15: Study Name | E15: Study Acronym | F15: Total Assignment | H15: study_id | I15: study_type_description | J15: sort_order | K15: study_name | L15: study_acronym | M15: study_status
A16: =LEN(C16) - LEN(SUBSTITUTE(C16, "!", "")) + 1 -> 1 | B16: 1 | C16: 3817 | D16: OSEP – Autism - Paper | E16: OSEP_AUT_P | F16: =aurora_data!U98 -> 22 | H16: 3767 | I16: Main | J16: 1 | K16: WISC-6 Standardization - Digital | L16: WISC6_STDZ_D | M16: Active
A17: =LEN(C17) - LEN(SUBSTITUTE(C17, "!", "")) + 1 -> 1 | B17: 2 | C17: 3829 | D17: OSEP – Autism - Digital | E17: OSEP_AUT_D | F17: =aurora_data!U226 -> 6 | H17: 3766 | I17: Main | J17: 1 | K17: WISC-6 Standardization - Paper | L17: WISC6_STDZ_P | M17: Active
A18: =LEN(C18) - LEN(SUBSTITUTE(C18, "!", "")) + 1 -> 1 | B18: 3 | C18: 3818 | D18: OSEP – Developmental Delay - Paper | E18: OSEP_DD_P | F18: =aurora_data!U270 -> 1 | H18: 3822 | I18: Clinical | J18: 2 | K18: OSEP – Other Health Impairment - Paper | L18: OSEP_OHI_P | M18: Active
A19: =LEN(C19) - LEN(SUBSTITUTE(C19, "!", "")) + 1 -> 1 | B19: 4 | C19: 3830 | D19: OSEP – Developmental Delay - Digital | E19: OSEP_DD_D | F19: =aurora_data!U370 -> 0 | H19: 3806 | I19: Clinical | J19: 2 | K19: WISC-6 Clinical Validity Language Disorder with Receptive Impairment (Ages 6-8) - Paper | L19: CV_LDR_CELF5_RF1_P | M19: Active
A20: =LEN(C20) - LEN(SUBSTITUTE(C20, "!", "")) + 1 -> 1 | B20: 5 | C20: 3819 | D20: OSEP – Emotional Disturbance - Paper | E20: OSEP_ED_P | F20: =aurora_data!U526 -> 0 | H20: 3821 | I20: Clinical | J20: 2 | K20: OSEP – Orthopedic Impairment - Paper | L20: OSEP_OI_P | M20: Active
A21: =LEN(C21) - LEN(SUBSTITUTE(C21, "!", "")) + 1 -> 1 | B21: 6 | C21: 3831 | D21: OSEP – Emotional Disturbance - Digital | E21: OSEP_ED_D | F21: =aurora_data!U646 -> 0 | H21: 3820 | I21: Clinical | J21: 2 | K21: OSEP – Multiple Disabilities - Paper | L21: OSEP_MD_P | M21: Active
A22: =LEN(C22) - LEN(SUBSTITUTE(C22, "!", "")) + 1 -> 1 | B22: 7 | C22: 3820 | D22: OSEP – Multiple Disabilities - Paper | E22: OSEP_MD_P | F22: =aurora_data!U746 -> 1 | H22: 3819 | I22: Clinical | J22: 2 | K22: OSEP – Emotional Disturbance - Paper | L22: OSEP_ED_P | M22: Active
A23: =LEN(C23) - LEN(SUBSTITUTE(C23, "!", "")) + 1 -> 1 | B23: 8 | C23: 3832 | D23: OSEP – Multiple Disabilities - Digital | E23: OSEP_MD_D | F23: =aurora_data!U846 -> 0 | H23: 3818 | I23: Clinical | J23: 2 | K23: OSEP – Developmental Delay - Paper | L23: OSEP_DD_P | M23: Active
A24: =LEN(C24) - LEN(SUBSTITUTE(C24, "!", "")) + 1 -> 1 | B24: 9 | C24: 3821 | D24: OSEP – Orthopedic Impairment - Paper | E24: OSEP_OI_P | F24: =aurora_data!U946 -> 2 | H24: 3817 | I24: Clinical | J24: 2 | K24: OSEP – Autism - Paper | L24: OSEP_AUT_P | M24: Active
A25: =LEN(C25) - LEN(SUBSTITUTE(C25, "!", "")) + 1 -> 1 | B25: 10 | C25: 3833 | D25: OSEP – Orthopedic Impairment - Digital | E25: OSEP_OI_D | F25: =aurora_data!U1046 -> 0 | H25: 3816 | I25: Clinical | J25: 2 | K25: WISC-6 Clinical Validity Traumatic Brain Injury - Paper | L25: CV_TBI_VINE3_P | M25: Active
A26: =LEN(C26) - LEN(SUBSTITUTE(C26, "!", "")) + 1 -> 1 | B26: 11 | C26: 3822 | D26: OSEP – Other Health Impairment - Paper | E26: OSEP_OHI_P | F26: =aurora_data!U1226 -> 0 | H26: 3815 | I26: Clinical | J26: 2 | K26: WISC-6 Clinical Traumatic Brain Injury - Paper | L26: C_TBI_P | M26: Active
A27: =LEN(C27) - LEN(SUBSTITUTE(C27, "!", "")) + 1 -> 1 | B27: 12 | C27: 3834 | D27: OSEP – Other Health Impairment - Digital | E27: OSEP_OHI_D | F27: =aurora_data!U1326 -> 0 | H27: 3814 | I27: Clinical | J27: 2 | K27: WISC-6 Clinical Validity Motor Impairment - Paper | L27: CV_MI_VINE3_P | M27: Active
A28: =LEN(C28) - LEN(SUBSTITUTE(C28, "!", "")) + 1 -> 1 | B28: 13 | C28: 3823 | D28: OSEP – Specific Learning Disability - Paper | E28: OSEP_SLD_P | F28: =aurora_data!U1426 -> 19 | H28: 3813 | I28: Clinical | J28: 2 | K28: WISC-6 Clinical Motor Impairment - Paper | L28: C_MI_P | M28: Active
A29: =LEN(C29) - LEN(SUBSTITUTE(C29, "!", "")) + 1 -> 1 | B29: 14 | C29: 3835 | D29: OSEP – Specific Learning Disability - Digital | E29: OSEP_SLD_D | F29: =aurora_data!U1526 -> 1 | H29: 3812 | I29: Clinical | J29: 2 | K29: WISC-6 Clinical Validity Language Disorder with Expressive Impairment (Ages 9-16) - Paper | L29: CV_LDE_CELF5_RF2_P | M29: Active
A30: =LEN(C30) - LEN(SUBSTITUTE(C30, "!", "")) + 1 -> 1 | B30: 15 | C30: 3824 | D30: OSEP – Speech Impairment - Paper | E30: OSEP_SI_P | F30: =aurora_data!U1626 -> 4 | H30: 3811 | I30: Clinical | J30: 2 | K30: WISC-6 Clinical Language Disorder with Expressive Impairment (Ages 9-16) - Paper | L30: C_LDE_9-16_P | M30: Active
A31: =LEN(C31) - LEN(SUBSTITUTE(C31, "!", "")) + 1 -> 1 | B31: 16 | C31: 3836 | D31: OSEP – Speech Impairment - Digital | E31: OSEP_SI_D | F31: =aurora_data!U1726 -> 0 | H31: 3810 | I31: Clinical | J31: 2 | K31: WISC-6 Clinical Validity Language Disorder with Expressive Impairment (Ages 6-8) - Paper | L31: CV_LDE_CELF5_RF1_P | M31: Active
A32: =LEN(C32) - LEN(SUBSTITUTE(C32, "!", "")) + 1 -> 1 | B32: 17 | C32: 3825 | D32: OSEP – Traumatic Brain Injury - Paper | E32: OSEP_TBI_P | F32: =aurora_data!U1746 -> 0 | H32: 3809 | I32: Clinical | J32: 2 | K32: WISC-6 Clinical Language Disorder with Expressive Impairment (Ages 6-8) - Paper | L32: C_LDE_6-8_P | M32: Active
A33: =LEN(C33) - LEN(SUBSTITUTE(C33, "!", "")) + 1 -> 1 | B33: 18 | C33: 3837 | D33: OSEP – Traumatic Brain Injury - Digital | E33: OSEP_TBI_D | F33: =aurora_data!U1846 -> 0 | H33: 3808 | I33: Clinical | J33: 2 | K33: WISC-6 Clinical Validity Language Disorder with Receptive Impairment (Ages 9-16) - Paper | L33: CV_LDR_CELF5_RF2_P | M33: Active
A34: =LEN(C33) - LEN(SUBSTITUTE(C33, "!", "")) + 1 -> 1 | B34: 19 | C34: 3827 | D34: OSEP – ADHD - Paper | E34: OSEP_ADHD_P | F34: =aurora_data!U2026 -> 117 | H34: 3807 | I34: Clinical | J34: 2 | K34: WISC-6 Clinical Language Disorder with Receptive Impairment (Ages 9-16) - Paper | L34: C_LDR_9-16_P | M34: Active
A35: =LEN(C34) - LEN(SUBSTITUTE(C34, "!", "")) + 1 -> 1 | B35: 20 | C35: 3838 | D35: OSEP – ADHD - Digital | E35: OSEP_ADHD_D | F35: =aurora_data!U2126 -> 19 | H35: 3843 | I35: Clinical | J35: 2 | K35: WISC-6 Clinical Validity Autism spectrum disorder with no language impairment - (Adolescent) Digital | L35: CV_ASD_NO_LI_BASC3_ADOL_D | M35: Active
H36: 3834 | I36: Clinical | J36: 2 | K36: OSEP – Other Health Impairment - Digital | L36: OSEP_OHI_D | M36: Active
H37: 3842 | I37: Clinical | J37: 2 | K37: WISC-6 Clinical Validity Autism spectrum disorder with no language impairment - (Adolescent) Paper | L37: CV_ASD_NO_LI_BASC3_ADOL_P | M37: Active
H38: 3841 | I38: Clinical | J38: 2 | K38: WISC-6 Clinical Validity Autism spectrum disorder with language impairment - (Adolescent) Paper | L38: CV_ASD_LI_BASC3_ADOL_P | M38: Active
H39: 3840 | I39: Clinical | J39: 2 | K39: WISC-6 Clinical Validity ADHD – (Adolescent) Digital | L39: CV_ADHD_BASC3_ADOL_D | M39: Active
H40: 3839 | I40: Clinical | J40: 2 | K40: WISC-6 Clinical Validity ADHD - (Adolescent) Paper | L40: CV_ADHD_BASC3_ADOL_P | M40: Active
H41: 3838 | I41: Clinical | J41: 2 | K41: OSEP – ADHD - Digital | L41: OSEP_ADHD_D | M41: Active
H42: 3837 | I42: Clinical | J42: 2 | K42: OSEP – Traumatic Brain Injury - Digital | L42: OSEP_TBI_D | M42: Active
H43: 3836 | I43: Clinical | J43: 2 | K43: OSEP – Speech Impairment - Digital | L43: OSEP_SI_D | M43: Active
...

Sheet aurora_data
A1: =setup!C16 -> 3817
A2: =_xlfn.CONCAT(setup!D16, " - ",setup!E16) -> OSEP – Autism - Paper - OSEP_AUT_P
A3: ageband | B3: gradeband | C3: report | D3: 1 | E3: 2 | F3: 3 | G3: 4 | H3: 5 | I3: AS | J3: BL | K3: HI | L3: OT | M3: WH | N3: MW | O3: NE | P3: SO | Q3: WE | R3: F | S3: M | T3: OTHER | U3: Total | V3: LastRefreshed
A4: 06.00.00-06.11.30 | C4: Target N | D4: 0 | E4: 0 | F4: 0 | G4: 0 | H4: 0 | I4: 0 | J4: 0 | K4: 0 | L4: 0 | M4: 0 | N4: 0 | O4: 0 | P4: 0 | Q4: 0 | R4: 0 | S4: 0 | T4: 0 | U4: 4 | V4: 09/17/2026 @ 7:20 AM
A5: 06.00.00-06.11.30 | C5: Stratified Usable N | D5: 0 | E5: 0 | F5: 0 | G5: 3 | H5: 1 | I5: 1 | J5: 0 | K5: 3 | L5: 0 | M5: 0 | N5: 0 | O5: 1 | P5: 1 | Q5: 2 | R5: 1 | S5: 3 | T5: 0 | U5: 4 | V5: 09/17/2026 @ 7:20 AM
A6: 06.00.00-06.11.30 | C6: Stratified Out Usable N | D6: 0 | E6: 0 | F6: 0 | G6: 0 | H6: 0 | I6: 0 | J6: 0 | K6: 0 | L6: 0 | M6: 0 | N6: 0 | O6: 0 | P6: 0 | Q6: 0 | R6: 0 | S6: 0 | T6: 0 | U6: 0 | V6: 09/17/2026 @ 7:20 AM
A7: 06.00.00-06.11.30 | C7: In Process N | D7: 0 | E7: 0 | F7: 0 | G7: 0 | H7: 0 | I7: 0 | J7: 0 | K7: 0 | L7: 0 | M7: 0 | N7: 0 | O7: 0 | P7: 0 | Q7: 0 | R7: 0 | S7: 0 | T7: 0 | U7: 0 | V7: 09/17/2026 @ 7:20 AM
A8: 06.00.00-06.11.30 | C8: Assigned Not Recd N | D8: 0 | E8: 0 | F8: 0 | G8: 0 | H8: 0 | I8: 0 | J8: 0 | K8: 0 | L8: 0 | M8: 0 | N8: 0 | O8: 0 | P8: 0 | Q8: 0 | R8: 0 | S8: 0 | T8: 0 | U8: 0 | V8: 09/17/2026 @ 7:20 AM
A9: 06.00.00-06.11.30 | C9: Reserved Not Recd N | D9: 0 | E9: 0 | F9: 0 | G9: 0 | H9: 0 | I9: 0 | J9: 0 | K9: 0 | L9: 0 | M9: 0 | N9: 0 | O9: 0 | P9: 0 | Q9: 0 | R9: 0 | S9: 0 | T9: 0 | U9: 0 | V9: 09/17/2026 @ 7:20 AM
A10: 06.00.00-06.11.30 | C10: Total Assignments | D10: 0 | E10: 0 | F10: 0 | G10: 3 | H10: 1 | I10: 1 | J10: 0 | K10: 3 | L10: 0 | M10: 0 | N10: 0 | O10: 1 | P10: 1 | Q10: 2 | R10: 1 | S10: 3 | T10: 0 | U10: 4 | V10: 09/17/2026 @ 7:20 AM
A11: 06.00.00-06.11.30 | C11: Selected N | D11: 0 | E11: 0 | F11: 0 | G11: 1 | H11: 0 | I11: 0 | J11: 0 | K11: 0 | L11: 0 | M11: 1 | N11: 0 | O11: 0 | P11: 1 | Q11: 0 | R11: 1 | S11: 0 | T11: 0 | U11: 1 | V11: 09/17/2026 @ 7:20 AM
A12: 07.00.00-07.11.30 | C12: Target N | D12: 0 | E12: 0 | F12: 0 | G12: 0 | H12: 0 | I12: 0 | J12: 0 | K12: 0 | L12: 0 | M12: 0 | N12: 0 | O12: 0 | P12: 0 | Q12: 0 | R12: 0 | S12: 0 | T12: 0 | U12: 4 | V12: 09/17/2026 @ 7:20 AM
A13: 07.00.00-07.11.30 | C13: Stratified Usable N | D13: 0 | E13: 1 | F13: 1 | G13: 1 | H13: 0 | I13: 0 | J13: 0 | K13: 2 | L13: 0 | M13: 1 | N13: 0 | O13: 0 | P13: 2 | Q13: 1 | R13: 1 | S13: 2 | T13: 0 | U13: 3 | V13: 09/17/2026 @ 7:20 AM
A14: 07.00.00-07.11.30 | C14: Stratified Out Usable N | D14: 0 | E14: 0 | F14: 0 | G14: 0 | H14: 0 | I14: 0 | J14: 0 | K14: 0 | L14: 0 | M14: 0 | N14: 0 | O14: 0 | P14: 0 | Q14: 0 | R14: 0 | S14: 0 | T14: 0 | U14: 0 | V14: 09/17/2026 @ 7:20 AM
A15: 07.00.00-07.11.30 | C15: In Process N | D15: 0 | E15: 0 | F15: 0 | G15: 0 | H15: 0 | I15: 0 | J15: 0 | K15: 0 | L15: 0 | M15: 0 | N15: 0 | O15: 0 | P15: 0 | Q15: 0 | R15: 0 | S15: 0 | T15: 0 | U15: 0 | V15: 09/17/2026 @ 7:20 AM
... A99: Total | C99: Selected N | D99: 0 | E99: 0 | F99: 0 | G99: 1 | H99: 0 | I99: 0 | J99: 0 | K99: 0 | L99: 0 | M99: 1 | N99: 0 | O99: 0 | P99: 1 | Q99: 0 | R99: 1 | S99: 0 | T99: 0 | U99: 1 | V99: 09/17/2026 @ 7:20 AM
A129: =setup!C17 -> 3829
A130: =_xlfn.CONCAT(setup!D17," - ",setup!E17) -> OSEP – Autism - Digital - OSEP_AUT_D
A131: ageband | B131: gradeband | C131: report | D131: 1 | E131: 2 | F131: 3 | G131: 4 | H131: 5 | I131: AS | J131: BL | K131: HI | L131: OT | M131: WH | N131: MW | O131: NE | P131: SO | Q131: WE | R131: F | S131: M | T131: OTHER | U131: Total | V131: LastRefreshed
A132: 06.00.00-06.11.30 | C132: Target N | D132: 0 | E132: 0 | F132: 0 | G132: 0 | H132: 0 | I132: 0 | J132: 0 | K132: 0 | L132: 0 | M132: 0 | N132: 0 | O132: 0 | P132: 0 | Q132: 0 | R132: 0 | S132: 0 | T132: 0 | U132: 1 | V132: 09/17/2026 @ 7:20 AM
A133: 06.00.00-06.11.30 | C133: Stratified Usable N | D133: 0 | E133: 0 | F133: 0 | G133: 0 | H133: 0 | I133: 0 | J133: 0 | K133: 0 | L133: 0 | M133: 0 | N133: 0 | O133: 0 | P133: 0 | Q133: 0 | R133: 0 | S133: 0 | T133: 0 | U133: 0 | V133: 09/17/2026 @ 7:20 AM
A134: 06.00.00-06.11.30 | C134: Stratified Out Usable N | D134: 0 | E134: 0 | F134: 0 | G134: 0 | H134: 0 | I134: 0 | J134: 0 | K134: 0 | L134: 0 | M134: 0 | N134: 0 | O134: 0 | P134: 0 | Q134: 0 | R134: 0 | S134: 0 | T134: 0 | U134: 0 | V134: 09/17/2026 @ 7:20 AM
A135: 06.00.00-06.11.30 | C135: In Process N | D135: 0 | E135: 0 | F135: 0 | G135: 0 | H135: 0 | I135: 0 | J135: 0 | K135: 0 | L135: 0 | M135: 0 | N135: 0 | O135: 0 | P135: 0 | Q135: 0 | R135: 0 | S135: 0 | T135: 0 | U135: 0 | V135: 09/17/2026 @ 7:20 AM
A136: 06.00.00-06.11.30 | C136: Assigned Not Recd N | D136: 0 | E136: 0 | F136: 0 | G136: 0 | H136: 1 | I136: 0 | J136: 0 | K136: 1 | L136: 0 | M136: 0 | N136: 0 | O136: 0 | P136: 1 | Q136: 0 | R136: 0 | S136: 1 | T136: 0 | U136: 1 | V136: 09/17/2026 @ 7:20 AM
A137: 06.00.00-06.11.30 | C137: Reserved Not Recd N | D137: 0 | E137: 0 | F137: 0 | G137: 0 | H137: 0 | I137: 0 | J137: 0 | K137: 0 | L137: 0 | M137: 0 | N137: 0 | O137: 0 | P137: 0 | Q137: 0 | R137: 0 | S137: 0 | T137: 0 | U137: 0 | V137: 09/17/2026 @ 7:20 AM
A138: 06.00.00-06.11.30 | C138: Total Assignments | D138: 0 | E138: 0 | F138: 0 | G138: 0 | H138: 1 | I138: 0 | J138: 0 | K138: 1 | L138: 0 | M138: 0 | N138: 0 | O138: 0 | P138: 1 | Q138: 0 | R138: 0 | S138: 1 | T138: 0 | U138: 1 | V138: 09/17/2026 @ 7:20 AM
A139: 06.00.00-06.11.30 | C139: Selected N | D139: 0 | E139: 0 | F139: 0 | G139: 0 | H139: 0 | I139: 0 | J139: 0 | K139: 0 | L139: 0 | M139: 0 | N139: 0 | O139: 0 | P139: 0 | Q139: 0 | R139: 0 | S139: 0 | T139: 0 | U139: 0 | V139: 09/17/2026 @ 7:20 AM
A140: 07.00.00-07.11.30 | C140: Target N | D140: 0 | E140: 0 | F140: 0 | G140: 0 | H140: 0 | I140: 0 | J140: 0 | K140: 0 | L140: 0 | M140: 0 | N140: 0 | O140: 0 | P140: 0 | Q140: 0 | R140: 0 | S140: 0 | T140: 0 | U140: 1 | V140: 09/17/2026 @ 7:20 AM
A141: 07.00.00-07.11.30 | C141: Stratified Usable N | D141: 0 | E141: 0 | F141: 0 | G141: 0 | H141: 0 | I141: 0 | J141: 0 | K141: 0 | L141: 0 | M141: 0 | N141: 0 | O141: 0 | P141: 0 | Q141: 0 | R141: 0 | S141: 0 | T141: 0 | U141: 0 | V141: 09/17/2026 @ 7:20 AM
A142: 07.00.00-07.11.30 | C142: Stratified Out Usable N | D142: 0 | E142: 0 | F142: 0 | G142: 0 | H142: 0 | I142: 0 | J142: 0 | K142: 0 | L142: 0 | M142: 0 | N142: 0 | O142: 0 | P142: 0 | Q142: 0 | R142: 0 | S142: 0 | T142: 0 | U142: 0 | V142: 09/17/2026 @ 7:20 AM
A143: 07.00.00-07.11.30 | C143: In Process N | D143: 0 | E143: 0 | F143: 0 | G143: 0 | H143: 0 | I143: 0 | J143: 0 | K143: 0 | L143: 0 | M143: 0 | N143: 0 | O143: 0 | P143: 0 | Q143: 0 | R143: 0 | S143: 0 | T143: 0 | U143: 0 | V143: 09/17/2026 @ 7:20 AM
... A227: Total | C227: Selected N | D227: 0 | E227: 0 | F227: 0 | G227: 0 | H227: 0 | I227: 0 | J227: 0 | K227: 0 | L227: 0 | M227: 0 | N227: 0 | O227: 0 | P227: 0 | Q227: 0 | R227: 0 | S227: 0 | T227: 0 | U227: 0 | V227: 09/17/2026 @ 7:20 AM
A229: =setup!C18 -> 3818
A230: =_xlfn.CONCAT(setup!D18," - ",setup!E18) -> OSEP – Developmental Delay - Paper - OSEP_DD_P
A231: ageband | B231: gradeband | C231: report | D231: 1 | E231: 2 | F231: 3 | G231: 4 | H231: 5 | I231: AS | J231: BL | K231: HI | L231: OT | M231: WH | N231: MW | O231: NE | P231: SO | Q231: WE | R231: F | S231: M | T231: OTHER | U231: Total | V231: LastRefreshed
A232: 06.00.00-06.11.30 | C232: Target N | D232: 0 | E232: 0 | F232: 0 | G232: 0 | H232: 0 | I232: 0 | J232: 0 | K232: 0 | L232: 0 | M232: 0 | N232: 0 | O232: 0 | P232: 0 | Q232: 0 | R232: 0 | S232: 0 | T232: 0 | U232: 7 | V232: 09/17/2026 @ 7:20 AM
A233: 06.00.00-06.11.30 | C233: Stratified Usable N | D233: 0 | E233: 0 | F233: 0 | G233: 0 | H233: 0 | I233: 0 | J233: 0 | K233: 0 | L233: 0 | M233: 0 | N233: 0 | O233: 0 | P233: 0 | Q233: 0 | R233: 0 | S233: 0 | T233: 0 | U233: 0 | V233: 09/17/2026 @ 7:20 AM
A234: 06.00.00-06.11.30 | C234: Stratified Out Usable N | D234: 0 | E234: 0 | F234: 0 | G234: 0 | H234: 0 | I234: 0 | J234: 0 | K234: 0 | L234: 0 | M234: 0 | N234: 0 | O234: 0 | P234: 0 | Q234: 0 | R234: 0 | S234: 0 | T234: 0 | U234: 0 | V234: 09/17/2026 @ 7:20 AM
A235: 06.00.00-06.11.30 | C235: In Process N | D235: 0 | E235: 0 | F235: 0 | G235: 0 | H235: 0 | I235: 0 | J235: 0 | K235: 0 | L235: 0 | M235: 0 | N235: 0 | O235: 0 | P235: 0 | Q235: 0 | R235: 0 | S235: 0 | T235: 0 | U235: 0 | V235: 09/17/2026 @ 7:20 AM
A236: 06.00.00-06.11.30 | C236: Assigned Not Recd N | D236: 0 | E236: 0 | F236: 0 | G236: 0 | H236: 0 | I236: 0 | J236: 0 | K236: 0 | L236: 0 | M236: 0 | N236: 0 | O236: 0 | P236: 0 | Q236: 0 | R236: 0 | S236: 0 | T236: 0 | U236: 0 | V236: 09/17/2026 @ 7:20 AM
...

Sheet Summary
A1: =_xlfn.CONCAT("Last Refreshed at: ",F3) -> Last Refreshed at: 09/17/2026 @ 7:20 AM | H1: Assignment Information | L1: Total usable from all tabs | P1: Tptal in-Process
A2: study_id | B2: study | C2: Target | D2: usableCount | E2: Percentage | F2: Refreshed_Date | H2: Total Assigned | I2: Percentage | L2: =SUM(OSEP_AUT_P!W101,OSEP_AUT_D!W101,OSEP_DD_P!W45,OSEP_DD_D!W45,OSEP_ED_P!W101,OSEP_ED_D!W21,OSEP_MD_P!W21,OSEP_MD_D!W21,OSEP_OI_P!W21,OSEP_OI_D!W21,OSEP_OHI_P!W101,OSEP_OHI_D!W101,OSEP_SLD_P!W101,OSEP_SLD_D!W101,OSEP_SI_P!W101,OSEP_SI_D!W101,OSEP_TBI_P!W21,OSEP_TBI_D!W21,OSEP_ADHD_P!W101,OSEP_ADHD_D!W101) -> 165 | M2: =SUM(#REF!,#REF!,#REF!,#REF!,#REF!,#REF!,#REF!,#REF!,#REF!,#REF!,#REF!,#REF!,#REF!,#REF!,#REF!,#REF!,#REF!,#REF!,#REF!) -> #REF! | P2: =SUM(#REF!,#REF!,#REF!) -> #REF!
A3: 3817 | B3: OSEP – Autism - Paper | C3: 44 | D3: 17 | E3: 0.38636364 | F3: 09/17/2026 @ 7:20 AM | H3: =setup!F16 -> 22 | I3: =IFERROR(H3/C3,0) -> 0.5
A4: 3829 | B4: OSEP – Autism - Digital | C4: 11 | D4: 3 | E4: 0.27272727 | F4: 09/17/2026 @ 7:20 AM | H4: =setup!F17 -> 6 | I4: =IFERROR(H4/C4,0) -> 0.54545455
A5: 3818 | B5: OSEP – Developmental Delay - Paper | C5: 22 | D5: 1 | E5: 0.045454545 | F5: 09/17/2026 @ 7:20 AM | H5: =setup!F18 -> 1 | I5: =IFERROR(H5/C5,0) -> 0.045454545
A6: 3830 | B6: OSEP – Developmental Delay - Digital | C6: 6 | F6: 09/17/2026 @ 7:20 AM | H6: =setup!F19 -> 0 | I6: =IFERROR(H6/C6,0) -> 0
A7: 3819 | B7: OSEP – Emotional Disturbance - Paper | C7: 15 | F7: 09/17/2026 @ 7:20 AM | H7: =setup!F20 -> 0 | I7: =IFERROR(H7/C7,0) -> 0
A8: 3831 | B8: OSEP – Emotional Disturbance - Digital | C8: 4 | F8: 09/17/2026 @ 7:20 AM | H8: =setup!F21 -> 0 | I8: =IFERROR(H8/C8,0) -> 0
A9: 3820 | B9: OSEP – Multiple Disabilities - Paper | C9: 7 | D9: 1 | E9: 0.14285714 | F9: 09/17/2026 @ 7:20 AM | H9: =setup!F22 -> 1 | I9: =IFERROR(H9/C9,0) -> 0.14285714
A10: 3832 | B10: OSEP – Multiple Disabilities - Digital | C10: 2 | F10: 09/17/2026 @ 7:20 AM | H10: =setup!F23 -> 0 | I10: =IFERROR(H10/C10,0) -> 0
A11: 3821 | B11: OSEP – Orthopedic Impairment - Paper | C11: 2 | D11: 2 | E11: 1 | F11: 09/17/2026 @ 7:20 AM | H11: =setup!F24 -> 2 | I11: =IFERROR(H11/C11,0) -> 1
A12: 3833 | B12: OSEP – Orthopedic Impairment - Digital | C12: 1 | F12: 09/17/2026 @ 7:20 AM | H12: =setup!F25 -> 0 | I12: =IFERROR(H12/C12,0) -> 0
A13: 3822 | B13: OSEP – Other Health Impairment - Paper | C13: 51 | F13: 09/17/2026 @ 7:20 AM | H13: =setup!F26 -> 0 | I13: =IFERROR(H13/C13,0) -> 0
A14: 3834 | B14: OSEP – Other Health Impairment - Digital | C14: 13 | F14: 09/17/2026 @ 7:20 AM | H14: =setup!F27 -> 0 | I14: =IFERROR(H14/C14,0) -> 0
A15: 3823 | B15: OSEP – Specific Learning Disability - Paper | C15: 108 | D15: 16 | E15: 0.14814815 | F15: 09/17/2026 @ 7:20 AM | H15: =setup!F28 -> 19 | I15: =IFERROR(H15/C15,0) -> 0.17592593
A16: 3835 | B16: OSEP – Specific Learning Disability - Digital | C16: 27 | D16: 1 | E16: 0.037037037 | F16: 09/17/2026 @ 7:20 AM | H16: =setup!F29 -> 1 | I16: =IFERROR(H16/C16,0) -> 0.037037037
A17: 3824 | B17: OSEP – Speech Impairment - Paper | C17: 64 | D17: 4 | E17: 0.0625 | F17: 09/17/2026 @ 7:20 AM | H17: =setup!F30 -> 4 | I17: =IFERROR(H17/C17,0) -> 0.0625
A18: 3836 | B18: OSEP – Speech Impairment - Digital | C18: 16 | F18: 09/17/2026 @ 7:20 AM | H18: =setup!F31 -> 0 | I18: =IFERROR(H18/C18,0) -> 0
A19: 3825 | B19: OSEP – Traumatic Brain Injury - Paper | C19: 2 | F19: 09/17/2026 @ 7:20 AM | H19: =setup!F32 -> 0 | I19: =IFERROR(H19/C19,0) -> 0
A20: 3837 | B20: OSEP – Traumatic Brain Injury - Digital | C20: 1 | F20: 09/17/2026 @ 7:20 AM | H20: =setup!F33 -> 0 | I20: =IFERROR(H20/C20,0) -> 0
A21: 3827 | B21: OSEP – ADHD - Paper | C21: 216 | D21: 105 | E21: 0.48611111 | F21: 09/17/2026 @ 7:20 AM | H21: =setup!F34 -> 117 | I21: =IFERROR(H21/C21,0) -> 0.54166667
A22: 3838 | B22: OSEP – ADHD - Digital | C22: 54 | D22: 15 | E22: 0.27777778 | F22: 09/17/2026 @ 7:20 AM | H22: =setup!F35 -> 19 | I22: =IFERROR(H22/C22,0) -> 0.35185185
A23: All | B23: Total | C23: 666 | D23: 165 | E23: 0.24774775 | F23: 09/17/2026 @ 7:20 AM | H23: =SUM(H3:H22) -> 192 | I23: =IFERROR(H23/C23,0) -> 0.28828829

Sheet OSEP_AUT_P
A1: Total Assigments below Target | D1: Study Information | N1: Additional Information
A2: Usable greater/equal to target | D2: =_xlfn.CONCAT("Study Name: "," OSEP – Autism - Paper") -> Study Name: OSEP – Autism - Paper | K2: Usable = case is available to Psychometrics for this study In Process = questionable, In Process Assigned Not Recd = Tests assigned to examiners, no tests received (required tests) Reserved not Received = Tests in reserved status, not received Total Assignments = sum of Usable, Received Non Final, Assigned Partial Received, Assigned Not Received Selected = default status for making an assignment
D3: =_xlfn.CONCAT("Study Acronym: "," OSEP_AUT_P") -> Study Acronym: OSEP_AUT_P | F3: Study ID: 3817
D5: Additional Requirements
D6: None
B8: =_xlfn.CONCAT("Last Refreshed at: ",aurora_data!V4) -> Last Refreshed at: 09/17/2026 @ 7:20 AM | E8: Demographic Variables | W8: Totals
D9: Variance Tolerance: | E9: some of each, if possible | J9: some of each, if possible | O9: some of each, if possible | S9: some of each, if possible
B10: Status | E10: Education Level | J10: Ethnicity | O10: Region | S10: SEX
C11: ageband | D11: report | E11: 1 | F11: 2 | G11: 3 | H11: 4 | I11: 5 | J11: AS | K11: BL | L11: HI | M11: OTH | N11: WH | O11: MW | P11: NE | Q11: SO | R11: WE | S11: F | T11: M | U11: INT
B12: Open | C12: =aurora_data!A4 -> 06.00.00-06.11.30 | D12: Target | E12: =IFERROR(aurora_data!D4,0) -> 0 | F12: =IFERROR(aurora_data!E4,0) -> 0 | G12: =IFERROR(aurora_data!F4,0) -> 0 | H12: =IFERROR(aurora_data!G4,0) -> 0 | I12: =IFERROR(aurora_data!H4,0) -> 0 | J12: =IFERROR(aurora_data!I4,0) -> 0 | K12: =IFERROR(aurora_data!J4,0) -> 0 | L12: =IFERROR(aurora_data!K4,0) -> 0 | ... U12: =IFERROR(aurora_data!T4,0) -> 0 | W12: =IFERROR(aurora_data!U4,0) -> 4 | X12: =IFERROR(W12/$W$12,0) -> 1
D13: Usable | E13: =IFERROR(aurora_data!D5,0) -> 0 | F13: =IFERROR(aurora_data!E5,0) -> 0 | G13: =IFERROR(aurora_data!F5,0) -> 0 | H13: =IFERROR(aurora_data!G5,0) -> 3 | I13: =IFERROR(aurora_data!H5,0) -> 1 | J13: =IFERROR(aurora_data!I5,0) -> 1 | K13: =IFERROR(aurora_data!J5,0) -> 0 | L13: =IFERROR(aurora_data!K5,0) -> 3 | ... U13: =IFERROR(aurora_data!T5,0) -> 0 | W13: =IFERROR(aurora_data!U5,0) -> 4 | X13: =IFERROR(W13/$W$12,0) -> 1
D14: Stratified Out Usable N | E14: =IFERROR(aurora_data!D6,0) -> 0 | F14: =IFERROR(aurora_data!E6,0) -> 0 | G14: =IFERROR(aurora_data!F6,0) -> 0 | H14: =IFERROR(aurora_data!G6,0) -> 0 | I14: =IFERROR(aurora_data!H6,0) -> 0 | J14: =IFERROR(aurora_data!I6,0) -> 0 | K14: =IFERROR(aurora_data!J6,0) -> 0 | L14: =IFERROR(aurora_data!K6,0) -> 0 | ... U14: =IFERROR(aurora_data!T6,0) -> 0 | W14: =IFERROR(aurora_data!U6,0) -> 0 | X14: =IFERROR(W14/$W$12,0) -> 0
D15: In Process | E15: =IFERROR(aurora_data!D7,0) -> 0 | F15: =IFERROR(aurora_data!E7,0) -> 0 | G15: =IFERROR(aurora_data!F7,0) -> 0 | H15: =IFERROR(aurora_data!G7,0) -> 0 | I15: =IFERROR(aurora_data!H7,0) -> 0 | J15: =IFERROR(aurora_data!I7,0) -> 0 | K15: =IFERROR(aurora_data!J7,0) -> 0 | L15: =IFERROR(aurora_data!K7,0) -> 0 | ... U15: =IFERROR(aurora_data!T7,0) -> 0 | W15: =IFERROR(aurora_data!U7,0) -> 0 | X15: =IFERROR(W15/$W$12,0) -> 0
D16: Assigned Not Received | E16: =IFERROR(aurora_data!D8,0) -> 0 | F16: =IFERROR(aurora_data!E8,0) -> 0 | G16: =IFERROR(aurora_data!F8,0) -> 0 | H16: =IFERROR(aurora_data!G8,0) -> 0 | I16: =IFERROR(aurora_data!H8,0) -> 0 | J16: =IFERROR(aurora_data!I8,0) -> 0 | K16: =IFERROR(aurora_data!J8,0) -> 0 | L16: =IFERROR(aurora_data!K8,0) -> 0 | ... U16: =IFERROR(aurora_data!T8,0) -> 0 | W16: =IFERROR(aurora_data!U8,0) -> 0 | X16: =IFERROR(W16/$W$12,0) -> 0
D17: Reserved Not Received | E17: =IFERROR(aurora_data!D9,0) -> 0 | F17: =IFERROR(aurora_data!E9,0) -> 0 | G17: =IFERROR(aurora_data!F9,0) -> 0 | H17: =IFERROR(aurora_data!G9,0) -> 0 | I17: =IFERROR(aurora_data!H9,0) -> 0 | J17: =IFERROR(aurora_data!I9,0) -> 0 | K17: =IFERROR(aurora_data!J9,0) -> 0 | L17: =IFERROR(aurora_data!K9,0) -> 0 | ... U17: =IFERROR(aurora_data!T9,0) -> 0 | W17: =IFERROR(aurora_data!U9,0) -> 0 | X17: =IFERROR(W17/$W$12,0) -> 0
D18: Total Assignments | E18: =IFERROR(aurora_data!D10,0) -> 0 | F18: =IFERROR(aurora_data!E10,0) -> 0 | G18: =IFERROR(aurora_data!F10,0) -> 0 | H18: =IFERROR(aurora_data!G10,0) -> 3 | I18: =IFERROR(aurora_data!H10,0) -> 1 | J18: =IFERROR(aurora_data!I10,0) -> 1 | K18: =IFERROR(aurora_data!J10,0) -> 0 | L18: =IFERROR(aurora_data!K10,0) -> 3 | ... U18: =IFERROR(aurora_data!T10,0) -> 0 | W18: =IFERROR(aurora_data!U10,0) -> 4 | X18: =IFERROR(W18/$W$12,0) -> 1
D19: Selected | E19: =IFERROR(aurora_data!D11,0) -> 0 | F19: =IFERROR(aurora_data!E11,0) -> 0 | G19: =IFERROR(aurora_data!F11,0) -> 0 | H19: =IFERROR(aurora_data!G11,0) -> 1 | I19: =IFERROR(aurora_data!H11,0) -> 0 | J19: =IFERROR(aurora_data!I11,0) -> 0 | K19: =IFERROR(aurora_data!J11,0) -> 0 | L19: =IFERROR(aurora_data!K11,0) -> 0 | ... U19: =IFERROR(aurora_data!T11,0) -> 0 | W19: =IFERROR(aurora_data!U11,0) -> 1 | X19: =IFERROR(W19/$W$12,0) -> 0.25
B20: Open | C20: =aurora_data!A12 -> 07.00.00-07.11.30 | D20: Target | E20: =IFERROR(aurora_data!D12,0) -> 0 | F20: =IFERROR(aurora_data!E12,0) -> 0 | G20: =IFERROR(aurora_data!F12,0) -> 0 | H20: =IFERROR(aurora_data!G12,0) -> 0 | I20: =IFERROR(aurora_data!H12,0) -> 0 | J20: =IFERROR(aurora_data!I12,0) -> 0 | K20: =IFERROR(aurora_data!J12,0) -> 0 | L20: =IFERROR(aurora_data!K12,0) -> 0 | ... U20: =IFERROR(aurora_data!T12,0) -> 0 | W20: =IFERROR(aurora_data!U12,0) -> 4 | X20: =IFERROR(W20/$W$12,0) -> 1
D21: Usable | E21: =IFERROR(aurora_data!D13,0) -> 0 | F21: =IFERROR(aurora_data!E13,0) -> 1 | G21: =IFERROR(aurora_data!F13,0) -> 1 | H21: =IFERROR(aurora_data!G13,0) -> 1 | I21: =IFERROR(aurora_data!H13,0) -> 0 | J21: =IFERROR(aurora_data!I13,0) -> 0 | K21: =IFERROR(aurora_data!J13,0) -> 0 | L21: =IFERROR(aurora_data!K13,0) -> 2 | ... U21: =IFERROR(aurora_data!T13,0) -> 0 | W21: =IFERROR(aurora_data!U13,0) -> 3 | X21: =IFERROR(W21/$W$12,0) -> 0.75
D22: Stratified Out Usable N | E22: =IFERROR(aurora_data!D14,0) -> 0 | F22: =IFERROR(aurora_data!E14,0) -> 0 | G22: =IFERROR(aurora_data!F14,0) -> 0 | H22: =IFERROR(aurora_data!G14,0) -> 0 | I22: =IFERROR(aurora_data!H14,0) -> 0 | J22: =IFERROR(aurora_data!I14,0) -> 0 | K22: =IFERROR(aurora_data!J14,0) -> 0 | L22: =IFERROR(aurora_data!K14,0) -> 0 | ... U22: =IFERROR(aurora_data!T14,0) -> 0 | W22: =IFERROR(aurora_data!U14,0) -> 0 | X22: =IFERROR(W22/$W$12,0) -> 0
D23: In Process | E23: =IFERROR(aurora_data!D15,0) -> 0 | F23: =IFERROR(aurora_data!E15,0) -> 0 | G23: =IFERROR(aurora_data!F15,0) -> 0 | H23: =IFERROR(aurora_data!G15,0) -> 0 | I23: =IFERROR(aurora_data!H15,0) -> 0 | J23: =IFERROR(aurora_data!I15,0) -> 0 | K23: =IFERROR(aurora_data!J15,0) -> 0 | L23: =IFERROR(aurora_data!K15,0) -> 0 | ... U23: =IFERROR(aurora_data!T15,0) -> 0 | W23: =IFERROR(aurora_data!U15,0) -> 0 | X23: =IFERROR(W23/$W$12,0) -> 0
D24: Assigned Not Received | E24: =IFERROR(aurora_data!D16,0) -> 0 | F24: =IFERROR(aurora_data!E16,0) -> 0 | G24: =IFERROR(aurora_data!F16,0) -> 1 | H24: =IFERROR(aurora_data!G16,0) -> 0 | I24: =IFERROR(aurora_data!H16,0) -> 0 | J24: =IFERROR(aurora_data!I16,0) -> 0 | K24: =IFERROR(aurora_data!J16,0) -> 0 | L24: =IFERROR(aurora_data!K16,0) -> 1 | ... U24: =IFERROR(aurora_data!T16,0) -> 0 | W24: =IFERROR(aurora_data!U16,0) -> 1 | X24: =IFERROR(W24/$W$12,0) -> 0.25
D25: Reserved Not Received | E25: =IFERROR(aurora_data!D17,0) -> 0 | F25: =IFERROR(aurora_data!E17,0) -> 0 | G25: =IFERROR(aurora_data!F17,0) -> 0 | H25: =IFERROR(aurora_data!G17,0) -> 0 | I25: =IFERROR(aurora_data!H17,0) -> 0 | J25: =IFERROR(aurora_data!I17,0) -> 0 | K25: =IFERROR(aurora_data!J17,0) -> 0 | L25: =IFERROR(aurora_data!K17,0) -> 0 | ... U25: =IFERROR(aurora_data!T17,0) -> 0 | W25: =IFERROR(aurora_data!U17,0) -> 0 | X25: =IFERROR(W25/$W$12,0) -> 0
D26: Total Assignments | E26: =IFERROR(aurora_data!D18,0) -> 0 | F26: =IFERROR(aurora_data!E18,0) -> 1 | G26: =IFERROR(aurora_data!F18,0) -> 2 | H26: =IFERROR(aurora_data!G18,0) -> 1 | I26: =IFERROR(aurora_data!H18,0) -> 0 | J26: =IFERROR(aurora_data!I18,0) -> 0 | K26: =IFERROR(aurora_data!J18,0) -> 0 | L26: =IFERROR(aurora_data!K18,0) -> 3 | ... U26: =IFERROR(aurora_data!T18,0) -> 0 | W26: =IFERROR(aurora_data!U18,0) -> 4 | X26: =IFERROR(W26/$W$12,0) -> 1
D27: Selected | E27: =IFERROR(aurora_data!D19,0) -> 0 | F27: =IFERROR(aurora_data!E19,0) -> 0 | G27: =IFERROR(aurora_data!F19,0) -> 0 | H27: =IFERROR(aurora_data!G19,0) -> 0 | I27: =IFERROR(aurora_data!H19,0) -> 0 | J27: =IFERROR(aurora_data!I19,0) -> 0 | K27: =IFERROR(aurora_data!J19,0) -> 0 | L27: =IFERROR(aurora_data!K19,0) -> 0 | ... U27: =IFERROR(aurora_data!T19,0) -> 0 | W27: =IFERROR(aurora_data!U19,0) -> 0 | X27: =IFERROR(W27/$W$12,0) -> 0
B28: Open | C28: =aurora_data!A20 -> 08.00.00-08.11.30 | D28: Target | E28: =IFERROR(aurora_data!D20,0) -> 0 | F28: =IFERROR(aurora_data!E20,0) -> 0 | G28: =IFERROR(aurora_data!F20,0) -> 0 | H28: =IFERROR(aurora_data!G20,0) -> 0 | I28: =IFERROR(aurora_data!H20,0) -> 0 | J28: =IFERROR(aurora_data!I20,0) -> 0 | K28: =IFERROR(aurora_data!J20,0) -> 0 | L28: =IFERROR(aurora_data!K20,0) -> 0 | ... U28: =IFERROR(aurora_data!T20,0) -> 0 | W28: =IFERROR(aurora_data!U20,0) -> 4 | X28: =IFERROR(W28/$W$12,0) -> 1
D29: Usable | E29: =IFERROR(aurora_data!D21,0) -> 0 | F29: =IFERROR(aurora_data!E21,0) -> 0 | G29: =IFERROR(aurora_data!F21,0) -> 1 | H29: =IFERROR(aurora_data!G21,0) -> 0 | I29: =IFERROR(aurora_data!H21,0) -> 0 | J29: =IFERROR(aurora_data!I21,0) -> 0 | K29: =IFERROR(aurora_data!J21,0) -> 0 | L29: =IFERROR(aurora_data!K21,0) -> 0 | ... U29: =IFERROR(aurora_data!T21,0) -> 0 | W29: =IFERROR(aurora_data!U21,0) -> 1 | X29: =IFERROR(W29/$W$12,0) -> 0.25
D30: Stratified Out Usable N | E30: =IFERROR(aurora_data!D22,0) -> 0 | F30: =IFERROR(aurora_data!E22,0) -> 0 | G30: =IFERROR(aurora_data!F22,0) -> 0 | H30: =IFERROR(aurora_data!G22,0) -> 0 | I30: =IFERROR(aurora_data!H22,0) -> 0 | J30: =IFERROR(aurora_data!I22,0) -> 0 | K30: =IFERROR(aurora_data!J22,0) -> 0 | L30: =IFERROR(aurora_data!K22,0) -> 0 | ... U30: =IFERROR(aurora_data!T22,0) -> 0 | W30: =IFERROR(aurora_data!U22,0) -> 0 | X30: =IFERROR(W30/$W$12,0) -> 0
D31: In Process | E31: =IFERROR(aurora_data!D23,0) -> 0 | F31: =IFERROR(aurora_data!E23,0) -> 0 | G31: =IFERROR(aurora_data!F23,0) -> 0 | H31: =IFERROR(aurora_data!G23,0) -> 0 | I31: =IFERROR(aurora_data!H23,0) -> 0 | J31: =IFERROR(aurora_data!I23,0) -> 0 | K31: =IFERROR(aurora_data!J23,0) -> 0 | L31: =IFERROR(aurora_data!K23,0) -> 0 | ... U31: =IFERROR(aurora_data!T23,0) -> 0 | W31: =IFERROR(aurora_data!U23,0) -> 0 | X31: =IFERROR(W31/$W$12,0) -> 0
D32: Assigned Not Received | E32: =IFERROR(aurora_data!D24,0) -> 0 | F32: =IFERROR(aurora_data!E24,0) -> 1 | G32: =IFERROR(aurora_data!F24,0) -> 0 | H32: =IFERROR(aurora_data!G24,0) -> 0 | I32: =IFERROR(aurora_data!H24,0) -> 0 | J32: =IFERROR(aurora_data!I24,0) -> 1 | K32: =IFERROR(aurora_data!J24,0) -> 0 | L32: =IFERROR(aurora_data!K24,0) -> 0 | ... U32: =IFERROR(aurora_data!T24,0) -> 0 | W32: =IFERROR(aurora_data!U24,0) -> 1 | X32: =IFERROR(W32/$W$12,0) -> 0.25
D33: Reserved Not Received | E33: =IFERROR(aurora_data!D25,0) -> 0 | F33: =IFERROR(aurora_data!E25,0) -> 0 | G33: =IFERROR(aurora_data!F25,0) -> 0 | H33: =IFERROR(aurora_data!G25,0) -> 0 | I33: =IFERROR(aurora_data!H25,0) -> 0 | J33: =IFERROR(aurora_data!I25,0) -> 0 | K33: =IFERROR(aurora_data!J25,0) -> 0 | L33: =IFERROR(aurora_data!K25,0) -> 0 | ... U33: =IFERROR(aurora_data!T25,0) -> 0 | W33: =IFERROR(aurora_data!U25,0) -> 0 | X33: =IFERROR(W33/$W$12,0) -> 0
D34: Total Assignments | E34: =IFERROR(aurora_data!D26,0) -> 0 | F34: =IFERROR(aurora_data!E26,0) -> 1 | G34: =IFERROR(aurora_data!F26,0) -> 1 | H34: =IFERROR(aurora_data!G26,0) -> 0 | I34: =IFERROR(aurora_data!H26,0) -> 0 | J34: =IFERROR(aurora_data!I26,0) -> 1 | K34: =IFERROR(aurora_data!J26,0) -> 0 | L34: =IFERROR(aurora_data!K26,0) -> 0 | ... U34: =IFERROR(aurora_data!T26,0) -> 0 | W34: =IFERROR(aurora_data!U26,0) -> 2 | X34: =IFERROR(W34/$W$12,0) -> 0.5
D35: Selected | E35: =IFERROR(aurora_data!D27,0) -> 0 | F35: =IFERROR(aurora_data!E27,0) -> 0 | G35: =IFERROR(aurora_data!F27,0) -> 0 | H35: =IFERROR(aurora_data!G27,0) -> 0 | I35: =IFERROR(aurora_data!H27,0) -> 0 | J35: =IFERROR(aurora_data!I27,0) -> 0 | K35: =IFERROR(aurora_data!J27,0) -> 0 | L35: =IFERROR(aurora_data!K27,0) -> 0 | ... U35: =IFERROR(aurora_data!T27,0) -> 0 | W35: =IFERROR(aurora_data!U27,0) -> 0 | X35: =IFERROR(W35/$W$12,0) -> 0
B36: Open | C36: =aurora_data!A28 -> 09.00.00-09.11.30 | D36: Target | E36: =IFERROR(aurora_data!D28,0) -> 0 | F36: =IFERROR(aurora_data!E28,0) -> 0 | G36: =IFERROR(aurora_data!F28,0) -> 0 | H36: =IFERROR(aurora_data!G28,0) -> 0 | I36: =IFERROR(aurora_data!H28,0) -> 0 | J36: =IFERROR(aurora_data!I28,0) -> 0 | K36: =IFERROR(aurora_data!J28,0) -> 0 | L36: =IFERROR(aurora_data!K28,0) -> 0 | ... U36: =IFERROR(aurora_data!T28,0) -> 0 | W36: =IFERROR(aurora_data!U28,0) -> 4 | X36: =IFERROR(W36/$W$12,0) -> 1
D37: Usable | E37: =IFERROR(aurora_data!D29,0) -> 0 | F37: =IFERROR(aurora_data!E29,0) -> 1 | G37: =IFERROR(aurora_data!F29,0) -> 0 | H37: =IFERROR(aurora_data!G29,0) -> 0 | I37: =IFERROR(aurora_data!H29,0) -> 0 | J37: =IFERROR(aurora_data!I29,0) -> 0 | K37: =IFERROR(aurora_data!J29,0) -> 1 | L37: =IFERROR(aurora_data!K29,0) -> 0 | ... U37: =IFERROR(aurora_data!T29,0) -> 0 | W37: =IFERROR(aurora_data!U29,0) -> 1 | X37: =IFERROR(W37/$W$12,0) -> 0.25
D38: Stratified Out Usable N | E38: =IFERROR(aurora_data!D30,0) -> 0 | F38: =IFERROR(aurora_data!E30,0) -> 0 | G38: =IFERROR(aurora_data!F30,0) -> 0 | H38: =IFERROR(aurora_data!G30,0) -> 0 | I38: =IFERROR(aurora_data!H30,0) -> 0 | J38: =IFERROR(aurora_data!I30,0) -> 0 | K38: =IFERROR(aurora_data!J30,0) -> 0 | L38: =IFERROR(aurora_data!K30,0) -> 0 | ... U38: =IFERROR(aurora_data!T30,0) -> 0 | W38: =IFERROR(aurora_data!U30,0) -> 0 | X38: =IFERROR(W38/$W$12,0) -> 0
D39: In Process | E39: =IFERROR(aurora_data!D31,0) -> 0 | F39: =IFERROR(aurora_data!E31,0) -> 0 | G39: =IFERROR(aurora_data!F31,0) -> 0 | H39: =IFERROR(aurora_data!G31,0) -> 0 | I39: =IFERROR(aurora_data!H31,0) -> 0 | J39: =IFERROR(aurora_data!I31,0) -> 0 | K39: =IFERROR(aurora_data!J31,0) -> 0 | L39: =IFERROR(aurora_data!K31,0) -> 0 | ... U39: =IFERROR(aurora_data!T31,0) -> 0 | W39: =IFERROR(aurora_data!U31,0) -> 0 | X39: =IFERROR(W39/$W$12,0) -> 0
D40: Assigned Not Received | E40: =IFERROR(aurora_data!D32,0) -> 0 | F40: =IFERROR(aurora_data!E32,0) -> 0 | G40: =IFERROR(aurora_data!F32,0) -> 0 | H40: =IFERROR(aurora_data!G32,0) -> 0 | I40: =IFERROR(aurora_data!H32,0) -> 0 | J40: =IFERROR(aurora_data!I32,0) -> 0 | K40: =IFERROR(aurora_data!J32,0) -> 0 | L40: =IFERROR(aurora_data!K32,0) -> 0 | ... U40: =IFERROR(aurora_data!T32,0) -> 0 | W40: =IFERROR(aurora_data!U32,0) -> 0 | X40: =IFERROR(W40/$W$12,0) -> 0
D41: Reserved Not Received | E41: =IFERROR(aurora_data!D33,0) -> 0 | F41: =IFERROR(aurora_data!E33,0) -> 0 | G41: =IFERROR(aurora_data!F33,0) -> 0 | H41: =IFERROR(aurora_data!G33,0) -> 0 | I41: =IFERROR(aurora_data!H33,0) -> 0 | J41: =IFERROR(aurora_data!I33,0) -> 0 | K41: =IFERROR(aurora_data!J33,0) -> 0 | L41: =IFERROR(aurora_data!K33,0) -> 0 | ... U41: =IFERROR(aurora_data!T33,0) -> 0 | W41: =IFERROR(aurora_data!U33,0) -> 0 | X41: =IFERROR(W41/$W$12,0) -> 0
D42: Total Assignments | E42: =IFERROR(aurora_data!D34,0) -> 0 | F42: =IFERROR(aurora_data!E34,0) -> 1 | G42: =IFERROR(aurora_data!F34,0) -> 0 | H42: =IFERROR(aurora_data!G34,0) -> 0 | I42: =IFERROR(aurora_data!H34,0) -> 0 | J42: =IFERROR(aurora_data!I34,0) -> 0 | K42: =IFERROR(aurora_data!J34,0) -> 1 | L42: =IFERROR(aurora_data!K34,0) -> 0 | ... U42: =IFERROR(aurora_data!T34,0) -> 0 | W42: =IFERROR(aurora_data!U34,0) -> 1 | X42: =IFERROR(W42/$W$12,0) -> 0.25
...

Sheet OSEP_AUT_D
A1: Total Assigments below Target | D1: Study Information | N1: Additional Information
A2: Usable greater/equal to target | D2: =_xlfn.CONCAT("Study Name: "," OSEP – Autism - Digital") -> Study Name: OSEP – Autism - Digital | K2: Usable = case is available to Psychometrics for this study In Process = questionable, In Process Assigned Not Recd = Tests assigned to examiners, no tests received (required tests) Reserved not Received = Tests in reserved status, not received Total Assignments = sum of Usable, Received Non Final, Assigned Partial Received, Assigned Not Received Selected = default status for making an assignment
D3: =_xlfn.CONCAT("Study Acronym: "," OSEP_AUT_D") -> Study Acronym: OSEP_AUT_D | F3: Study ID: 3829
D5: Additional Requirements
D6: None
B8: =_xlfn.CONCAT("Last Refreshed at: ",aurora_data!V132) -> Last Refreshed at: 09/17/2026 @ 7:20 AM | E8: Demographic Variables | W8: Totals
D9: Variance Tolerance: | E9: some of each, if possible | J9: some of each, if possible | O9: some of each, if possible | S9: some of each, if possible
B10: Status | E10: Education Level | J10: Ethnicity | O10: Region | S10: SEX
C11: ageband | D11: report | E11: 1 | F11: 2 | G11: 3 | H11: 4 | I11: 5 | J11: AS | K11: BL | L11: HI | M11: OTH | N11: WH | O11: MW | P11: NE | Q11: SO | R11: WE | S11: F | T11: M | U11: INT
B12: Open | C12: =aurora_data!A132 -> 06.00.00-06.11.30 | D12: Target | E12: =IFERROR(aurora_data!D132,0) -> 0 | F12: =IFERROR(aurora_data!E132,0) -> 0 | G12: =IFERROR(aurora_data!F132,0) -> 0 | H12: =IFERROR(aurora_data!G132,0) -> 0 | I12: =IFERROR(aurora_data!H132,0) -> 0 | J12: =IFERROR(aurora_data!I132,0) -> 0 | K12: =IFERROR(aurora_data!J132,0) -> 0 | L12: =IFERROR(aurora_data!K132,0) -> 0 | ... U12: =IFERROR(aurora_data!T132,0) -> 0 | W12: =IFERROR(aurora_data!U132,0) -> 1 | X12: =IFERROR(W12/$W$12,0) -> 1
D13: Usable | E13: =IFERROR(aurora_data!D133,0) -> 0 | F13: =IFERROR(aurora_data!E133,0) -> 0 | G13: =IFERROR(aurora_data!F133,0) -> 0 | H13: =IFERROR(aurora_data!G133,0) -> 0 | I13: =IFERROR(aurora_data!H133,0) -> 0 | J13: =IFERROR(aurora_data!I133,0) -> 0 | K13: =IFERROR(aurora_data!J133,0) -> 0 | L13: =IFERROR(aurora_data!K133,0) -> 0 | ... U13: =IFERROR(aurora_data!T133,0) -> 0 | W13: =IFERROR(aurora_data!U133,0) -> 0 | X13: =IFERROR(W13/$W$12,0) -> 0
D14: Stratified Out Usable N | E14: =IFERROR(aurora_data!D134,0) -> 0 | F14: =IFERROR(aurora_data!E134,0) -> 0 | G14: =IFERROR(aurora_data!F134,0) -> 0 | H14: =IFERROR(aurora_data!G134,0) -> 0 | I14: =IFERROR(aurora_data!H134,0) -> 0 | J14: =IFERROR(aurora_data!I134,0) -> 0 | K14: =IFERROR(aurora_data!J134,0) -> 0 | L14: =IFERROR(aurora_data!K134,0) -> 0 | ... U14: =IFERROR(aurora_data!T134,0) -> 0 | W14: =IFERROR(aurora_data!U134,0) -> 0 | X14: =IFERROR(W14/$W$12,0) -> 0
D15: In Process | E15: =IFERROR(aurora_data!D135,0) -> 0 | F15: =IFERROR(aurora_data!E135,0) -> 0 | G15: =IFERROR(aurora_data!F135,0) -> 0 | H15: =IFERROR(aurora_data!G135,0) -> 0 | I15: =IFERROR(aurora_data!H135,0) -> 0 | J15: =IFERROR(aurora_data!I135,0) -> 0 | K15: =IFERROR(aurora_data!J135,0) -> 0 | L15: =IFERROR(aurora_data!K135,0) -> 0 | ... U15: =IFERROR(aurora_data!T135,0) -> 0 | W15: =IFERROR(aurora_data!U135,0) -> 0 | X15: =IFERROR(W15/$W$12,0) -> 0
D16: Assigned Not Received | E16: =IFERROR(aurora_data!D136,0) -> 0 | F16: =IFERROR(aurora_data!E136,0) -> 0 | G16: =IFERROR(aurora_data!F136,0) -> 0 | H16: =IFERROR(aurora_data!G136,0) -> 0 | I16: =IFERROR(aurora_data!H136,0) -> 1 | J16: =IFERROR(aurora_data!I136,0) -> 0 | K16: =IFERROR(aurora_data!J136,0) -> 0 | L16: =IFERROR(aurora_data!K136,0) -> 1 | ... U16: =IFERROR(aurora_data!T136,0) -> 0 | W16: =IFERROR(aurora_data!U136,0) -> 1 | X16: =IFERROR(W16/$W$12,0) -> 1
D17: Reserved Not Received | E17: =IFERROR(aurora_data!D137,0) -> 0 | F17: =IFERROR(aurora_data!E137,0) -> 0 | G17: =IFERROR(aurora_data!F137,0) -> 0 | H17: =IFERROR(aurora_data!G137,0) -> 0 | I17: =IFERROR(aurora_data!H137,0) -> 0 | J17: =IFERROR(aurora_data!I137,0) -> 0 | K17: =IFERROR(aurora_data!J137,0) -> 0 | L17: =IFERROR(aurora_data!K137,0) -> 0 | ... U17: =IFERROR(aurora_data!T137,0) -> 0 | W17: =IFERROR(aurora_data!U137,0) -> 0 | X17: =IFERROR(W17/$W$12,0) -> 0
D18: Total Assignments | E18: =IFERROR(aurora_data!D138,0) -> 0 | F18: =IFERROR(aurora_data!E138,0) -> 0 | G18: =IFERROR(aurora_data!F138,0) -> 0 | H18: =IFERROR(aurora_data!G138,0) -> 0 | I18: =IFERROR(aurora_data!H138,0) -> 1 | J18: =IFERROR(aurora_data!I138,0) -> 0 | K18: =IFERROR(aurora_data!J138,0) -> 0 | L18: =IFERROR(aurora_data!K138,0) -> 1 | ... U18: =IFERROR(aurora_data!T138,0) -> 0 | W18: =IFERROR(aurora_data!U138,0) -> 1 | X18: =IFERROR(W18/$W$12,0) -> 1
D19: Selected | E19: =IFERROR(aurora_data!D139,0) -> 0 | F19: =IFERROR(aurora_data!E139,0) -> 0 | G19: =IFERROR(aurora_data!F139,0) -> 0 | H19: =IFERROR(aurora_data!G139,0) -> 0 | I19: =IFERROR(aurora_data!H139,0) -> 0 | J19: =IFERROR(aurora_data!I139,0) -> 0 | K19: =IFERROR(aurora_data!J139,0) -> 0 | L19: =IFERROR(aurora_data!K139,0) -> 0 | ... U19: =IFERROR(aurora_data!T139,0) -> 0 | W19: =IFERROR(aurora_data!U139,0) -> 0 | X19: =IFERROR(W19/$W$12,0) -> 0
B20: Open | C20: =aurora_data!A140 -> 07.00.00-07.11.30 | D20: Target | E20: =IFERROR(aurora_data!D140,0) -> 0 | F20: =IFERROR(aurora_data!E140,0) -> 0 | G20: =IFERROR(aurora_data!F140,0) -> 0 | H20: =IFERROR(aurora_data!G140,0) -> 0 | I20: =IFERROR(aurora_data!H140,0) -> 0 | J20: =IFERROR(aurora_data!I140,0) -> 0 | K20: =IFERROR(aurora_data!J140,0) -> 0 | L20: =IFERROR(aurora_data!K140,0) -> 0 | ... U20: =IFERROR(aurora_data!T140,0) -> 0 | W20: =IFERROR(aurora_data!U140,0) -> 1 | X20: =IFERROR(W20/$W$12,0) -> 1
D21: Usable | E21: =IFERROR(aurora_data!D141,0) -> 0 | F21: =IFERROR(aurora_data!E141,0) -> 0 | G21: =IFERROR(aurora_data!F141,0) -> 0 | H21: =IFERROR(aurora_data!G141,0) -> 0 | I21: =IFERROR(aurora_data!H141,0) -> 0 | J21: =IFERROR(aurora_data!I141,0) -> 0 | K21: =IFERROR(aurora_data!J141,0) -> 0 | L21: =IFERROR(aurora_data!K141,0) -> 0 | ... U21: =IFERROR(aurora_data!T141,0) -> 0 | W21: =IFERROR(aurora_data!U141,0) -> 0 | X21: =IFERROR(W21/$W$12,0) -> 0
D22: Stratified Out Usable N | E22: =IFERROR(aurora_data!D142,0) -> 0 | F22: =IFERROR(aurora_data!E142,0) -> 0 | G22: =IFERROR(aurora_data!F142,0) -> 0 | H22: =IFERROR(aurora_data!G142,0) -> 0 | I22: =IFERROR(aurora_data!H142,0) -> 0 | J22: =IFERROR(aurora_data!I142,0) -> 0 | K22: =IFERROR(aurora_data!J142,0) -> 0 | L22: =IFERROR(aurora_data!K142,0) -> 0 | ... U22: =IFERROR(aurora_data!T142,0) -> 0 | W22: =IFERROR(aurora_data!U142,0) -> 0 | X22: =IFERROR(W22/$W$12,0) -> 0
D23: In Process | E23: =IFERROR(aurora_data!D143,0) -> 0 | F23: =IFERROR(aurora_data!E143,0) -> 0 | G23: =IFERROR(aurora_data!F143,0) -> 0 | H23: =IFERROR(aurora_data!G143,0) -> 0 | I23: =IFERROR(aurora_data!H143,0) -> 0 | J23: =IFERROR(aurora_data!I143,0) -> 0 | K23: =IFERROR(aurora_data!J143,0) -> 0 | L23: =IFERROR(aurora_data!K143,0) -> 0 | ... U23: =IFERROR(aurora_data!T143,0) -> 0 | W23: =IFERROR(aurora_data!U143,0) -> 0 | X23: =IFERROR(W23/$W$12,0) -> 0
D24: Assigned Not Received | E24: =IFERROR(aurora_data!D144,0) -> 0 | F24: =IFERROR(aurora_data!E144,0) -> 0 | G24: =IFERROR(aurora_data!F144,0) -> 0 | H24: =IFERROR(aurora_data!G144,0) -> 1 | I24: =IFERROR(aurora_data!H144,0) -> 0 | J24: =IFERROR(aurora_data!I144,0) -> 0 | K24: =IFERROR(aurora_data!J144,0) -> 0 | L24: =IFERROR(aurora_data!K144,0) -> 0 | ... U24: =IFERROR(aurora_data!T144,0) -> 0 | W24: =IFERROR(aurora_data!U144,0) -> 1 | X24: =IFERROR(W24/$W$12,0) -> 1
D25: Reserved Not Received | E25: =IFERROR(aurora_data!D145,0) -> 0 | F25: =IFERROR(aurora_data!E145,0) -> 0 | G25: =IFERROR(aurora_data!F145,0) -> 0 | H25: =IFERROR(aurora_data!G145,0) -> 0 | I25: =IFERROR(aurora_data!H145,0) -> 0 | J25: =IFERROR(aurora_data!I145,0) -> 0 | K25: =IFERROR(aurora_data!J145,0) -> 0 | L25: =IFERROR(aurora_data!K145,0) -> 0 | ... U25: =IFERROR(aurora_data!T145,0) -> 0 | W25: =IFERROR(aurora_data!U145,0) -> 0 | X25: =IFERROR(W25/$W$12,0) -> 0
D26: Total Assignments | E26: =IFERROR(aurora_data!D146,0) -> 0 | F26: =IFERROR(aurora_data!E146,0) -> 0 | G26: =IFERROR(aurora_data!F146,0) -> 0 | H26: =IFERROR(aurora_data!G146,0) -> 1 | I26: =IFERROR(aurora_data!H146,0) -> 0 | J26: =IFERROR(aurora_data!I146,0) -> 0 | K26: =IFERROR(aurora_data!J146,0) -> 0 | L26: =IFERROR(aurora_data!K146,0) -> 0 | ... U26: =IFERROR(aurora_data!T146,0) -> 0 | W26: =IFERROR(aurora_data!U146,0) -> 1 | X26: =IFERROR(W26/$W$12,0) -> 1
D27: Selected | E27: =IFERROR(aurora_data!D147,0) -> 0 | F27: =IFERROR(aurora_data!E147,0) -> 0 | G27: =IFERROR(aurora_data!F147,0) -> 0 | H27: =IFERROR(aurora_data!G147,0) -> 0 | I27: =IFERROR(aurora_data!H147,0) -> 0 | J27: =IFERROR(aurora_data!I147,0) -> 0 | K27: =IFERROR(aurora_data!J147,0) -> 0 | L27: =IFERROR(aurora_data!K147,0) -> 0 | ... U27: =IFERROR(aurora_data!T147,0) -> 0 | W27: =IFERROR(aurora_data!U147,0) -> 0 | X27: =IFERROR(W27/$W$12,0) -> 0
B28: Open | C28: =aurora_data!A148 -> 08.00.00-08.11.30 | D28: Target | E28: =IFERROR(aurora_data!D148,0) -> 0 | F28: =IFERROR(aurora_data!E148,0) -> 0 | G28: =IFERROR(aurora_data!F148,0) -> 0 | H28: =IFERROR(aurora_data!G148,0) -> 0 | I28: =IFERROR(aurora_data!H148,0) -> 0 | J28: =IFERROR(aurora_data!I148,0) -> 0 | K28: =IFERROR(aurora_data!J148,0) -> 0 | L28: =IFERROR(aurora_data!K148,0) -> 0 | ... U28: =IFERROR(aurora_data!T148,0) -> 0 | W28: =IFERROR(aurora_data!U148,0) -> 1 | X28: =IFERROR(W28/$W$12,0) -> 1
D29: Usable | E29: =IFERROR(aurora_data!D149,0) -> 0 | F29: =IFERROR(aurora_data!E149,0) -> 0 | G29: =IFERROR(aurora_data!F149,0) -> 0 | H29: =IFERROR(aurora_data!G149,0) -> 0 | I29: =IFERROR(aurora_data!H149,0) -> 0 | J29: =IFERROR(aurora_data!I149,0) -> 0 | K29: =IFERROR(aurora_data!J149,0) -> 0 | L29: =IFERROR(aurora_data!K149,0) -> 0 | ... U29: =IFERROR(aurora_data!T149,0) -> 0 | W29: =IFERROR(aurora_data!U149,0) -> 0 | X29: =IFERROR(W29/$W$12,0) -> 0
D30: Stratified Out Usable N | E30: =IFERROR(aurora_data!D150,0) -> 0 | F30: =IFERROR(aurora_data!E150,0) -> 0 | G30: =IFERROR(aurora_data!F150,0) -> 0 | H30: =IFERROR(aurora_data!G150,0) -> 0 | I30: =IFERROR(aurora_data!H150,0) -> 0 | J30: =IFERROR(aurora_data!I150,0) -> 0 | K30: =IFERROR(aurora_data!J150,0) -> 0 | L30: =IFERROR(aurora_data!K150,0) -> 0 | ... U30: =IFERROR(aurora_data!T150,0) -> 0 | W30: =IFERROR(aurora_data!U150,0) -> 0 | X30: =IFERROR(W30/$W$12,0) -> 0
D31: In Process | E31: =IFERROR(aurora_data!D151,0) -> 0 | F31: =IFERROR(aurora_data!E151,0) -> 0 | G31: =IFERROR(aurora_data!F151,0) -> 0 | H31: =IFERROR(aurora_data!G151,0) -> 0 | I31: =IFERROR(aurora_data!H151,0) -> 0 | J31: =IFERROR(aurora_data!I151,0) -> 0 | K31: =IFERROR(aurora_data!J151,0) -> 0 | L31: =IFERROR(aurora_data!K151,0) -> 0 | ... U31: =IFERROR(aurora_data!T151,0) -> 0 | W31: =IFERROR(aurora_data!U151,0) -> 0 | X31: =IFERROR(W31/$W$12,0) -> 0
D32: Assigned Not Received | E32: =IFERROR(aurora_data!D152,0) -> 0 | F32: =IFERROR(aurora_data!E152,0) -> 0 | G32: =IFERROR(aurora_data!F152,0) -> 0 | H32: =IFERROR(aurora_data!G152,0) -> 0 | I32: =IFERROR(aurora_data!H152,0) -> 0 | J32: =IFERROR(aurora_data!I152,0) -> 0 | K32: =IFERROR(aurora_data!J152,0) -> 0 | L32: =IFERROR(aurora_data!K152,0) -> 0 | ... U32: =IFERROR(aurora_data!T152,0) -> 0 | W32: =IFERROR(aurora_data!U152,0) -> 0 | X32: =IFERROR(W32/$W$12,0) -> 0
D33: Reserved Not Received | E33: =IFERROR(aurora_data!D153,0) -> 0 | F33: =IFERROR(aurora_data!E153,0) -> 0 | G33: =IFERROR(aurora_data!F153,0) -> 0 | H33: =IFERROR(aurora_data!G153,0) -> 0 | I33: =IFERROR(aurora_data!H153,0) -> 0 | J33: =IFERROR(aurora_data!I153,0) -> 0 | K33: =IFERROR(aurora_data!J153,0) -> 0 | L33: =IFERROR(aurora_data!K153,0) -> 0 | ... U33: =IFERROR(aurora_data!T153,0) -> 0 | W33: =IFERROR(aurora_data!U153,0) -> 0 | X33: =IFERROR(W33/$W$12,0) -> 0
D34: Total Assignments | E34: =IFERROR(aurora_data!D154,0) -> 0 | F34: =IFERROR(aurora_data!E154,0) -> 0 | G34: =IFERROR(aurora_data!F154,0) -> 0 | H34: =IFERROR(aurora_data!G154,0) -> 0 | I34: =IFERROR(aurora_data!H154,0) -> 0 | J34: =IFERROR(aurora_data!I154,0) -> 0 | K34: =IFERROR(aurora_data!J154,0) -> 0 | L34: =IFERROR(aurora_data!K154,0) -> 0 | ... U34: =IFERROR(aurora_data!T154,0) -> 0 | W34: =IFERROR(aurora_data!U154,0) -> 0 | X34: =IFERROR(W34/$W$12,0) -> 0
D35: Selected | E35: =IFERROR(aurora_data!D155,0) -> 0 | F35: =IFERROR(aurora_data!E155,0) -> 0 | G35: =IFERROR(aurora_data!F155,0) -> 0 | H35: =IFERROR(aurora_data!G155,0) -> 0 | I35: =IFERROR(aurora_data!H155,0) -> 0 | J35: =IFERROR(aurora_data!I155,0) -> 0 | K35: =IFERROR(aurora_data!J155,0) -> 0 | L35: =IFERROR(aurora_data!K155,0) -> 0 | ... U35: =IFERROR(aurora_data!T155,0) -> 0 | W35: =IFERROR(aurora_data!U155,0) -> 0 | X35: =IFERROR(W35/$W$12,0) -> 0
B36: Open | C36: =aurora_data!A156 -> 09.00.00-09.11.30 | D36: Target | E36: =IFERROR(aurora_data!D156,0) -> 0 | F36: =IFERROR(aurora_data!E156,0) -> 0 | G36: =IFERROR(aurora_data!F156,0) -> 0 | H36: =IFERROR(aurora_data!G156,0) -> 0 | I36: =IFERROR(aurora_data!H156,0) -> 0 | J36: =IFERROR(aurora_data!I156,0) -> 0 | K36: =IFERROR(aurora_data!J156,0) -> 0 | L36: =IFERROR(aurora_data!K156,0) -> 0 | ... U36: =IFERROR(aurora_data!T156,0) -> 0 | W36: =IFERROR(aurora_data!U156,0) -> 1 | X36: =IFERROR(W36/$W$12,0) -> 1
D37: Usable | E37: =IFERROR(aurora_data!D157,0) -> 0 | F37: =IFERROR(aurora_data!E157,0) -> 0 | G37: =IFERROR(aurora_data!F157,0) -> 0 | H37: =IFERROR(aurora_data!G157,0) -> 0 | I37: =IFERROR(aurora_data!H157,0) -> 0 | J37: =IFERROR(aurora_data!I157,0) -> 0 | K37: =IFERROR(aurora_data!J157,0) -> 0 | L37: =IFERROR(aurora_data!K157,0) -> 0 | ... U37: =IFERROR(aurora_data!T157,0) -> 0 | W37: =IFERROR(aurora_data!U157,0) -> 0 | X37: =IFERROR(W37/$W$12,0) -> 0
D38: Stratified Out Usable N | E38: =IFERROR(aurora_data!D158,0) -> 0 | F38: =IFERROR(aurora_data!E158,0) -> 0 | G38: =IFERROR(aurora_data!F158,0) -> 0 | H38: =IFERROR(aurora_data!G158,0) -> 0 | I38: =IFERROR(aurora_data!H158,0) -> 0 | J38: =IFERROR(aurora_data!I158,0) -> 0 | K38: =IFERROR(aurora_data!J158,0) -> 0 | L38: =IFERROR(aurora_data!K158,0) -> 0 | ... U38: =IFERROR(aurora_data!T158,0) -> 0 | W38: =IFERROR(aurora_data!U158,0) -> 0 | X38: =IFERROR(W38/$W$12,0) -> 0
D39: In Process | E39: =IFERROR(aurora_data!D159,0) -> 0 | F39: =IFERROR(aurora_data!E159,0) -> 0 | G39: =IFERROR(aurora_data!F159,0) -> 0 | H39: =IFERROR(aurora_data!G159,0) -> 0 | I39: =IFERROR(aurora_data!H159,0) -> 0 | J39: =IFERROR(aurora_data!I159,0) -> 0 | K39: =IFERROR(aurora_data!J159,0) -> 0 | L39: =IFERROR(aurora_data!K159,0) -> 0 | ... U39: =IFERROR(aurora_data!T159,0) -> 0 | W39: =IFERROR(aurora_data!U159,0) -> 0 | X39: =IFERROR(W39/$W$12,0) -> 0
D40: Assigned Not Received | E40: =IFERROR(aurora_data!D160,0) -> 0 | F40: =IFERROR(aurora_data!E160,0) -> 0 | G40: =IFERROR(aurora_data!F160,0) -> 0 | H40: =IFERROR(aurora_data!G160,0) -> 0 | I40: =IFERROR(aurora_data!H160,0) -> 0 | J40: =IFERROR(aurora_data!I160,0) -> 0 | K40: =IFERROR(aurora_data!J160,0) -> 0 | L40: =IFERROR(aurora_data!K160,0) -> 0 | ... U40: =IFERROR(aurora_data!T160,0) -> 0 | W40: =IFERROR(aurora_data!U160,0) -> 0 | X40: =IFERROR(W40/$W$12,0) -> 0
D41: Reserved Not Received | E41: =IFERROR(aurora_data!D161,0) -> 0 | F41: =IFERROR(aurora_data!E161,0) -> 0 | G41: =IFERROR(aurora_data!F161,0) -> 0 | H41: =IFERROR(aurora_data!G161,0) -> 0 | I41: =IFERROR(aurora_data!H161,0) -> 0 | J41: =IFERROR(aurora_data!I161,0) -> 0 | K41: =IFERROR(aurora_data!J161,0) -> 0 | L41: =IFERROR(aurora_data!K161,0) -> 0 | ... U41: =IFERROR(aurora_data!T161,0) -> 0 | W41: =IFERROR(aurora_data!U161,0) -> 0 | X41: =IFERROR(W41/$W$12,0) -> 0
D42: Total Assignments | E42: =IFERROR(aurora_data!D162,0) -> 0 | F42: =IFERROR(aurora_data!E162,0) -> 0 | G42: =IFERROR(aurora_data!F162,0) -> 0 | H42: =IFERROR(aurora_data!G162,0) -> 0 | I42: =IFERROR(aurora_data!H162,0) -> 0 | J42: =IFERROR(aurora_data!I162,0) -> 0 | K42: =IFERROR(aurora_data!J162,0) -> 0 | L42: =IFERROR(aurora_data!K162,0) -> 0 | ... U42: =IFERROR(aurora_data!T162,0) -> 0 | W42: =IFERROR(aurora_data!U162,0) -> 0 | X42: =IFERROR(W42/$W$12,0) -> 0
...

Sheet OSEP_DD_P
A1: Total Assigments below Target | D1: Study Information | N1: Additional Information
A2: Usable greater/equal to target | D2: =_xlfn.CONCAT("Study Name: "," OSEP – Developmental Delay - Paper") -> Study Name: OSEP – Developmental Delay - Paper | K2: Usable = case is available to Psychometrics for this study In Process = questionable, In Process Assigned Not Recd = Tests assigned to examiners, no tests received (required tests) Reserved not Received = Tests in reserved status, not received Total Assignments = sum of Usable, Received Non Final, Assigned Partial Received, Assigned Not Received Selected = default status for making an assignment
D3: =_xlfn.CONCAT("Study Acronym: "," OSEP_DD_P") -> Study Acronym: OSEP_DD_P | F3: Study ID: 3818
D5: Additional Requirements
D6: None
B8: =_xlfn.CONCAT("Last Refreshed at: ",aurora_data!V232) -> Last Refreshed at: 09/17/2026 @ 7:20 AM | E8: Demographic Variables | W8: Totals
D9: Variance Tolerance: | E9: some of each, if possible | J9: some of each, if possible | O9: some of each, if possible | S9: some of each, if possible
B10: Status | E10: Education Level | J10: Ethnicity | O10: Region | S10: SEX
C11: ageband | D11: report | E11: 1 | F11: 2 | G11: 3 | H11: 4 | I11: 5 | J11: AS | K11: BL | L11: HI | M11: OTH | N11: WH | O11: MW | P11: NE | Q11: SO | R11: WE | S11: F | T11: M | U11: INT
B12: Open | C12: =aurora_data!A232 -> 06.00.00-06.11.30 | D12: Target | E12: =IFERROR(aurora_data!D232,0) -> 0 | F12: =IFERROR(aurora_data!E232,0) -> 0 | G12: =IFERROR(aurora_data!F232,0) -> 0 | H12: =IFERROR(aurora_data!G232,0) -> 0 | I12: =IFERROR(aurora_data!H232,0) -> 0 | J12: =IFERROR(aurora_data!I232,0) -> 0 | K12: =IFERROR(aurora_data!J232,0) -> 0 | L12: =IFERROR(aurora_data!K232,0) -> 0 | ... V12: =IFERROR(aurora_data!U232,0) -> 7 | W12: =IFERROR(aurora_data!U232,0) -> 7 | X12: =IFERROR(W12/$W$12,0) -> 1
D13: Usable | E13: =IFERROR(aurora_data!D233,0) -> 0 | F13: =IFERROR(aurora_data!E233,0) -> 0 | G13: =IFERROR(aurora_data!F233,0) -> 0 | H13: =IFERROR(aurora_data!G233,0) -> 0 | I13: =IFERROR(aurora_data!H233,0) -> 0 | J13: =IFERROR(aurora_data!I233,0) -> 0 | K13: =IFERROR(aurora_data!J233,0) -> 0 | L13: =IFERROR(aurora_data!K233,0) -> 0 | ... V13: =IFERROR(aurora_data!U233,0) -> 0 | W13: =IFERROR(aurora_data!U233,0) -> 0 | X13: =IFERROR(W13/$W$12,0) -> 0
D14: Stratified Out Usable N | E14: =IFERROR(aurora_data!D234,0) -> 0 | F14: =IFERROR(aurora_data!E234,0) -> 0 | G14: =IFERROR(aurora_data!F234,0) -> 0 | H14: =IFERROR(aurora_data!G234,0) -> 0 | I14: =IFERROR(aurora_data!H234,0) -> 0 | J14: =IFERROR(aurora_data!I234,0) -> 0 | K14: =IFERROR(aurora_data!J234,0) -> 0 | L14: =IFERROR(aurora_data!K234,0) -> 0 | ... V14: =IFERROR(aurora_data!U234,0) -> 0 | W14: =IFERROR(aurora_data!U234,0) -> 0 | X14: =IFERROR(W14/$W$12,0) -> 0
D15: In Process | E15: =IFERROR(aurora_data!D235,0) -> 0 | F15: =IFERROR(aurora_data!E235,0) -> 0 | G15: =IFERROR(aurora_data!F235,0) -> 0 | H15: =IFERROR(aurora_data!G235,0) -> 0 | I15: =IFERROR(aurora_data!H235,0) -> 0 | J15: =IFERROR(aurora_data!I235,0) -> 0 | K15: =IFERROR(aurora_data!J235,0) -> 0 | L15: =IFERROR(aurora_data!K235,0) -> 0 | ... V15: =IFERROR(aurora_data!U235,0) -> 0 | W15: =IFERROR(aurora_data!U235,0) -> 0 | X15: =IFERROR(W15/$W$12,0) -> 0
D16: Assigned Not Received | E16: =IFERROR(aurora_data!D236,0) -> 0 | F16: =IFERROR(aurora_data!E236,0) -> 0 | G16: =IFERROR(aurora_data!F236,0) -> 0 | H16: =IFERROR(aurora_data!G236,0) -> 0 | I16: =IFERROR(aurora_data!H236,0) -> 0 | J16: =IFERROR(aurora_data!I236,0) -> 0 | K16: =IFERROR(aurora_data!J236,0) -> 0 | L16: =IFERROR(aurora_data!K236,0) -> 0 | ... V16: =IFERROR(aurora_data!U236,0) -> 0 | W16: =IFERROR(aurora_data!U236,0) -> 0 | X16: =IFERROR(W16/$W$12,0) -> 0
D17: Reserved Not Received | E17: =IFERROR(aurora_data!D237,0) -> 0 | F17: =IFERROR(aurora_data!E237,0) -> 0 | G17: =IFERROR(aurora_data!F237,0) -> 0 | H17: =IFERROR(aurora_data!G237,0) -> 0 | I17: =IFERROR(aurora_data!H237,0) -> 0 | J17: =IFERROR(aurora_data!I237,0) -> 0 | K17: =IFERROR(aurora_data!J237,0) -> 0 | L17: =IFERROR(aurora_data!K237,0) -> 0 | ... V17: =IFERROR(aurora_data!U237,0) -> 0 | W17: =IFERROR(aurora_data!U237,0) -> 0 | X17: =IFERROR(W17/$W$12,0) -> 0
D18: Total Assignments | E18: =IFERROR(aurora_data!D238,0) -> 0 | F18: =IFERROR(aurora_data!E238,0) -> 0 | G18: =IFERROR(aurora_data!F238,0) -> 0 | H18: =IFERROR(aurora_data!G238,0) -> 0 | I18: =IFERROR(aurora_data!H238,0) -> 0 | J18: =IFERROR(aurora_data!I238,0) -> 0 | K18: =IFERROR(aurora_data!J238,0) -> 0 | L18: =IFERROR(aurora_data!K238,0) -> 0 | ... V18: =IFERROR(aurora_data!U238,0) -> 0 | W18: =IFERROR(aurora_data!U238,0) -> 0 | X18: =IFERROR(W18/$W$12,0) -> 0
D19: Selected | E19: =IFERROR(aurora_data!D239,0) -> 0 | F19: =IFERROR(aurora_data!E239,0) -> 0 | G19: =IFERROR(aurora_data!F239,0) -> 0 | H19: =IFERROR(aurora_data!G239,0) -> 0 | I19: =IFERROR(aurora_data!H239,0) -> 0 | J19: =IFERROR(aurora_data!I239,0) -> 0 | K19: =IFERROR(aurora_data!J239,0) -> 0 | L19: =IFERROR(aurora_data!K239,0) -> 0 | ... V19: =IFERROR(aurora_data!U239,0) -> 0 | W19: =IFERROR(aurora_data!U239,0) -> 0 | X19: =IFERROR(W19/$W$12,0) -> 0
B20: Open | C20: =aurora_data!A240 -> 07.00.00-07.11.30 | D20: Target | E20: =IFERROR(aurora_data!D240,0) -> 0 | F20: =IFERROR(aurora_data!E240,0) -> 0 | G20: =IFERROR(aurora_data!F240,0) -> 0 | H20: =IFERROR(aurora_data!G240,0) -> 0 | I20: =IFERROR(aurora_data!H240,0) -> 0 | J20: =IFERROR(aurora_data!I240,0) -> 0 | K20: =IFERROR(aurora_data!J240,0) -> 0 | L20: =IFERROR(aurora_data!K240,0) -> 0 | ... V20: =IFERROR(aurora_data!U240,0) -> 7 | W20: =IFERROR(aurora_data!U240,0) -> 7 | X20: =IFERROR(W20/$W$12,0) -> 1
D21: Usable | E21: =IFERROR(aurora_data!D241,0) -> 0 | F21: =IFERROR(aurora_data!E241,0) -> 1 | G21: =IFERROR(aurora_data!F241,0) -> 0 | H21: =IFERROR(aurora_data!G241,0) -> 0 | I21: =IFERROR(aurora_data!H241,0) -> 0 | J21: =IFERROR(aurora_data!I241,0) -> 0 | K21: =IFERROR(aurora_data!J241,0) -> 1 | L21: =IFERROR(aurora_data!K241,0) -> 0 | ... V21: =IFERROR(aurora_data!U241,0) -> 1 | W21: =IFERROR(aurora_data!U241,0) -> 1 | X21: =IFERROR(W21/$W$12,0) -> 0.14285714
D22: Stratified Out Usable N | E22: =IFERROR(aurora_data!D242,0) -> 0 | F22: =IFERROR(aurora_data!E242,0) -> 0 | G22: =IFERROR(aurora_data!F242,0) -> 0 | H22: =IFERROR(aurora_data!G242,0) -> 0 | I22: =IFERROR(aurora_data!H242,0) -> 0 | J22: =IFERROR(aurora_data!I242,0) -> 0 | K22: =IFERROR(aurora_data!J242,0) -> 0 | L22: =IFERROR(aurora_data!K242,0) -> 0 | ... V22: =IFERROR(aurora_data!U242,0) -> 0 | W22: =IFERROR(aurora_data!U242,0) -> 0 | X22: =IFERROR(W22/$W$12,0) -> 0
